Workbook

Sheet 19+ all
C1: EDU
C2: 0 | D2: 1 | E2: 2 | F2: 3 | G2: 4 | H2: 5 | I2: 6 | J2: 7 | K2: 8 | L2: 9 | M2: 10 | N2: 11 | O2: 12 | P2: 13 | Q2: 14 | R2: 15 | S2: 16 | T2: 17 | U2: 18 | V2: 19 | W2: 20 | X2: 21 | Y2: 22 | Z2: 23 | AA2: 24
C3: Count | D3: Count | E3: Count | F3: Count | G3: Count | H3: Count | I3: Count | J3: Count | K3: Count | L3: Count | M3: Count | N3: Count | O3: Count | P3: Count | Q3: Count | R3: Count | S3: Count | T3: Count | U3: Count | V3: Count | W3: Count | X3: Count | Y3: Count | Z3: Count | AA3: Count | AC3: Total people | AD3: Total years edu | AE3: Average years of education
A4: MUN | B4: 010101 | C4: 9860 | D4: 2379 | E4: 3767 | F4: 5878 | G4: 4332 | H4: 8330 | I4: 4306 | J4: 3144 | K4: 5108 | L4: 3534 | M4: 3559 | N4: 4120 | O4: 34497 | P4: 9394 | Q4: 13395 | R4: 19864 | S4: 6948 | T4: 46497 | U4: 1391 | V4: 5925 | W4: 119 | X4: 52 | Y4: 66 | Z4: 586 | AA4: 2598 | AC4: =SUM(C4:AA4) -> 199649 | AD4: =C$2*C4+D$2*D4+E$2*E4+F$2*F4+G$2*G4+H$2*H4+I$2*I4+J$2*J4+K$2*K4+L$2*L4+M$2*M4+N$2*N4+O$2*O4+P$2*P4+Q$2*Q4+R$2*R4+S$2*S4+T$2*T4+U$2*U4+V$2*V4+W$2*W4+X$2*X4+Y$2*Y4+Z$2*Z4+AA$2*AA4 -> 2429509 | AE4: =AD4/AC4 -> 12.168901
B5: 010102 | C5: 725 | D5: 171 | E5: 260 | F5: 464 | G5: 327 | H5: 564 | I5: 223 | J5: 172 | K5: 235 | L5: 132 | M5: 144 | N5: 151 | O5: 1105 | P5: 181 | Q5: 259 | R5: 301 | S5: 79 | T5: 635 | U5: 19 | V5: 60 | W5: 1 | X5: 1 | Y5: 1 | Z5: 8 | AA5: 89 | AC5: =SUM(C5:AA5) -> 6307 | AD5: =C$2*C5+D$2*D5+E$2*E5+F$2*F5+G$2*G5+H$2*H5+I$2*I5+J$2*J5+K$2*K5+L$2*L5+M$2*M5+N$2*N5+O$2*O5+P$2*P5+Q$2*Q5+R$2*R5+S$2*S5+T$2*T5+U$2*U5+V$2*V5+W$2*W5+X$2*X5+Y$2*Y5+Z$2*Z5+AA$2*AA5 -> 54600 | AE5: =AD5/AC5 -> 8.6570477
B6: 010103 | C6: 1742 | D6: 347 | E6: 762 | F6: 982 | G6: 726 | H6: 952 | I6: 492 | J6: 187 | K6: 331 | L6: 137 | M6: 139 | N6: 148 | O6: 780 | P6: 56 | Q6: 101 | R6: 72 | S6: 19 | T6: 210 | U6: 2 | V6: 15 | W6: 2 | X6: 0 | Y6: 0 | Z6: 2 | AA6: 150 | AC6: =SUM(C6:AA6) -> 8354 | AD6: =C$2*C6+D$2*D6+E$2*E6+F$2*F6+G$2*G6+H$2*H6+I$2*I6+J$2*J6+K$2*K6+L$2*L6+M$2*M6+N$2*N6+O$2*O6+P$2*P6+Q$2*Q6+R$2*R6+S$2*S6+T$2*T6+U$2*U6+V$2*V6+W$2*W6+X$2*X6+Y$2*Y6+Z$2*Z6+AA$2*AA6 -> 44104 | AE6: =AD6/AC6 -> 5.2793871
B7: 010201 | C7: 999 | D7: 164 | E7: 384 | F7: 401 | G7: 282 | H7: 536 | I7: 396 | J7: 100 | K7: 148 | L7: 80 | M7: 65 | N7: 55 | O7: 366 | P7: 43 | Q7: 99 | R7: 140 | S7: 11 | T7: 323 | U7: 9 | V7: 19 | W7: 0 | X7: 0 | Y7: 1 | Z7: 1 | AA7: 235 | AC7: =SUM(C7:AA7) -> 4857 | AD7: =C$2*C7+D$2*D7+E$2*E7+F$2*F7+G$2*G7+H$2*H7+I$2*I7+J$2*J7+K$2*K7+L$2*L7+M$2*M7+N$2*N7+O$2*O7+P$2*P7+Q$2*Q7+R$2*R7+S$2*S7+T$2*T7+U$2*U7+V$2*V7+W$2*W7+X$2*X7+Y$2*Y7+Z$2*Z7+AA$2*AA7 -> 32490 | AE7: =AD7/AC7 -> 6.6893144
B8: 010202 | C8: 2505 | D8: 331 | E8: 706 | F8: 699 | G8: 513 | H8: 875 | I8: 390 | J8: 297 | K8: 549 | L8: 256 | M8: 260 | N8: 271 | O8: 1359 | P8: 155 | Q8: 268 | R8: 258 | S8: 62 | T8: 469 | U8: 9 | V8: 31 | W8: 0 | X8: 1 | Y8: 1 | Z8: 1 | AA8: 285 | AC8: =SUM(C8:AA8) -> 10551 | AD8: =C$2*C8+D$2*D8+E$2*E8+F$2*F8+G$2*G8+H$2*H8+I$2*I8+J$2*J8+K$2*K8+L$2*L8+M$2*M8+N$2*N8+O$2*O8+P$2*P8+Q$2*Q8+R$2*R8+S$2*S8+T$2*T8+U$2*U8+V$2*V8+W$2*W8+X$2*X8+Y$2*Y8+Z$2*Z8+AA$2*AA8 -> 69530 | AE8: =AD8/AC8 -> 6.5898967
B9: 010301 | C9: 1040 | D9: 188 | E9: 475 | F9: 710 | G9: 640 | H9: 1001 | I9: 774 | J9: 219 | K9: 389 | L9: 191 | M9: 196 | N9: 195 | O9: 1446 | P9: 184 | Q9: 298 | R9: 360 | S9: 82 | T9: 674 | U9: 16 | V9: 53 | W9: 1 | X9: 0 | Y9: 0 | Z9: 8 | AA9: 204 | AC9: =SUM(C9:AA9) -> 9344 | AD9: =C$2*C9+D$2*D9+E$2*E9+F$2*F9+G$2*G9+H$2*H9+I$2*I9+J$2*J9+K$2*K9+L$2*L9+M$2*M9+N$2*N9+O$2*O9+P$2*P9+Q$2*Q9+R$2*R9+S$2*S9+T$2*T9+U$2*U9+V$2*V9+W$2*W9+X$2*X9+Y$2*Y9+Z$2*Z9+AA$2*AA9 -> 74427 | AE9: =AD9/AC9 -> 7.9652183
B10: 010302 | C10: 1919 | D10: 159 | E10: 317 | F10: 489 | G10: 430 | H10: 755 | I10: 593 | J10: 179 | K10: 388 | L10: 159 | M10: 175 | N10: 219 | O10: 1130 | P10: 88 | Q10: 156 | R10: 189 | S10: 31 | T10: 303 | U10: 4 | V10: 19 | W10: 1 | X10: 1 | Y10: 0 | Z10: 2 | AA10: 231 | AC10: =SUM(C10:AA10) -> 7937 | AD10: =C$2*C10+D$2*D10+E$2*E10+F$2*F10+G$2*G10+H$2*H10+I$2*I10+J$2*J10+K$2*K10+L$2*L10+M$2*M10+N$2*N10+O$2*O10+P$2*P10+Q$2*Q10+R$2*R10+S$2*S10+T$2*T10+U$2*U10+V$2*V10+W$2*W10+X$2*X10+Y$2*Y10+Z$2*Z10+AA$2*AA10 -> 52694 | AE10: =AD10/AC10 -> 6.6390324
B11: 010303 | C11: 708 | D11: 155 | E11: 324 | F11: 418 | G11: 332 | H11: 593 | I11: 236 | J11: 152 | K11: 296 | L11: 147 | M11: 151 | N11: 157 | O11: 1150 | P11: 111 | Q11: 194 | R11: 283 | S11: 70 | T11: 348 | U11: 11 | V11: 16 | W11: 0 | X11: 0 | Y11: 1 | Z11: 3 | AA11: 51 | AC11: =SUM(C11:AA11) -> 5907 | AD11: =C$2*C11+D$2*D11+E$2*E11+F$2*F11+G$2*G11+H$2*H11+I$2*I11+J$2*J11+K$2*K11+L$2*L11+M$2*M11+N$2*N11+O$2*O11+P$2*P11+Q$2*Q11+R$2*R11+S$2*S11+T$2*T11+U$2*U11+V$2*V11+W$2*W11+X$2*X11+Y$2*Y11+Z$2*Z11+AA$2*AA11 -> 46815 | AE11: =AD11/AC11 -> 7.9253428
B12: 010304 | C12: 1223 | D12: 198 | E12: 338 | F12: 481 | G12: 330 | H12: 485 | I12: 324 | J12: 194 | K12: 331 | L12: 147 | M12: 114 | N12: 146 | O12: 1091 | P12: 60 | Q12: 90 | R12: 121 | S12: 15 | T12: 236 | U12: 7 | V12: 23 | W12: 0 | X12: 0 | Y12: 0 | Z12: 5 | AA12: 184 | AC12: =SUM(C12:AA12) -> 6143 | AD12: =C$2*C12+D$2*D12+E$2*E12+F$2*F12+G$2*G12+H$2*H12+I$2*I12+J$2*J12+K$2*K12+L$2*L12+M$2*M12+N$2*N12+O$2*O12+P$2*P12+Q$2*Q12+R$2*R12+S$2*S12+T$2*T12+U$2*U12+V$2*V12+W$2*W12+X$2*X12+Y$2*Y12+Z$2*Z12+AA$2*AA12 -> 42374 | AE12: =AD12/AC12 -> 6.8979326
B13: 010401 | C13: 657 | D13: 210 | E13: 418 | F13: 605 | G13: 522 | H13: 763 | I13: 311 | J13: 169 | K13: 291 | L13: 104 | M13: 98 | N13: 92 | O13: 570 | P13: 121 | Q13: 186 | R13: 295 | S13: 122 | T13: 679 | U13: 17 | V13: 57 | W13: 2 | X13: 0 | Y13: 2 | Z13: 5 | AA13: 91 | AC13: =SUM(C13:AA13) -> 6387 | AD13: =C$2*C13+D$2*D13+E$2*E13+F$2*F13+G$2*G13+H$2*H13+I$2*I13+J$2*J13+K$2*K13+L$2*L13+M$2*M13+N$2*N13+O$2*O13+P$2*P13+Q$2*Q13+R$2*R13+S$2*S13+T$2*T13+U$2*U13+V$2*V13+W$2*W13+X$2*X13+Y$2*Y13+Z$2*Z13+AA$2*AA13 -> 49778 | AE13: =AD13/AC13 -> 7.7936433
B14: 010402 | C14: 893 | D14: 206 | E14: 410 | F14: 389 | G14: 315 | H14: 531 | I14: 578 | J14: 118 | K14: 169 | L14: 71 | M14: 80 | N14: 85 | O14: 799 | P14: 92 | Q14: 121 | R14: 222 | S14: 36 | T14: 344 | U14: 8 | V14: 27 | W14: 1 | X14: 0 | Y14: 0 | Z14: 4 | AA14: 77 | AC14: =SUM(C14:AA14) -> 5576 | AD14: =C$2*C14+D$2*D14+E$2*E14+F$2*F14+G$2*G14+H$2*H14+I$2*I14+J$2*J14+K$2*K14+L$2*L14+M$2*M14+N$2*N14+O$2*O14+P$2*P14+Q$2*Q14+R$2*R14+S$2*S14+T$2*T14+U$2*U14+V$2*V14+W$2*W14+X$2*X14+Y$2*Y14+Z$2*Z14+AA$2*AA14 -> 38977 | AE14: =AD14/AC14 -> 6.9901363
B15: 010403 | C15: 1017 | D15: 136 | E15: 377 | F15: 412 | G15: 322 | H15: 331 | I15: 319 | J15: 122 | K15: 236 | L15: 52 | M15: 59 | N15: 65 | O15: 435 | P15: 54 | Q15: 89 | R15: 122 | S15: 18 | T15: 298 | U15: 10 | V15: 18 | W15: 0 | X15: 0 | Y15: 0 | Z15: 4 | AA15: 51 | AC15: =SUM(C15:AA15) -> 4547 | AD15: =C$2*C15+D$2*D15+E$2*E15+F$2*F15+G$2*G15+H$2*H15+I$2*I15+J$2*J15+K$2*K15+L$2*L15+M$2*M15+N$2*N15+O$2*O15+P$2*P15+Q$2*Q15+R$2*R15+S$2*S15+T$2*T15+U$2*U15+V$2*V15+W$2*W15+X$2*X15+Y$2*Y15+Z$2*Z15+AA$2*AA15 -> 27688 | AE15: =AD15/AC15 -> 6.0892896
B16: 010404 | C16: 302 | D16: 66 | E16: 146 | F16: 173 | G16: 140 | H16: 193 | I16: 75 | J16: 63 | K16: 106 | L16: 39 | M16: 44 | N16: 44 | O16: 384 | P16: 55 | Q16: 104 | R16: 215 | S16: 26 | T16: 376 | U16: 9 | V16: 23 | W16: 1 | X16: 0 | Y16: 0 | Z16: 6 | AA16: 72 | AC16: =SUM(C16:AA16) -> 2662 | AD16: =C$2*C16+D$2*D16+E$2*E16+F$2*F16+G$2*G16+H$2*H16+I$2*I16+J$2*J16+K$2*K16+L$2*L16+M$2*M16+N$2*N16+O$2*O16+P$2*P16+Q$2*Q16+R$2*R16+S$2*S16+T$2*T16+U$2*U16+V$2*V16+W$2*W16+X$2*X16+Y$2*Y16+Z$2*Z16+AA$2*AA16 -> 24713 | AE16: =AD16/AC16 -> 9.2836213
... B346: 090503 | C346: 53 | D346: 15 | E346: 22 | F346: 52 | G346: 55 | H346: 129 | I346: 71 | J346: 80 | K346: 129 | L346: 103 | M346: 89 | N346: 81 | O346: 361 | P346: 31 | Q346: 17 | R346: 26 | S346: 1 | T346: 29 | U346: 0 | V346: 0 | W346: 0 | X346: 0 | Y346: 0 | Z346: 1 | AA346: 96 | AC346: =SUM(C346:AA346) -> 1441 | AD346: =C$2*C346+D$2*D346+E$2*E346+F$2*F346+G$2*G346+H$2*H346+I$2*I346+J$2*J346+K$2*K346+L$2*L346+M$2*M346+N$2*N346+O$2*O346+P$2*P346+Q$2*Q346+R$2*R346+S$2*S346+T$2*T346+U$2*U346+V$2*V346+W$2*W346+X$2*X346+Y$2*Y346+Z$2*Z346+AA$2*AA346 -> 14005 | AE346: =AD346/AC346 -> 9.7189452
C347: =SUM(C4:C346) -> 362260 | D347: =SUM(D4:D346) -> 122421 | E347: =SUM(E4:E346) -> 197009 | F347: =SUM(F4:F346) -> 290759 | G347: =SUM(G4:G346) -> 221181 | H347: =SUM(H4:H346) -> 414954 | I347: =SUM(I4:I346) -> 226090 | J347: =SUM(J4:J346) -> 200615 | ... AA347: =SUM(AA4:AA346) -> 134118 | AC347: =SUM(AC4:AC346) -> 7484400 | AD347: =SUM(AD4:AD346) -> 80866927 | AE347: =AD347/AC347 -> 10.804731

Sheet 19+ female
C1: EDU
C2: 0 | D2: 1 | E2: 2 | F2: 3 | G2: 4 | H2: 5 | I2: 6 | J2: 7 | K2: 8 | L2: 9 | M2: 10 | N2: 11 | O2: 12 | P2: 13 | Q2: 14 | R2: 15 | S2: 16 | T2: 17 | U2: 18 | V2: 19 | W2: 20 | X2: 21 | Y2: 22 | Z2: 23 | AA2: 24
C3: Count | D3: Count | E3: Count | F3: Count | G3: Count | H3: Count | I3: Count | J3: Count | K3: Count | L3: Count | M3: Count | N3: Count | O3: Count | P3: Count | Q3: Count | R3: Count | S3: Count | T3: Count | U3: Count | V3: Count | W3: Count | X3: Count | Y3: Count | Z3: Count | AA3: Count | AC3: Total people | AD3: Total years edu | AE3: Average years of education
A4: MUN | B4: 010101 | C4: 7645 | D4: 1613 | E4: 2463 | F4: 3522 | G4: 2447 | H4: 4524 | I4: 2254 | J4: 1424 | K4: 2380 | L4: 1560 | M4: 1515 | N4: 1781 | O4: 15689 | P4: 4843 | Q4: 6852 | R4: 9981 | S4: 3666 | T4: 26742 | U4: 704 | V4: 2960 | W4: 45 | X4: 23 | Y4: 41 | Z4: 191 | AA4: 1419 | AC4: =SUM(C4:AA4) -> 106284 | AD4: =C$2*C4+D$2*D4+E$2*E4+F$2*F4+G$2*G4+H$2*H4+I$2*I4+J$2*J4+K$2*K4+L$2*L4+M$2*M4+N$2*N4+O$2*O4+P$2*P4+Q$2*Q4+R$2*R4+S$2*S4+T$2*T4+U$2*U4+V$2*V4+W$2*W4+X$2*X4+Y$2*Y4+Z$2*Z4+AA$2*AA4 -> 1260612 | AE4: =AD4/AC4 -> 11.860788
B5: 010102 | C5: 559 | D5: 107 | E5: 146 | F5: 228 | G5: 164 | H5: 258 | I5: 104 | J5: 61 | K5: 89 | L5: 44 | M5: 56 | N5: 62 | O5: 504 | P5: 95 | Q5: 129 | R5: 129 | S5: 42 | T5: 346 | U5: 6 | V5: 28 | W5: 0 | X5: 0 | Y5: 1 | Z5: 3 | AA5: 44 | AC5: =SUM(C5:AA5) -> 3205 | AD5: =C$2*C5+D$2*D5+E$2*E5+F$2*F5+G$2*G5+H$2*H5+I$2*I5+J$2*J5+K$2*K5+L$2*L5+M$2*M5+N$2*N5+O$2*O5+P$2*P5+Q$2*Q5+R$2*R5+S$2*S5+T$2*T5+U$2*U5+V$2*V5+W$2*W5+X$2*X5+Y$2*Y5+Z$2*Z5+AA$2*AA5 -> 25795 | AE5: =AD5/AC5 -> 8.0483619
B6: 010103 | C6: 1258 | D6: 191 | E6: 361 | F6: 446 | G6: 275 | H6: 360 | I6: 241 | J6: 61 | K6: 147 | L6: 42 | M6: 55 | N6: 63 | O6: 298 | P6: 21 | Q6: 51 | R6: 25 | S6: 11 | T6: 100 | U6: 0 | V6: 7 | W6: 1 | X6: 0 | Y6: 0 | Z6: 2 | AA6: 88 | AC6: =SUM(C6:AA6) -> 4104 | AD6: =C$2*C6+D$2*D6+E$2*E6+F$2*F6+G$2*G6+H$2*H6+I$2*I6+J$2*J6+K$2*K6+L$2*L6+M$2*M6+N$2*N6+O$2*O6+P$2*P6+Q$2*Q6+R$2*R6+S$2*S6+T$2*T6+U$2*U6+V$2*V6+W$2*W6+X$2*X6+Y$2*Y6+Z$2*Z6+AA$2*AA6 -> 18946 | AE6: =AD6/AC6 -> 4.6164717
B7: 010201 | C7: 704 | D7: 85 | E7: 157 | F7: 178 | G7: 101 | H7: 236 | I7: 164 | J7: 37 | K7: 57 | L7: 31 | M7: 23 | N7: 21 | O7: 164 | P7: 23 | Q7: 50 | R7: 59 | S7: 2 | T7: 177 | U7: 5 | V7: 13 | W7: 0 | X7: 0 | Y7: 1 | Z7: 1 | AA7: 135 | AC7: =SUM(C7:AA7) -> 2424 | AD7: =C$2*C7+D$2*D7+E$2*E7+F$2*F7+G$2*G7+H$2*H7+I$2*I7+J$2*J7+K$2*K7+L$2*L7+M$2*M7+N$2*N7+O$2*O7+P$2*P7+Q$2*Q7+R$2*R7+S$2*S7+T$2*T7+U$2*U7+V$2*V7+W$2*W7+X$2*X7+Y$2*Y7+Z$2*Z7+AA$2*AA7 -> 15471 | AE7: =AD7/AC7 -> 6.3824257
B8: 010202 | C8: 1638 | D8: 178 | E8: 320 | F8: 270 | G8: 186 | H8: 366 | I8: 174 | J8: 142 | K8: 238 | L8: 122 | M8: 130 | N8: 125 | O8: 655 | P8: 78 | Q8: 134 | R8: 109 | S8: 36 | T8: 263 | U8: 3 | V8: 16 | W8: 0 | X8: 1 | Y8: 0 | Z8: 1 | AA8: 195 | AC8: =SUM(C8:AA8) -> 5380 | AD8: =C$2*C8+D$2*D8+E$2*E8+F$2*F8+G$2*G8+H$2*H8+I$2*I8+J$2*J8+K$2*K8+L$2*L8+M$2*M8+N$2*N8+O$2*O8+P$2*P8+Q$2*Q8+R$2*R8+S$2*S8+T$2*T8+U$2*U8+V$2*V8+W$2*W8+X$2*X8+Y$2*Y8+Z$2*Z8+AA$2*AA8 -> 34431 | AE8: =AD8/AC8 -> 6.3998141
B9: 010301 | C9: 671 | D9: 103 | E9: 254 | F9: 350 | G9: 287 | H9: 400 | I9: 356 | J9: 83 | K9: 156 | L9: 77 | M9: 76 | N9: 85 | O9: 619 | P9: 91 | Q9: 141 | R9: 156 | S9: 38 | T9: 351 | U9: 7 | V9: 24 | W9: 1 | X9: 0 | Y9: 0 | Z9: 3 | AA9: 108 | AC9: =SUM(C9:AA9) -> 4437 | AD9: =C$2*C9+D$2*D9+E$2*E9+F$2*F9+G$2*G9+H$2*H9+I$2*I9+J$2*J9+K$2*K9+L$2*L9+M$2*M9+N$2*N9+O$2*O9+P$2*P9+Q$2*Q9+R$2*R9+S$2*S9+T$2*T9+U$2*U9+V$2*V9+W$2*W9+X$2*X9+Y$2*Y9+Z$2*Z9+AA$2*AA9 -> 33925 | AE9: =AD9/AC9 -> 7.6459319
B10: 010302 | C10: 1089 | D10: 77 | E10: 152 | F10: 209 | G10: 204 | H10: 291 | I10: 297 | J10: 82 | K10: 158 | L10: 74 | M10: 81 | N10: 111 | O10: 473 | P10: 35 | Q10: 65 | R10: 80 | S10: 17 | T10: 163 | U10: 1 | V10: 8 | W10: 1 | X10: 1 | Y10: 0 | Z10: 0 | AA10: 108 | AC10: =SUM(C10:AA10) -> 3777 | AD10: =C$2*C10+D$2*D10+E$2*E10+F$2*F10+G$2*G10+H$2*H10+I$2*I10+J$2*J10+K$2*K10+L$2*L10+M$2*M10+N$2*N10+O$2*O10+P$2*P10+Q$2*Q10+R$2*R10+S$2*S10+T$2*T10+U$2*U10+V$2*V10+W$2*W10+X$2*X10+Y$2*Y10+Z$2*Z10+AA$2*AA10 -> 23683 | AE10: =AD10/AC10 -> 6.2703204
B11: 010303 | C11: 516 | D11: 77 | E11: 165 | F11: 200 | G11: 159 | H11: 269 | I11: 102 | J11: 75 | K11: 113 | L11: 63 | M11: 64 | N11: 73 | O11: 538 | P11: 52 | Q11: 95 | R11: 136 | S11: 36 | T11: 188 | U11: 2 | V11: 9 | W11: 0 | X11: 0 | Y11: 0 | Z11: 2 | AA11: 33 | AC11: =SUM(C11:AA11) -> 2967 | AD11: =C$2*C11+D$2*D11+E$2*E11+F$2*F11+G$2*G11+H$2*H11+I$2*I11+J$2*J11+K$2*K11+L$2*L11+M$2*M11+N$2*N11+O$2*O11+P$2*P11+Q$2*Q11+R$2*R11+S$2*S11+T$2*T11+U$2*U11+V$2*V11+W$2*W11+X$2*X11+Y$2*Y11+Z$2*Z11+AA$2*AA11 -> 22358 | AE11: =AD11/AC11 -> 7.5355578
B12: 010304 | C12: 877 | D12: 107 | E12: 136 | F12: 183 | G12: 135 | H12: 200 | I12: 141 | J12: 76 | K12: 129 | L12: 55 | M12: 40 | N12: 66 | O12: 513 | P12: 26 | Q12: 47 | R12: 55 | S12: 10 | T12: 119 | U12: 3 | V12: 13 | W12: 0 | X12: 0 | Y12: 0 | Z12: 3 | AA12: 90 | AC12: =SUM(C12:AA12) -> 3024 | AD12: =C$2*C12+D$2*D12+E$2*E12+F$2*F12+G$2*G12+H$2*H12+I$2*I12+J$2*J12+K$2*K12+L$2*L12+M$2*M12+N$2*N12+O$2*O12+P$2*P12+Q$2*Q12+R$2*R12+S$2*S12+T$2*T12+U$2*U12+V$2*V12+W$2*W12+X$2*X12+Y$2*Y12+Z$2*Z12+AA$2*AA12 -> 19189 | AE12: =AD12/AC12 -> 6.3455688
B13: 010401 | C13: 452 | D13: 118 | E13: 202 | F13: 267 | G13: 221 | H13: 319 | I13: 134 | J13: 54 | K13: 112 | L13: 44 | M13: 43 | N13: 42 | O13: 273 | P13: 77 | Q13: 91 | R13: 133 | S13: 78 | T13: 392 | U13: 7 | V13: 16 | W13: 1 | X13: 0 | Y13: 1 | Z13: 2 | AA13: 48 | AC13: =SUM(C13:AA13) -> 3127 | AD13: =C$2*C13+D$2*D13+E$2*E13+F$2*F13+G$2*G13+H$2*H13+I$2*I13+J$2*J13+K$2*K13+L$2*L13+M$2*M13+N$2*N13+O$2*O13+P$2*P13+Q$2*Q13+R$2*R13+S$2*S13+T$2*T13+U$2*U13+V$2*V13+W$2*W13+X$2*X13+Y$2*Y13+Z$2*Z13+AA$2*AA13 -> 24296 | AE13: =AD13/AC13 -> 7.7697474
B14: 010402 | C14: 639 | D14: 109 | E14: 176 | F14: 171 | G14: 130 | H14: 225 | I14: 274 | J14: 43 | K14: 65 | L14: 24 | M14: 36 | N14: 33 | O14: 359 | P14: 40 | Q14: 52 | R14: 92 | S14: 21 | T14: 203 | U14: 5 | V14: 18 | W14: 0 | X14: 0 | Y14: 0 | Z14: 1 | AA14: 44 | AC14: =SUM(C14:AA14) -> 2760 | AD14: =C$2*C14+D$2*D14+E$2*E14+F$2*F14+G$2*G14+H$2*H14+I$2*I14+J$2*J14+K$2*K14+L$2*L14+M$2*M14+N$2*N14+O$2*O14+P$2*P14+Q$2*Q14+R$2*R14+S$2*S14+T$2*T14+U$2*U14+V$2*V14+W$2*W14+X$2*X14+Y$2*Y14+Z$2*Z14+AA$2*AA14 -> 18257 | AE14: =AD14/AC14 -> 6.6148551
B15: 010403 | C15: 700 | D15: 71 | E15: 160 | F15: 159 | G15: 139 | H15: 145 | I15: 148 | J15: 45 | K15: 102 | L15: 22 | M15: 22 | N15: 32 | O15: 194 | P15: 23 | Q15: 49 | R15: 62 | S15: 5 | T15: 156 | U15: 6 | V15: 10 | W15: 0 | X15: 0 | Y15: 0 | Z15: 2 | AA15: 26 | AC15: =SUM(C15:AA15) -> 2278 | AD15: =C$2*C15+D$2*D15+E$2*E15+F$2*F15+G$2*G15+H$2*H15+I$2*I15+J$2*J15+K$2*K15+L$2*L15+M$2*M15+N$2*N15+O$2*O15+P$2*P15+Q$2*Q15+R$2*R15+S$2*S15+T$2*T15+U$2*U15+V$2*V15+W$2*W15+X$2*X15+Y$2*Y15+Z$2*Z15+AA$2*AA15 -> 12881 | AE15: =AD15/AC15 -> 5.6545215
B16: 010404 | C16: 217 | D16: 42 | E16: 68 | F16: 75 | G16: 54 | H16: 79 | I16: 30 | J16: 24 | K16: 49 | L16: 13 | M16: 15 | N16: 22 | O16: 174 | P16: 23 | Q16: 51 | R16: 111 | S16: 21 | T16: 207 | U16: 2 | V16: 12 | W16: 1 | X16: 0 | Y16: 0 | Z16: 2 | AA16: 45 | AC16: =SUM(C16:AA16) -> 1337 | AD16: =C$2*C16+D$2*D16+E$2*E16+F$2*F16+G$2*G16+H$2*H16+I$2*I16+J$2*J16+K$2*K16+L$2*L16+M$2*M16+N$2*N16+O$2*O16+P$2*P16+Q$2*Q16+R$2*R16+S$2*S16+T$2*T16+U$2*U16+V$2*V16+W$2*W16+X$2*X16+Y$2*Y16+Z$2*Z16+AA$2*AA16 -> 12294 | AE16: =AD16/AC16 -> 9.1952132
... B346: 090503 | C346: 26 | D346: 7 | E346: 8 | F346: 23 | G346: 23 | H346: 42 | I346: 25 | J346: 34 | K346: 54 | L346: 34 | M346: 37 | N346: 22 | O346: 149 | P346: 13 | Q346: 6 | R346: 8 | S346: 0 | T346: 15 | U346: 0 | V346: 0 | W346: 0 | X346: 0 | Y346: 0 | Z346: 1 | AA346: 47 | AC346: =SUM(C346:AA346) -> 574 | AD346: =C$2*C346+D$2*D346+E$2*E346+F$2*F346+G$2*G346+H$2*H346+I$2*I346+J$2*J346+K$2*K346+L$2*L346+M$2*M346+N$2*N346+O$2*O346+P$2*P346+Q$2*Q346+R$2*R346+S$2*S346+T$2*T346+U$2*U346+V$2*V346+W$2*W346+X$2*X346+Y$2*Y346+Z$2*Z346+AA$2*AA346 -> 5699 | AE346: =AD346/AC346 -> 9.9285714
C347: =SUM(C4:C346) -> 268270 | D347: =SUM(D4:D346) -> 82310 | E347: =SUM(E4:E346) -> 122548 | F347: =SUM(F4:F346) -> 164711 | G347: =SUM(G4:G346) -> 115449 | H347: =SUM(H4:H346) -> 209908 | I347: =SUM(I4:I346) -> 110193 | J347: =SUM(J4:J346) -> 88305 | ... AA347: =SUM(AA4:AA346) -> 69610 | AC347: =SUM(AC4:AC346) -> 3782938 | AD347: =SUM(AD4:AD346) -> 39622741 | AE347: =AD347/AC347 -> 10.474066

Sheet 19+ male
C1: EDU
C2: 0 | D2: 1 | E2: 2 | F2: 3 | G2: 4 | H2: 5 | I2: 6 | J2: 7 | K2: 8 | L2: 9 | M2: 10 | N2: 11 | O2: 12 | P2: 13 | Q2: 14 | R2: 15 | S2: 16 | T2: 17 | U2: 18 | V2: 19 | W2: 20 | X2: 21 | Y2: 22 | Z2: 23 | AA2: 24
C3: Count | D3: Count | E3: Count | F3: Count | G3: Count | H3: Count | I3: Count | J3: Count | K3: Count | L3: Count | M3: Count | N3: Count | O3: Count | P3: Count | Q3: Count | R3: Count | S3: Count | T3: Count | U3: Count | V3: Count | W3: Count | X3: Count | Y3: Count | Z3: Count | AA3: Count | AC3: Total people | AD3: Total years edu | AE3: Average years of education
A4: MUN | B4: 010101 | C4: 2215 | D4: 766 | E4: 1304 | F4: 2356 | G4: 1885 | H4: 3806 | I4: 2052 | J4: 1720 | K4: 2728 | L4: 1974 | M4: 2044 | N4: 2339 | O4: 18808 | P4: 4551 | Q4: 6543 | R4: 9883 | S4: 3282 | T4: 19755 | U4: 687 | V4: 2965 | W4: 74 | X4: 29 | Y4: 25 | Z4: 395 | AA4: 1179 | AC4: =SUM(C4:AA4) -> 93365 | AD4: =C$2*C4+D$2*D4+E$2*E4+F$2*F4+G$2*G4+H$2*H4+I$2*I4+J$2*J4+K$2*K4+L$2*L4+M$2*M4+N$2*N4+O$2*O4+P$2*P4+Q$2*Q4+R$2*R4+S$2*S4+T$2*T4+U$2*U4+V$2*V4+W$2*W4+X$2*X4+Y$2*Y4+Z$2*Z4+AA$2*AA4 -> 1168897 | AE4: =AD4/AC4 -> 12.519649
B5: 010102 | C5: 166 | D5: 64 | E5: 114 | F5: 236 | G5: 163 | H5: 306 | I5: 119 | J5: 111 | K5: 146 | L5: 88 | M5: 88 | N5: 89 | O5: 601 | P5: 86 | Q5: 130 | R5: 172 | S5: 37 | T5: 289 | U5: 13 | V5: 32 | W5: 1 | X5: 1 | Y5: 0 | Z5: 5 | AA5: 45 | AC5: =SUM(C5:AA5) -> 3102 | AD5: =C$2*C5+D$2*D5+E$2*E5+F$2*F5+G$2*G5+H$2*H5+I$2*I5+J$2*J5+K$2*K5+L$2*L5+M$2*M5+N$2*N5+O$2*O5+P$2*P5+Q$2*Q5+R$2*R5+S$2*S5+T$2*T5+U$2*U5+V$2*V5+W$2*W5+X$2*X5+Y$2*Y5+Z$2*Z5+AA$2*AA5 -> 28805 | AE5: =AD5/AC5 -> 9.2859446
B6: 010103 | C6: 484 | D6: 156 | E6: 401 | F6: 536 | G6: 451 | H6: 592 | I6: 251 | J6: 126 | K6: 184 | L6: 95 | M6: 84 | N6: 85 | O6: 482 | P6: 35 | Q6: 50 | R6: 47 | S6: 8 | T6: 110 | U6: 2 | V6: 8 | W6: 1 | X6: 0 | Y6: 0 | Z6: 0 | AA6: 62 | AC6: =SUM(C6:AA6) -> 4250 | AD6: =C$2*C6+D$2*D6+E$2*E6+F$2*F6+G$2*G6+H$2*H6+I$2*I6+J$2*J6+K$2*K6+L$2*L6+M$2*M6+N$2*N6+O$2*O6+P$2*P6+Q$2*Q6+R$2*R6+S$2*S6+T$2*T6+U$2*U6+V$2*V6+W$2*W6+X$2*X6+Y$2*Y6+Z$2*Z6+AA$2*AA6 -> 25158 | AE6: =AD6/AC6 -> 5.9195294
B7: 010201 | C7: 295 | D7: 79 | E7: 227 | F7: 223 | G7: 181 | H7: 300 | I7: 232 | J7: 63 | K7: 91 | L7: 49 | M7: 42 | N7: 34 | O7: 202 | P7: 20 | Q7: 49 | R7: 81 | S7: 9 | T7: 146 | U7: 4 | V7: 6 | W7: 0 | X7: 0 | Y7: 0 | Z7: 0 | AA7: 100 | AC7: =SUM(C7:AA7) -> 2433 | AD7: =C$2*C7+D$2*D7+E$2*E7+F$2*F7+G$2*G7+H$2*H7+I$2*I7+J$2*J7+K$2*K7+L$2*L7+M$2*M7+N$2*N7+O$2*O7+P$2*P7+Q$2*Q7+R$2*R7+S$2*S7+T$2*T7+U$2*U7+V$2*V7+W$2*W7+X$2*X7+Y$2*Y7+Z$2*Z7+AA$2*AA7 -> 17019 | AE7: =AD7/AC7 -> 6.9950678
B8: 010202 | C8: 867 | D8: 153 | E8: 386 | F8: 429 | G8: 327 | H8: 509 | I8: 216 | J8: 155 | K8: 311 | L8: 134 | M8: 130 | N8: 146 | O8: 704 | P8: 77 | Q8: 134 | R8: 149 | S8: 26 | T8: 206 | U8: 6 | V8: 15 | W8: 0 | X8: 0 | Y8: 1 | Z8: 0 | AA8: 90 | AC8: =SUM(C8:AA8) -> 5171 | AD8: =C$2*C8+D$2*D8+E$2*E8+F$2*F8+G$2*G8+H$2*H8+I$2*I8+J$2*J8+K$2*K8+L$2*L8+M$2*M8+N$2*N8+O$2*O8+P$2*P8+Q$2*Q8+R$2*R8+S$2*S8+T$2*T8+U$2*U8+V$2*V8+W$2*W8+X$2*X8+Y$2*Y8+Z$2*Z8+AA$2*AA8 -> 35099 | AE8: =AD8/AC8 -> 6.787662
B9: 010301 | C9: 369 | D9: 85 | E9: 221 | F9: 360 | G9: 353 | H9: 601 | I9: 418 | J9: 136 | K9: 233 | L9: 114 | M9: 120 | N9: 110 | O9: 827 | P9: 93 | Q9: 157 | R9: 204 | S9: 44 | T9: 323 | U9: 9 | V9: 29 | W9: 0 | X9: 0 | Y9: 0 | Z9: 5 | AA9: 96 | AC9: =SUM(C9:AA9) -> 4907 | AD9: =C$2*C9+D$2*D9+E$2*E9+F$2*F9+G$2*G9+H$2*H9+I$2*I9+J$2*J9+K$2*K9+L$2*L9+M$2*M9+N$2*N9+O$2*O9+P$2*P9+Q$2*Q9+R$2*R9+S$2*S9+T$2*T9+U$2*U9+V$2*V9+W$2*W9+X$2*X9+Y$2*Y9+Z$2*Z9+AA$2*AA9 -> 40502 | AE9: =AD9/AC9 -> 8.253923
B10: 010302 | C10: 830 | D10: 82 | E10: 165 | F10: 280 | G10: 226 | H10: 464 | I10: 296 | J10: 97 | K10: 230 | L10: 85 | M10: 94 | N10: 108 | O10: 657 | P10: 53 | Q10: 91 | R10: 109 | S10: 14 | T10: 140 | U10: 3 | V10: 11 | W10: 0 | X10: 0 | Y10: 0 | Z10: 2 | AA10: 123 | AC10: =SUM(C10:AA10) -> 4160 | AD10: =C$2*C10+D$2*D10+E$2*E10+F$2*F10+G$2*G10+H$2*H10+I$2*I10+J$2*J10+K$2*K10+L$2*L10+M$2*M10+N$2*N10+O$2*O10+P$2*P10+Q$2*Q10+R$2*R10+S$2*S10+T$2*T10+U$2*U10+V$2*V10+W$2*W10+X$2*X10+Y$2*Y10+Z$2*Z10+AA$2*AA10 -> 29011 | AE10: =AD10/AC10 -> 6.9737981
B11: 010303 | C11: 192 | D11: 78 | E11: 159 | F11: 218 | G11: 173 | H11: 324 | I11: 134 | J11: 77 | K11: 183 | L11: 84 | M11: 87 | N11: 84 | O11: 612 | P11: 59 | Q11: 99 | R11: 147 | S11: 34 | T11: 160 | U11: 9 | V11: 7 | W11: 0 | X11: 0 | Y11: 1 | Z11: 1 | AA11: 18 | AC11: =SUM(C11:AA11) -> 2940 | AD11: =C$2*C11+D$2*D11+E$2*E11+F$2*F11+G$2*G11+H$2*H11+I$2*I11+J$2*J11+K$2*K11+L$2*L11+M$2*M11+N$2*N11+O$2*O11+P$2*P11+Q$2*Q11+R$2*R11+S$2*S11+T$2*T11+U$2*U11+V$2*V11+W$2*W11+X$2*X11+Y$2*Y11+Z$2*Z11+AA$2*AA11 -> 24457 | AE11: =AD11/AC11 -> 8.3187075
B12: 010304 | C12: 346 | D12: 91 | E12: 202 | F12: 298 | G12: 195 | H12: 285 | I12: 183 | J12: 118 | K12: 202 | L12: 92 | M12: 74 | N12: 80 | O12: 578 | P12: 34 | Q12: 43 | R12: 66 | S12: 5 | T12: 117 | U12: 4 | V12: 10 | W12: 0 | X12: 0 | Y12: 0 | Z12: 2 | AA12: 94 | AC12: =SUM(C12:AA12) -> 3119 | AD12: =C$2*C12+D$2*D12+E$2*E12+F$2*F12+G$2*G12+H$2*H12+I$2*I12+J$2*J12+K$2*K12+L$2*L12+M$2*M12+N$2*N12+O$2*O12+P$2*P12+Q$2*Q12+R$2*R12+S$2*S12+T$2*T12+U$2*U12+V$2*V12+W$2*W12+X$2*X12+Y$2*Y12+Z$2*Z12+AA$2*AA12 -> 23185 | AE12: =AD12/AC12 -> 7.4334723
B13: 010401 | C13: 205 | D13: 92 | E13: 216 | F13: 338 | G13: 301 | H13: 444 | I13: 177 | J13: 115 | K13: 179 | L13: 60 | M13: 55 | N13: 50 | O13: 297 | P13: 44 | Q13: 95 | R13: 162 | S13: 44 | T13: 287 | U13: 10 | V13: 41 | W13: 1 | X13: 0 | Y13: 1 | Z13: 3 | AA13: 43 | AC13: =SUM(C13:AA13) -> 3260 | AD13: =C$2*C13+D$2*D13+E$2*E13+F$2*F13+G$2*G13+H$2*H13+I$2*I13+J$2*J13+K$2*K13+L$2*L13+M$2*M13+N$2*N13+O$2*O13+P$2*P13+Q$2*Q13+R$2*R13+S$2*S13+T$2*T13+U$2*U13+V$2*V13+W$2*W13+X$2*X13+Y$2*Y13+Z$2*Z13+AA$2*AA13 -> 25482 | AE13: =AD13/AC13 -> 7.8165644
B14: 010402 | C14: 254 | D14: 97 | E14: 234 | F14: 218 | G14: 185 | H14: 306 | I14: 304 | J14: 75 | K14: 104 | L14: 47 | M14: 44 | N14: 52 | O14: 440 | P14: 52 | Q14: 69 | R14: 130 | S14: 15 | T14: 141 | U14: 3 | V14: 9 | W14: 1 | X14: 0 | Y14: 0 | Z14: 3 | AA14: 33 | AC14: =SUM(C14:AA14) -> 2816 | AD14: =C$2*C14+D$2*D14+E$2*E14+F$2*F14+G$2*G14+H$2*H14+I$2*I14+J$2*J14+K$2*K14+L$2*L14+M$2*M14+N$2*N14+O$2*O14+P$2*P14+Q$2*Q14+R$2*R14+S$2*S14+T$2*T14+U$2*U14+V$2*V14+W$2*W14+X$2*X14+Y$2*Y14+Z$2*Z14+AA$2*AA14 -> 20720 | AE14: =AD14/AC14 -> 7.3579545
B15: 010403 | C15: 317 | D15: 65 | E15: 217 | F15: 253 | G15: 183 | H15: 186 | I15: 171 | J15: 77 | K15: 134 | L15: 30 | M15: 37 | N15: 33 | O15: 241 | P15: 31 | Q15: 40 | R15: 60 | S15: 13 | T15: 142 | U15: 4 | V15: 8 | W15: 0 | X15: 0 | Y15: 0 | Z15: 2 | AA15: 25 | AC15: =SUM(C15:AA15) -> 2269 | AD15: =C$2*C15+D$2*D15+E$2*E15+F$2*F15+G$2*G15+H$2*H15+I$2*I15+J$2*J15+K$2*K15+L$2*L15+M$2*M15+N$2*N15+O$2*O15+P$2*P15+Q$2*Q15+R$2*R15+S$2*S15+T$2*T15+U$2*U15+V$2*V15+W$2*W15+X$2*X15+Y$2*Y15+Z$2*Z15+AA$2*AA15 -> 14807 | AE15: =AD15/AC15 -> 6.5257823
B16: 010404 | C16: 85 | D16: 24 | E16: 78 | F16: 98 | G16: 86 | H16: 114 | I16: 45 | J16: 39 | K16: 57 | L16: 26 | M16: 29 | N16: 22 | O16: 210 | P16: 32 | Q16: 53 | R16: 104 | S16: 5 | T16: 169 | U16: 7 | V16: 11 | W16: 0 | X16: 0 | Y16: 0 | Z16: 4 | AA16: 27 | AC16: =SUM(C16:AA16) -> 1325 | AD16: =C$2*C16+D$2*D16+E$2*E16+F$2*F16+G$2*G16+H$2*H16+I$2*I16+J$2*J16+K$2*K16+L$2*L16+M$2*M16+N$2*N16+O$2*O16+P$2*P16+Q$2*Q16+R$2*R16+S$2*S16+T$2*T16+U$2*U16+V$2*V16+W$2*W16+X$2*X16+Y$2*Y16+Z$2*Z16+AA$2*AA16 -> 12419 | AE16: =AD16/AC16 -> 9.3728302
... B346: 090503 | C346: 27 | D346: 8 | E346: 14 | F346: 29 | G346: 32 | H346: 87 | I346: 46 | J346: 46 | K346: 75 | L346: 69 | M346: 52 | N346: 59 | O346: 212 | P346: 18 | Q346: 11 | R346: 18 | S346: 1 | T346: 14 | U346: 0 | V346: 0 | W346: 0 | X346: 0 | Y346: 0 | Z346: 0 | AA346: 49 | AC346: =SUM(C346:AA346) -> 867 | AD346: =C$2*C346+D$2*D346+E$2*E346+F$2*F346+G$2*G346+H$2*H346+I$2*I346+J$2*J346+K$2*K346+L$2*L346+M$2*M346+N$2*N346+O$2*O346+P$2*P346+Q$2*Q346+R$2*R346+S$2*S346+T$2*T346+U$2*U346+V$2*V346+W$2*W346+X$2*X346+Y$2*Y346+Z$2*Z346+AA$2*AA346 -> 8306 | AE346: =AD346/AC346 -> 9.5801615
C347: =SUM(C4:C346) -> 93990 | D347: =SUM(D4:D346) -> 40111 | E347: =SUM(E4:E346) -> 74461 | F347: =SUM(F4:F346) -> 126048 | G347: =SUM(G4:G346) -> 105732 | H347: =SUM(H4:H346) -> 205046 | I347: =SUM(I4:I346) -> 115897 | J347: =SUM(J4:J346) -> 112310 | ... AA347: =SUM(AA4:AA346) -> 64508 | AC347: =SUM(AC4:AC346) -> 3701462 | AD347: =SUM(AD4:AD346) -> 41244186 | AE347: =AD347/AC347 -> 11.142674

Sheet 25-35 all
C1: EDU
C2: 0 | D2: 1 | E2: 2 | F2: 3 | G2: 4 | H2: 5 | I2: 6 | J2: 7 | K2: 8 | L2: 9 | M2: 10 | N2: 11 | O2: 12 | P2: 13 | Q2: 14 | R2: 15 | S2: 16 | T2: 17 | U2: 18 | V2: 19 | W2: 20 | X2: 21 | Y2: 22 | Z2: 23 | AA2: 24
C3: Count | D3: Count | E3: Count | F3: Count | G3: Count | H3: Count | I3: Count | J3: Count | K3: Count | L3: Count | M3: Count | N3: Count | O3: Count | P3: Count | Q3: Count | R3: Count | S3: Count | T3: Count | U3: Count | V3: Count | W3: Count | X3: Count | Y3: Count | Z3: Count | AA3: Count | AC3: Total people | AD3: Total years edu | AE3: Average years of education
A4: MUN | B4: 010101 | C4: 562 | D4: 222 | E4: 310 | F4: 592 | G4: 626 | H4: 1337 | I4: 1223 | J4: 1047 | K4: 1486 | L4: 1020 | M4: 961 | N4: 1052 | O4: 10582 | P4: 2404 | Q4: 3802 | R4: 6641 | S4: 3013 | T4: 17536 | U4: 417 | V4: 1342 | W4: 24 | X4: 10 | Y4: 6 | Z4: 49 | AA4: 685 | AC4: =SUM(C4:AA4) -> 56949 | AD4: =C$2*C4+D$2*D4+E$2*E4+F$2*F4+G$2*G4+H$2*H4+I$2*I4+J$2*J4+K$2*K4+L$2*L4+M$2*M4+N$2*N4+O$2*O4+P$2*P4+Q$2*Q4+R$2*R4+S$2*S4+T$2*T4+U$2*U4+V$2*V4+W$2*W4+X$2*X4+Y$2*Y4+Z$2*Z4+AA$2*AA4 -> 777516 | AE4: =AD4/AC4 -> 13.652847
B5: 010102 | C5: 23 | D5: 8 | E5: 7 | F5: 13 | G5: 16 | H5: 43 | I5: 54 | J5: 46 | K5: 84 | L5: 37 | M5: 48 | N5: 49 | O5: 382 | P5: 61 | Q5: 82 | R5: 128 | S5: 38 | T5: 278 | U5: 5 | V5: 17 | W5: 0 | X5: 0 | Y5: 0 | Z5: 2 | AA5: 17 | AC5: =SUM(C5:AA5) -> 1438 | AD5: =C$2*C5+D$2*D5+E$2*E5+F$2*F5+G$2*G5+H$2*H5+I$2*I5+J$2*J5+K$2*K5+L$2*L5+M$2*M5+N$2*N5+O$2*O5+P$2*P5+Q$2*Q5+R$2*R5+S$2*S5+T$2*T5+U$2*U5+V$2*V5+W$2*W5+X$2*X5+Y$2*Y5+Z$2*Z5+AA$2*AA5 -> 17656 | AE5: =AD5/AC5 -> 12.278164
B6: 010103 | C6: 53 | D6: 17 | E6: 46 | F6: 88 | G6: 75 | H6: 183 | I6: 184 | J6: 89 | K6: 150 | L6: 46 | M6: 54 | N6: 36 | O6: 313 | P6: 18 | Q6: 30 | R6: 34 | S6: 7 | T6: 100 | U6: 0 | V6: 5 | W6: 0 | X6: 0 | Y6: 0 | Z6: 0 | AA6: 33 | AC6: =SUM(C6:AA6) -> 1561 | AD6: =C$2*C6+D$2*D6+E$2*E6+F$2*F6+G$2*G6+H$2*H6+I$2*I6+J$2*J6+K$2*K6+L$2*L6+M$2*M6+N$2*N6+O$2*O6+P$2*P6+Q$2*Q6+R$2*R6+S$2*S6+T$2*T6+U$2*U6+V$2*V6+W$2*W6+X$2*X6+Y$2*Y6+Z$2*Z6+AA$2*AA6 -> 13484 | AE6: =AD6/AC6 -> 8.6380525
B7: 010201 | C7: 26 | D7: 7 | E7: 16 | F7: 41 | G7: 38 | H7: 108 | I7: 170 | J7: 32 | K7: 65 | L7: 28 | M7: 16 | N7: 14 | O7: 123 | P7: 15 | Q7: 42 | R7: 60 | S7: 2 | T7: 114 | U7: 3 | V7: 2 | W7: 0 | X7: 0 | Y7: 0 | Z7: 0 | AA7: 49 | AC7: =SUM(C7:AA7) -> 971 | AD7: =C$2*C7+D$2*D7+E$2*E7+F$2*F7+G$2*G7+H$2*H7+I$2*I7+J$2*J7+K$2*K7+L$2*L7+M$2*M7+N$2*N7+O$2*O7+P$2*P7+Q$2*Q7+R$2*R7+S$2*S7+T$2*T7+U$2*U7+V$2*V7+W$2*W7+X$2*X7+Y$2*Y7+Z$2*Z7+AA$2*AA7 -> 9581 | AE7: =AD7/AC7 -> 9.8671473
B8: 010202 | C8: 122 | D8: 20 | E8: 64 | F8: 81 | G8: 104 | H8: 235 | I8: 150 | J8: 119 | K8: 229 | L8: 104 | M8: 103 | N8: 91 | O8: 507 | P8: 48 | Q8: 106 | R8: 112 | S8: 30 | T8: 214 | U8: 4 | V8: 8 | W8: 0 | X8: 0 | Y8: 0 | Z8: 0 | AA8: 58 | AC8: =SUM(C8:AA8) -> 2509 | AD8: =C$2*C8+D$2*D8+E$2*E8+F$2*F8+G$2*G8+H$2*H8+I$2*I8+J$2*J8+K$2*K8+L$2*L8+M$2*M8+N$2*N8+O$2*O8+P$2*P8+Q$2*Q8+R$2*R8+S$2*S8+T$2*T8+U$2*U8+V$2*V8+W$2*W8+X$2*X8+Y$2*Y8+Z$2*Z8+AA$2*AA8 -> 24120 | AE8: =AD8/AC8 -> 9.6133918
B9: 010301 | C9: 24 | D9: 18 | E9: 32 | F9: 92 | G9: 117 | H9: 241 | I9: 333 | J9: 78 | K9: 170 | L9: 70 | M9: 91 | N9: 60 | O9: 577 | P9: 68 | Q9: 104 | R9: 163 | S9: 34 | T9: 307 | U9: 4 | V9: 18 | W9: 1 | X9: 0 | Y9: 0 | Z9: 5 | AA9: 46 | AC9: =SUM(C9:AA9) -> 2653 | AD9: =C$2*C9+D$2*D9+E$2*E9+F$2*F9+G$2*G9+H$2*H9+I$2*I9+J$2*J9+K$2*K9+L$2*L9+M$2*M9+N$2*N9+O$2*O9+P$2*P9+Q$2*Q9+R$2*R9+S$2*S9+T$2*T9+U$2*U9+V$2*V9+W$2*W9+X$2*X9+Y$2*Y9+Z$2*Z9+AA$2*AA9 -> 27260 | AE9: =AD9/AC9 -> 10.27516
B10: 010302 | C10: 124 | D10: 15 | E10: 36 | F10: 94 | G10: 118 | H10: 246 | I10: 224 | J10: 84 | K10: 154 | L10: 84 | M10: 89 | N10: 75 | O10: 477 | P10: 19 | Q10: 63 | R10: 80 | S10: 15 | T10: 120 | U10: 2 | V10: 8 | W10: 1 | X10: 1 | Y10: 0 | Z10: 1 | AA10: 57 | AC10: =SUM(C10:AA10) -> 2187 | AD10: =C$2*C10+D$2*D10+E$2*E10+F$2*F10+G$2*G10+H$2*H10+I$2*I10+J$2*J10+K$2*K10+L$2*L10+M$2*M10+N$2*N10+O$2*O10+P$2*P10+Q$2*Q10+R$2*R10+S$2*S10+T$2*T10+U$2*U10+V$2*V10+W$2*W10+X$2*X10+Y$2*Y10+Z$2*Z10+AA$2*AA10 -> 19659 | AE10: =AD10/AC10 -> 8.9890261
B11: 010303 | C11: 26 | D11: 17 | E11: 32 | F11: 52 | G11: 50 | H11: 121 | I11: 85 | J11: 65 | K11: 115 | L11: 62 | M11: 74 | N11: 66 | O11: 474 | P11: 35 | Q11: 81 | R11: 152 | S11: 30 | T11: 143 | U11: 4 | V11: 4 | W11: 0 | X11: 0 | Y11: 0 | Z11: 1 | AA11: 20 | AC11: =SUM(C11:AA11) -> 1709 | AD11: =C$2*C11+D$2*D11+E$2*E11+F$2*F11+G$2*G11+H$2*H11+I$2*I11+J$2*J11+K$2*K11+L$2*L11+M$2*M11+N$2*N11+O$2*O11+P$2*P11+Q$2*Q11+R$2*R11+S$2*S11+T$2*T11+U$2*U11+V$2*V11+W$2*W11+X$2*X11+Y$2*Y11+Z$2*Z11+AA$2*AA11 -> 18070 | AE11: =AD11/AC11 -> 10.573435
B12: 010304 | C12: 45 | D12: 10 | E12: 19 | F12: 41 | G12: 41 | H12: 97 | I12: 111 | J12: 83 | K12: 158 | L12: 56 | M12: 39 | N12: 52 | O12: 443 | P12: 22 | Q12: 31 | R12: 56 | S12: 11 | T12: 129 | U12: 1 | V12: 7 | W12: 0 | X12: 0 | Y12: 0 | Z12: 2 | AA12: 55 | AC12: =SUM(C12:AA12) -> 1509 | AD12: =C$2*C12+D$2*D12+E$2*E12+F$2*F12+G$2*G12+H$2*H12+I$2*I12+J$2*J12+K$2*K12+L$2*L12+M$2*M12+N$2*N12+O$2*O12+P$2*P12+Q$2*Q12+R$2*R12+S$2*S12+T$2*T12+U$2*U12+V$2*V12+W$2*W12+X$2*X12+Y$2*Y12+Z$2*Z12+AA$2*AA12 -> 15559 | AE12: =AD12/AC12 -> 10.310802
B13: 010401 | C13: 17 | D13: 14 | E13: 16 | F13: 40 | G13: 46 | H13: 119 | I13: 126 | J13: 62 | K13: 116 | L13: 28 | M13: 21 | N13: 28 | O13: 190 | P13: 35 | Q13: 56 | R13: 86 | S13: 52 | T13: 251 | U13: 5 | V13: 6 | W13: 0 | X13: 0 | Y13: 1 | Z13: 1 | AA13: 14 | AC13: =SUM(C13:AA13) -> 1330 | AD13: =C$2*C13+D$2*D13+E$2*E13+F$2*F13+G$2*G13+H$2*H13+I$2*I13+J$2*J13+K$2*K13+L$2*L13+M$2*M13+N$2*N13+O$2*O13+P$2*P13+Q$2*Q13+R$2*R13+S$2*S13+T$2*T13+U$2*U13+V$2*V13+W$2*W13+X$2*X13+Y$2*Y13+Z$2*Z13+AA$2*AA13 -> 14326 | AE13: =AD13/AC13 -> 10.771429
B14: 010402 | C14: 27 | D14: 11 | E14: 24 | F14: 27 | G14: 52 | H14: 100 | I14: 273 | J14: 60 | K14: 88 | L14: 25 | M14: 35 | N14: 29 | O14: 306 | P14: 27 | Q14: 35 | R14: 105 | S14: 11 | T14: 144 | U14: 4 | V14: 9 | W14: 1 | X14: 0 | Y14: 0 | Z14: 2 | AA14: 19 | AC14: =SUM(C14:AA14) -> 1414 | AD14: =C$2*C14+D$2*D14+E$2*E14+F$2*F14+G$2*G14+H$2*H14+I$2*I14+J$2*J14+K$2*K14+L$2*L14+M$2*M14+N$2*N14+O$2*O14+P$2*P14+Q$2*Q14+R$2*R14+S$2*S14+T$2*T14+U$2*U14+V$2*V14+W$2*W14+X$2*X14+Y$2*Y14+Z$2*Z14+AA$2*AA14 -> 13981 | AE14: =AD14/AC14 -> 9.887553
B15: 010403 | C15: 19 | D15: 3 | E15: 26 | F15: 44 | G15: 57 | H15: 89 | I15: 140 | J15: 43 | K15: 105 | L15: 20 | M15: 22 | N15: 14 | O15: 164 | P15: 8 | Q15: 30 | R15: 59 | S15: 9 | T15: 105 | U15: 5 | V15: 8 | W15: 0 | X15: 0 | Y15: 0 | Z15: 1 | AA15: 11 | AC15: =SUM(C15:AA15) -> 982 | AD15: =C$2*C15+D$2*D15+E$2*E15+F$2*F15+G$2*G15+H$2*H15+I$2*I15+J$2*J15+K$2*K15+L$2*L15+M$2*M15+N$2*N15+O$2*O15+P$2*P15+Q$2*Q15+R$2*R15+S$2*S15+T$2*T15+U$2*U15+V$2*V15+W$2*W15+X$2*X15+Y$2*Y15+Z$2*Z15+AA$2*AA15 -> 9230 | AE15: =AD15/AC15 -> 9.3991853
B16: 010404 | C16: 8 | D16: 0 | E16: 6 | F16: 5 | G16: 8 | H16: 17 | I16: 24 | J16: 28 | K16: 46 | L16: 12 | M16: 15 | N16: 12 | O16: 128 | P16: 13 | Q16: 31 | R16: 104 | S16: 12 | T16: 152 | U16: 2 | V16: 8 | W16: 1 | X16: 0 | Y16: 0 | Z16: 0 | AA16: 11 | AC16: =SUM(C16:AA16) -> 643 | AD16: =C$2*C16+D$2*D16+E$2*E16+F$2*F16+G$2*G16+H$2*H16+I$2*I16+J$2*J16+K$2*K16+L$2*L16+M$2*M16+N$2*N16+O$2*O16+P$2*P16+Q$2*Q16+R$2*R16+S$2*S16+T$2*T16+U$2*U16+V$2*V16+W$2*W16+X$2*X16+Y$2*Y16+Z$2*Z16+AA$2*AA16 -> 8189 | AE16: =AD16/AC16 -> 12.735614
... B346: 090503 | C346: 7 | D346: 1 | E346: 1 | F346: 6 | G346: 5 | H346: 23 | I346: 22 | J346: 20 | K346: 41 | L346: 41 | M346: 32 | N346: 32 | O346: 124 | P346: 7 | Q346: 6 | R346: 10 | S346: 0 | T346: 11 | U346: 0 | V346: 0 | W346: 0 | X346: 0 | Y346: 0 | Z346: 1 | AA346: 38 | AC346: =SUM(C346:AA346) -> 428 | AD346: =C$2*C346+D$2*D346+E$2*E346+F$2*F346+G$2*G346+H$2*H346+I$2*I346+J$2*J346+K$2*K346+L$2*L346+M$2*M346+N$2*N346+O$2*O346+P$2*P346+Q$2*Q346+R$2*R346+S$2*S346+T$2*T346+U$2*U346+V$2*V346+W$2*W346+X$2*X346+Y$2*Y346+Z$2*Z346+AA$2*AA346 -> 4732 | AE346: =AD346/AC346 -> 11.056075
C347: =SUM(C4:C346) -> 22352 | D347: =SUM(D4:D346) -> 9489 | E347: =SUM(E4:E346) -> 12561 | F347: =SUM(F4:F346) -> 25120 | G347: =SUM(G4:G346) -> 27246 | H347: =SUM(H4:H346) -> 59969 | I347: =SUM(I4:I346) -> 56648 | J347: =SUM(J4:J346) -> 59392 | ... AA347: =SUM(AA4:AA346) -> 35390 | AC347: =SUM(AC4:AC346) -> 2087276 | AD347: =SUM(AD4:AD346) -> 26104100 | AE347: =AD347/AC347 -> 12.5063

Sheet 25-35 female_2012
C1: EDU
C2: 0 | D2: 1 | E2: 2 | F2: 3 | G2: 4 | H2: 5 | I2: 6 | J2: 7 | K2: 8 | L2: 9 | M2: 10 | N2: 11 | O2: 12 | P2: 13 | Q2: 14 | R2: 15 | S2: 16 | T2: 17 | U2: 18 | V2: 19 | W2: 20 | X2: 21 | Y2: 22 | Z2: 23
C3: Count | D3: Count | E3: Count | F3: Count | G3: Count | H3: Count | I3: Count | J3: Count | K3: Count | L3: Count | M3: Count | N3: Count | O3: Count | P3: Count | Q3: Count | R3: Count | S3: Count | T3: Count | U3: Count | V3: Count | W3: Count | X3: Count | Y3: Count | Z3: Count | AB3: Total people | AC3: Total years edu | AD3: Average years of education | AF3: Departamento | AG3: Población de mujeres de 25-35 años | AH3: Total años de educación de mujeres de 25-35 años | AI3: Promedio de años de educación
A4: MUN | B4: 010101 | C4: 997 | D4: 502 | E4: 700 | F4: 883 | G4: 898 | H4: 1310 | I4: 767 | J4: 489 | K4: 602 | L4: 653 | M4: 748 | N4: 696 | O4: 2729 | P4: 382 | Q4: 629 | R4: 1970 | S4: 2830 | T4: 4696 | U4: 247 | V4: 313 | W4: 34 | X4: 21 | Y4: 7 | Z4: 10 | AB4: =SUM(C4:Z4) -> 23113 | AC4: =C$2*C4+D$2*D4+E$2*E4+F$2*F4+G$2*G4+H$2*H4+I$2*I4+J$2*J4+K$2*K4+L$2*L4+M$2*M4+N$2*N4+O$2*O4+P$2*P4+Q$2*Q4+R$2*R4+S$2*S4+T$2*T4+U$2*U4+V$2*V4+W$2*W4+X$2*X4+Y$2*Y4+Z$2*Z4 -> 261627 | AD4: =AC4/AB4 -> 11.319474 | AF4: Chuquisaca | AG4: =+SUM(AB4:AB32) -> 43867 | AH4: =+SUM(AC4:AC32) -> 398980 | AI4: =+AH4/AG4 -> 9.0952196
B5: 010102 | C5: 36 | D5: 28 | E5: 29 | F5: 41 | G5: 49 | H5: 81 | I5: 34 | J5: 21 | K5: 33 | L5: 31 | M5: 23 | N5: 18 | O5: 72 | P5: 6 | Q5: 10 | R5: 24 | S5: 42 | T5: 38 | U5: 0 | V5: 3 | W5: 0 | X5: 0 | Y5: 0 | Z5: 0 | AB5: =SUM(C5:Z5) -> 619 | AC5: =C$2*C5+D$2*D5+E$2*E5+F$2*F5+G$2*G5+H$2*H5+I$2*I5+J$2*J5+K$2*K5+L$2*L5+M$2*M5+N$2*N5+O$2*O5+P$2*P5+Q$2*Q5+R$2*R5+S$2*S5+T$2*T5+U$2*U5+V$2*V5+W$2*W5+X$2*X5+Y$2*Y5+Z$2*Z5 -> 4949 | AD5: =AC5/AB5 -> 7.9951535 | AF5: La Paz | AG5: =+SUM(AB33:AB119) -> 235678 | AH5: =+SUM(AC33:AC119) -> 2499635 | AI5: =+AH5/AG5 -> 10.606145
B6: 010103 | C6: 206 | D6: 81 | E6: 122 | F6: 152 | G6: 139 | H6: 112 | I6: 80 | J6: 26 | K6: 39 | L6: 7 | M6: 12 | N6: 9 | O6: 29 | P6: 5 | Q6: 10 | R6: 11 | S6: 18 | T6: 17 | U6: 0 | V6: 0 | W6: 0 | X6: 0 | Y6: 0 | Z6: 0 | AB6: =SUM(C6:Z6) -> 1075 | AC6: =C$2*C6+D$2*D6+E$2*E6+F$2*F6+G$2*G6+H$2*H6+I$2*I6+J$2*J6+K$2*K6+L$2*L6+M$2*M6+N$2*N6+O$2*O6+P$2*P6+Q$2*Q6+R$2*R6+S$2*S6+T$2*T6+U$2*U6+V$2*V6+W$2*W6+X$2*X6+Y$2*Y6+Z$2*Z6 -> 4448 | AD6: =AC6/AB6 -> 4.1376744 | AF6: Cochabamba | AG6: =+SUM(AB120:AB166) -> 147163 | AH6: =+SUM(AC120:AC166) -> 1440012 | AI6: =+AH6/AG6 -> 9.7851498
B7: 010201 | C7: 139 | D7: 41 | E7: 56 | F7: 71 | G7: 61 | H7: 97 | I7: 41 | J7: 15 | K7: 18 | L7: 10 | M7: 4 | N7: 11 | O7: 22 | P7: 4 | Q7: 11 | R7: 27 | S7: 14 | T7: 26 | U7: 0 | V7: 2 | W7: 1 | X7: 0 | Y7: 0 | Z7: 0 | AB7: =SUM(C7:Z7) -> 671 | AC7: =C$2*C7+D$2*D7+E$2*E7+F$2*F7+G$2*G7+H$2*H7+I$2*I7+J$2*J7+K$2*K7+L$2*L7+M$2*M7+N$2*N7+O$2*O7+P$2*P7+Q$2*Q7+R$2*R7+S$2*S7+T$2*T7+U$2*U7+V$2*V7+W$2*W7+X$2*X7+Y$2*Y7+Z$2*Z7 -> 3440 | AD7: =AC7/AB7 -> 5.1266766 | AF7: Oruro | AG7: =+SUM(AB167:AB201) -> 43066 | AH7: =+SUM(AC167:AC201) -> 473031 | AI7: =+AH7/AG7 -> 10.983862
B8: 010202 | C8: 197 | D8: 51 | E8: 57 | F8: 70 | G8: 63 | H8: 58 | I8: 48 | J8: 19 | K8: 23 | L8: 11 | M8: 5 | N8: 8 | O8: 19 | P8: 7 | Q8: 9 | R8: 35 | S8: 27 | T8: 36 | U8: 0 | V8: 0 | W8: 0 | X8: 0 | Y8: 0 | Z8: 0 | AB8: =SUM(C8:Z8) -> 743 | AC8: =C$2*C8+D$2*D8+E$2*E8+F$2*F8+G$2*G8+H$2*H8+I$2*I8+J$2*J8+K$2*K8+L$2*L8+M$2*M8+N$2*N8+O$2*O8+P$2*P8+Q$2*Q8+R$2*R8+S$2*S8+T$2*T8+U$2*U8+V$2*V8+W$2*W8+X$2*X8+Y$2*Y8+Z$2*Z8 -> 3773 | AD8: =AC8/AB8 -> 5.0780619 | AF8: Potosi | AG8: =+SUM(AB202:AB241) -> 59635 | AH8: =+SUM(AC202:AC241) -> 521379 | AI8: =+AH8/AG8 -> 8.7428356
B9: 010301 | C9: 84 | D9: 40 | E9: 69 | F9: 81 | G9: 67 | H9: 111 | I9: 33 | J9: 24 | K9: 28 | L9: 22 | M9: 21 | N9: 10 | O9: 68 | P9: 11 | Q9: 9 | R9: 40 | S9: 46 | T9: 59 | U9: 1 | V9: 1 | W9: 2 | X9: 0 | Y9: 0 | Z9: 0 | AB9: =SUM(C9:Z9) -> 827 | AC9: =C$2*C9+D$2*D9+E$2*E9+F$2*F9+G$2*G9+H$2*H9+I$2*I9+J$2*J9+K$2*K9+L$2*L9+M$2*M9+N$2*N9+O$2*O9+P$2*P9+Q$2*Q9+R$2*R9+S$2*S9+T$2*T9+U$2*U9+V$2*V9+W$2*W9+X$2*X9+Y$2*Y9+Z$2*Z9 -> 5853 | AD9: =AC9/AB9 -> 7.0773881 | AF9: Tarija | AG9: =+SUM(AB242:AB252) -> 42113 | AH9: =+SUM(AC242:AC252) -> 430568 | AI9: =+AH9/AG9 -> 10.224111
B10: 010302 | C10: 220 | D10: 56 | E10: 62 | F10: 79 | G10: 80 | H10: 118 | I10: 41 | J10: 37 | K10: 43 | L10: 19 | M10: 12 | N10: 22 | O10: 51 | P10: 2 | Q10: 6 | R10: 33 | S10: 41 | T10: 33 | U10: 0 | V10: 1 | W10: 0 | X10: 0 | Y10: 0 | Z10: 0 | AB10: =SUM(C10:Z10) -> 956 | AC10: =C$2*C10+D$2*D10+E$2*E10+F$2*F10+G$2*G10+H$2*H10+I$2*I10+J$2*J10+K$2*K10+L$2*L10+M$2*M10+N$2*N10+O$2*O10+P$2*P10+Q$2*Q10+R$2*R10+S$2*S10+T$2*T10+U$2*U10+V$2*V10+W$2*W10+X$2*X10+Y$2*Y10+Z$2*Z10 -> 5162 | AD10: =AC10/AB10 -> 5.3995816 | AF10: Santa Cruz | AG10: =+SUM(AB253:AB308) -> 231498 | AH10: =+SUM(AC253:AC308) -> 2408673 | AI10: =+AH10/AG10 -> 10.404725
B11: 010303 | C11: 62 | D11: 23 | E11: 25 | F11: 33 | G11: 48 | H11: 69 | I11: 40 | J11: 17 | K11: 31 | L11: 8 | M11: 13 | N11: 16 | O11: 36 | P11: 5 | Q11: 1 | R11: 23 | S11: 18 | T11: 16 | U11: 0 | V11: 0 | W11: 0 | X11: 0 | Y11: 0 | Z11: 0 | AB11: =SUM(C11:Z11) -> 484 | AC11: =C$2*C11+D$2*D11+E$2*E11+F$2*F11+G$2*G11+H$2*H11+I$2*I11+J$2*J11+K$2*K11+L$2*L11+M$2*M11+N$2*N11+O$2*O11+P$2*P11+Q$2*Q11+R$2*R11+S$2*S11+T$2*T11+U$2*U11+V$2*V11+W$2*W11+X$2*X11+Y$2*Y11+Z$2*Z11 -> 3110 | AD11: =AC11/AB11 -> 6.4256198 | AF11: Beni | AG11: =+SUM(AB309:AB327) -> 32557 | AH11: =+SUM(AC309:AC327) -> 327073 | AI11: =+AH11/AG11 -> 10.046165
B12: 010304 | C12: 87 | D12: 27 | E12: 31 | F12: 33 | G12: 36 | H12: 53 | I12: 22 | J12: 14 | K12: 27 | L12: 8 | M12: 8 | N12: 9 | O12: 21 | P12: 1 | Q12: 3 | R12: 15 | S12: 21 | T12: 19 | U12: 1 | V12: 1 | W12: 0 | X12: 0 | Y12: 0 | Z12: 0 | AB12: =SUM(C12:Z12) -> 437 | AC12: =C$2*C12+D$2*D12+E$2*E12+F$2*F12+G$2*G12+H$2*H12+I$2*I12+J$2*J12+K$2*K12+L$2*L12+M$2*M12+N$2*N12+O$2*O12+P$2*P12+Q$2*Q12+R$2*R12+S$2*S12+T$2*T12+U$2*U12+V$2*V12+W$2*W12+X$2*X12+Y$2*Y12+Z$2*Z12 -> 2522 | AD12: =AC12/AB12 -> 5.771167 | AF12: Pando | AG12: =+SUM(AB328:AB342) -> 9114 | AH12: =+SUM(AC328:AC342) -> 90040 | AI12: =+AH12/AG12 -> 9.8793066
B13: 010401 | C13: 53 | D13: 36 | E13: 48 | F13: 60 | G13: 72 | H13: 114 | I13: 38 | J13: 17 | K13: 31 | L13: 16 | M13: 17 | N13: 14 | O13: 32 | P13: 6 | Q13: 15 | R13: 50 | S13: 33 | T13: 52 | U13: 0 | V13: 1 | W13: 0 | X13: 0 | Y13: 0 | Z13: 0 | AB13: =SUM(C13:Z13) -> 705 | AC13: =C$2*C13+D$2*D13+E$2*E13+F$2*F13+G$2*G13+H$2*H13+I$2*I13+J$2*J13+K$2*K13+L$2*L13+M$2*M13+N$2*N13+O$2*O13+P$2*P13+Q$2*Q13+R$2*R13+S$2*S13+T$2*T13+U$2*U13+V$2*V13+W$2*W13+X$2*X13+Y$2*Y13+Z$2*Z13 -> 5086 | AD13: =AC13/AB13 -> 7.2141844 | AF13: Bolivia | AG13: =SUM(AG4:AG12) -> 844691 | AH13: =SUM(AH4:AH12) -> 8589391 | AI13: =+AH13/AG13 -> 10.168678
B14: 010402 | C14: 118 | D14: 22 | E14: 39 | F14: 48 | G14: 55 | H14: 65 | I14: 32 | J14: 24 | K14: 15 | L14: 8 | M14: 12 | N14: 8 | O14: 25 | P14: 4 | Q14: 3 | R14: 34 | S14: 21 | T14: 25 | U14: 0 | V14: 0 | W14: 0 | X14: 1 | Y14: 0 | Z14: 0 | AB14: =SUM(C14:Z14) -> 559 | AC14: =C$2*C14+D$2*D14+E$2*E14+F$2*F14+G$2*G14+H$2*H14+I$2*I14+J$2*J14+K$2*K14+L$2*L14+M$2*M14+N$2*N14+O$2*O14+P$2*P14+Q$2*Q14+R$2*R14+S$2*S14+T$2*T14+U$2*U14+V$2*V14+W$2*W14+X$2*X14+Y$2*Y14+Z$2*Z14 -> 3235 | AD14: =AC14/AB14 -> 5.7871199 | AF14: Gran Chaco | AG14: =SUM(AB245:AB247) -> 12425 | AH14: =SUM(AC245:AC247) -> 119838 | AI14: =+AH14/AG14 -> 9.6449095
B15: 010403 | C15: 105 | D15: 29 | E15: 51 | F15: 49 | G15: 34 | H15: 43 | I15: 24 | J15: 12 | K15: 26 | L15: 7 | M15: 7 | N15: 8 | O15: 14 | P15: 8 | Q15: 6 | R15: 15 | S15: 29 | T15: 28 | U15: 0 | V15: 1 | W15: 0 | X15: 0 | Y15: 0 | Z15: 1 | AB15: =SUM(C15:Z15) -> 497 | AC15: =C$2*C15+D$2*D15+E$2*E15+F$2*F15+G$2*G15+H$2*H15+I$2*I15+J$2*J15+K$2*K15+L$2*L15+M$2*M15+N$2*N15+O$2*O15+P$2*P15+Q$2*Q15+R$2*R15+S$2*S15+T$2*T15+U$2*U15+V$2*V15+W$2*W15+X$2*X15+Y$2*Y15+Z$2*Z15 -> 2849 | AD15: =AC15/AB15 -> 5.7323944
B16: 010404 | C16: 30 | D16: 16 | E16: 21 | F16: 38 | G16: 20 | H16: 40 | I16: 26 | J16: 12 | K16: 15 | L16: 11 | M16: 11 | N16: 13 | O16: 52 | P16: 7 | Q16: 6 | R16: 22 | S16: 34 | T16: 43 | U16: 0 | V16: 3 | W16: 1 | X16: 0 | Y16: 0 | Z16: 0 | AB16: =SUM(C16:Z16) -> 421 | AC16: =C$2*C16+D$2*D16+E$2*E16+F$2*F16+G$2*G16+H$2*H16+I$2*I16+J$2*J16+K$2*K16+L$2*L16+M$2*M16+N$2*N16+O$2*O16+P$2*P16+Q$2*Q16+R$2*R16+S$2*S16+T$2*T16+U$2*U16+V$2*V16+W$2*W16+X$2*X16+Y$2*Y16+Z$2*Z16 -> 3645 | AD16: =AC16/AB16 -> 8.6579572
B17: 010405 | C17: 40 | D17: 13 | E17: 14 | F17: 34 | G17: 25 | H17: 30 | I17: 17 | J17: 9 | K17: 12 | L17: 11 | M17: 10 | N17: 10 | O17: 36 | P17: 0 | Q17: 6 | R17: 13 | S17: 14 | T17: 13 | U17: 0 | V17: 0 | W17: 0 | X17: 0 | Y17: 0 | Z17: 0 | AB17: =SUM(C17:Z17) -> 307 | AC17: =C$2*C17+D$2*D17+E$2*E17+F$2*F17+G$2*G17+H$2*H17+I$2*I17+J$2*J17+K$2*K17+L$2*L17+M$2*M17+N$2*N17+O$2*O17+P$2*P17+Q$2*Q17+R$2*R17+S$2*S17+T$2*T17+U$2*U17+V$2*V17+W$2*W17+X$2*X17+Y$2*Y17+Z$2*Z17 -> 2119 | AD17: =AC17/AB17 -> 6.9022801
B18: 010501 | C18: 128 | D18: 42 | E18: 77 | F18: 93 | G18: 100 | H18: 168 | I18: 95 | J18: 70 | K18: 76 | L18: 51 | M18: 64 | N18: 58 | O18: 210 | P18: 26 | Q18: 27 | R18: 105 | S18: 143 | T18: 130 | U18: 5 | V18: 8 | W18: 0 | X18: 0 | Y18: 0 | Z18: 0 | AB18: =SUM(C18:Z18) -> 1676 | AC18: =C$2*C18+D$2*D18+E$2*E18+F$2*F18+G$2*G18+H$2*H18+I$2*I18+J$2*J18+K$2*K18+L$2*L18+M$2*M18+N$2*N18+O$2*O18+P$2*P18+Q$2*Q18+R$2*R18+S$2*S18+T$2*T18+U$2*U18+V$2*V18+W$2*W18+X$2*X18+Y$2*Y18+Z$2*Z18 -> 14671 | AD18: =AC18/AB18 -> 8.75358
B19: 010502 | C19: 55 | D19: 18 | E19: 44 | F19: 43 | G19: 28 | H19: 50 | I19: 35 | J19: 17 | K19: 32 | L19: 15 | M19: 20 | N19: 17 | O19: 61 | P19: 6 | Q19: 7 | R19: 29 | S19: 25 | T19: 18 | U19: 1 | V19: 0 | W19: 0 | X19: 0 | Y19: 0 | Z19: 0 | AB19: =SUM(C19:Z19) -> 521 | AC19: =C$2*C19+D$2*D19+E$2*E19+F$2*F19+G$2*G19+H$2*H19+I$2*I19+J$2*J19+K$2*K19+L$2*L19+M$2*M19+N$2*N19+O$2*O19+P$2*P19+Q$2*Q19+R$2*R19+S$2*S19+T$2*T19+U$2*U19+V$2*V19+W$2*W19+X$2*X19+Y$2*Y19+Z$2*Z19 -> 3771 | AD19: =AC19/AB19 -> 7.2380038
B20: 010601 | C20: 185 | D20: 42 | E20: 67 | F20: 83 | G20: 80 | H20: 108 | I20: 51 | J20: 27 | K20: 37 | L20: 12 | M20: 10 | N20: 16 | O20: 31 | P20: 9 | Q20: 11 | R20: 47 | S20: 29 | T20: 33 | U20: 2 | V20: 2 | W20: 0 | X20: 0 | Y20: 0 | Z20: 0 | AB20: =SUM(C20:Z20) -> 882 | AC20: =C$2*C20+D$2*D20+E$2*E20+F$2*F20+G$2*G20+H$2*H20+I$2*I20+J$2*J20+K$2*K20+L$2*L20+M$2*M20+N$2*N20+O$2*O20+P$2*P20+Q$2*Q20+R$2*R20+S$2*S20+T$2*T20+U$2*U20+V$2*V20+W$2*W20+X$2*X20+Y$2*Y20+Z$2*Z20 -> 4907 | AD20: =AC20/AB20 -> 5.5634921
B21: 010602 | C21: 46 | D21: 21 | E21: 31 | F21: 46 | G21: 66 | H21: 107 | I21: 43 | J21: 31 | K21: 27 | L21: 10 | M21: 9 | N21: 9 | O21: 33 | P21: 3 | Q21: 6 | R21: 27 | S21: 28 | T21: 35 | U21: 2 | V21: 1 | W21: 1 | X21: 1 | Y21: 1 | Z21: 0 | AB21: =SUM(C21:Z21) -> 584 | AC21: =C$2*C21+D$2*D21+E$2*E21+F$2*F21+G$2*G21+H$2*H21+I$2*I21+J$2*J21+K$2*K21+L$2*L21+M$2*M21+N$2*N21+O$2*O21+P$2*P21+Q$2*Q21+R$2*R21+S$2*S21+T$2*T21+U$2*U21+V$2*V21+W$2*W21+X$2*X21+Y$2*Y21+Z$2*Z21 -> 4075 | AD21: =AC21/AB21 -> 6.9777397
B22: 010701 | C22: 59 | D22: 54 | E22: 52 | F22: 63 | G22: 87 | H22: 179 | I22: 42 | J22: 37 | K22: 50 | L22: 30 | M22: 36 | N22: 29 | O22: 167 | P22: 15 | Q22: 23 | R22: 64 | S22: 68 | T22: 81 | U22: 1 | V22: 7 | W22: 2 | X22: 0 | Y22: 0 | Z22: 0 | AB22: =SUM(C22:Z22) -> 1146 | AC22: =C$2*C22+D$2*D22+E$2*E22+F$2*F22+G$2*G22+H$2*H22+I$2*I22+J$2*J22+K$2*K22+L$2*L22+M$2*M22+N$2*N22+O$2*O22+P$2*P22+Q$2*Q22+R$2*R22+S$2*S22+T$2*T22+U$2*U22+V$2*V22+W$2*W22+X$2*X22+Y$2*Y22+Z$2*Z22 -> 9587 | AD22: =AC22/AB22 -> 8.3656195
B23: 010702 | C23: 244 | D23: 106 | E23: 132 | F23: 196 | G23: 171 | H23: 271 | I23: 148 | J23: 94 | K23: 127 | L23: 27 | M23: 40 | N23: 26 | O23: 111 | P23: 17 | Q23: 13 | R23: 62 | S23: 56 | T23: 44 | U23: 4 | V23: 2 | W23: 0 | X23: 0 | Y23: 0 | Z23: 0 | AB23: =SUM(C23:Z23) -> 1891 | AC23: =C$2*C23+D$2*D23+E$2*E23+F$2*F23+G$2*G23+H$2*H23+I$2*I23+J$2*J23+K$2*K23+L$2*L23+M$2*M23+N$2*N23+O$2*O23+P$2*P23+Q$2*Q23+R$2*R23+S$2*S23+T$2*T23+U$2*U23+V$2*V23+W$2*W23+X$2*X23+Y$2*Y23+Z$2*Z23 -> 10907 | AD23: =AC23/AB23 -> 5.7678477
B24: 010703 | C24: 103 | D24: 38 | E24: 48 | F24: 91 | G24: 78 | H24: 186 | I24: 46 | J24: 45 | K24: 45 | L24: 21 | M24: 18 | N24: 12 | O24: 73 | P24: 4 | Q24: 4 | R24: 28 | S24: 33 | T24: 30 | U24: 0 | V24: 0 | W24: 0 | X24: 0 | Y24: 0 | Z24: 0 | AB24: =SUM(C24:Z24) -> 903 | AC24: =C$2*C24+D$2*D24+E$2*E24+F$2*F24+G$2*G24+H$2*H24+I$2*I24+J$2*J24+K$2*K24+L$2*L24+M$2*M24+N$2*N24+O$2*O24+P$2*P24+Q$2*Q24+R$2*R24+S$2*S24+T$2*T24+U$2*U24+V$2*V24+W$2*W24+X$2*X24+Y$2*Y24+Z$2*Z24 -> 5543 | AD24: =AC24/AB24 -> 6.1384275
B25: 010704 | C25: 93 | D25: 56 | E25: 83 | F25: 97 | G25: 117 | H25: 296 | I25: 85 | J25: 67 | K25: 64 | L25: 24 | M25: 23 | N25: 17 | O25: 45 | P25: 6 | Q25: 8 | R25: 26 | S25: 21 | T25: 14 | U25: 0 | V25: 0 | W25: 1 | X25: 0 | Y25: 0 | Z25: 0 | AB25: =SUM(C25:Z25) -> 1143 | AC25: =C$2*C25+D$2*D25+E$2*E25+F$2*F25+G$2*G25+H$2*H25+I$2*I25+J$2*J25+K$2*K25+L$2*L25+M$2*M25+N$2*N25+O$2*O25+P$2*P25+Q$2*Q25+R$2*R25+S$2*S25+T$2*T25+U$2*U25+V$2*V25+W$2*W25+X$2*X25+Y$2*Y25+Z$2*Z25 -> 6299 | AD25: =AC25/AB25 -> 5.5109361
B26: 010801 | C26: 85 | D26: 29 | E26: 61 | F26: 51 | G26: 59 | H26: 71 | I26: 33 | J26: 10 | K26: 23 | L26: 8 | M26: 14 | N26: 11 | O26: 43 | P26: 16 | Q26: 18 | R26: 45 | S26: 44 | T26: 27 | U26: 0 | V26: 0 | W26: 0 | X26: 0 | Y26: 0 | Z26: 0 | AB26: =SUM(C26:Z26) -> 648 | AC26: =C$2*C26+D$2*D26+E$2*E26+F$2*F26+G$2*G26+H$2*H26+I$2*I26+J$2*J26+K$2*K26+L$2*L26+M$2*M26+N$2*N26+O$2*O26+P$2*P26+Q$2*Q26+R$2*R26+S$2*S26+T$2*T26+U$2*U26+V$2*V26+W$2*W26+X$2*X26+Y$2*Y26+Z$2*Z26 -> 4494 | AD26: =AC26/AB26 -> 6.9351852
... B342: 090503 | C342: 9 | D342: 5 | E342: 8 | F342: 13 | G342: 6 | H342: 17 | I342: 18 | J342: 10 | K342: 5 | L342: 10 | M342: 10 | N342: 9 | O342: 17 | P342: 1 | Q342: 1 | R342: 1 | S342: 3 | T342: 2 | U342: 0 | V342: 0 | W342: 0 | X342: 0 | Y342: 0 | Z342: 0 | AB342: =SUM(C342:Z342) -> 145 | AC342: =C$2*C342+D$2*D342+E$2*E342+F$2*F342+G$2*G342+H$2*H342+I$2*I342+J$2*J342+K$2*K342+L$2*L342+M$2*M342+N$2*N342+O$2*O342+P$2*P342+Q$2*Q342+R$2*R342+S$2*S342+T$2*T342+U$2*U342+V$2*V342+W$2*W342+X$2*X342+Y$2*Y342+Z$2*Z342 -> 1004 | AD342: =AC342/AB342 -> 6.9241379
C343: =SUM(C4:C342) -> 30763 | D343: =SUM(D4:D342) -> 18352 | E343: =SUM(E4:E342) -> 26558 | F343: =SUM(F4:F342) -> 36024 | G343: =SUM(G4:G342) -> 34364 | H343: =SUM(H4:H342) -> 55376 | I343: =SUM(I4:I342) -> 36989 | J343: =SUM(J4:J342) -> 27885 | ... Z343: =SUM(Z4:Z342) -> 245 | AB343: =SUM(AB4:AB342) -> 844691 | AC343: =SUM(AC4:AC342) -> 8589391 | AD343: =AC343/AB343 -> 10.168678

Sheet 25-35 male_2012
C1: EDU
C2: 0 | D2: 1 | E2: 2 | F2: 3 | G2: 4 | H2: 5 | I2: 6 | J2: 7 | K2: 8 | L2: 9 | M2: 10 | N2: 11 | O2: 12 | P2: 13 | Q2: 14 | R2: 15 | S2: 16 | T2: 17 | U2: 18 | V2: 19 | W2: 20 | X2: 21 | Y2: 22 | Z2: 23
C3: Count | D3: Count | E3: Count | F3: Count | G3: Count | H3: Count | I3: Count | J3: Count | K3: Count | L3: Count | M3: Count | N3: Count | O3: Count | P3: Count | Q3: Count | R3: Count | S3: Count | T3: Count | U3: Count | V3: Count | W3: Count | X3: Count | Y3: Count | Z3: Count | AB3: Total people | AC3: Total years edu | AD3: Average years of education | AF3: Departamento | AG3: Población de mujeres de 25-35 años | AH3: Total años de educación de mujeres de 25-35 años | AI3: Promedio de años de educación
A4: MUN | B4: 010101 | C4: 405 | D4: 304 | E4: 372 | F4: 585 | G4: 608 | H4: 1031 | I4: 701 | J4: 504 | K4: 675 | L4: 791 | M4: 930 | N4: 881 | O4: 3018 | P4: 401 | Q4: 549 | R4: 2113 | S4: 2879 | T4: 4074 | U4: 202 | V4: 290 | W4: 35 | X4: 22 | Y4: 18 | Z4: 11 | AB4: =SUM(C4:Z4) -> 21399 | AC4: =C$2*C4+D$2*D4+E$2*E4+F$2*F4+G$2*G4+H$2*H4+I$2*I4+J$2*J4+K$2*K4+L$2*L4+M$2*M4+N$2*N4+O$2*O4+P$2*P4+Q$2*Q4+R$2*R4+S$2*S4+T$2*T4+U$2*U4+V$2*V4+W$2*W4+X$2*X4+Y$2*Y4+Z$2*Z4 -> 256723 | AD4: =AC4/AB4 -> 11.996962 | AF4: Chuquisaca | AG4: =+SUM(AB4:AB32) -> 42681 | AH4: =+SUM(AC4:AC32) -> 414956 | AI4: =+AH4/AG4 -> 9.7222652
B5: 010102 | C5: 10 | D5: 17 | E5: 24 | F5: 31 | G5: 31 | H5: 51 | I5: 32 | J5: 25 | K5: 36 | L5: 39 | M5: 40 | N5: 41 | O5: 79 | P5: 5 | Q5: 8 | R5: 36 | S5: 41 | T5: 45 | U5: 1 | V5: 2 | W5: 0 | X5: 0 | Y5: 1 | Z5: 0 | AB5: =SUM(C5:Z5) -> 595 | AC5: =C$2*C5+D$2*D5+E$2*E5+F$2*F5+G$2*G5+H$2*H5+I$2*I5+J$2*J5+K$2*K5+L$2*L5+M$2*M5+N$2*N5+O$2*O5+P$2*P5+Q$2*Q5+R$2*R5+S$2*S5+T$2*T5+U$2*U5+V$2*V5+W$2*W5+X$2*X5+Y$2*Y5+Z$2*Z5 -> 5558 | AD5: =AC5/AB5 -> 9.3411765 | AF5: La Paz | AG5: =+SUM(AB33:AB119) -> 222901 | AH5: =+SUM(AC33:AC119) -> 2593429 | AI5: =+AH5/AG5 -> 11.634892
B6: 010103 | C6: 88 | D6: 49 | E6: 104 | F6: 105 | G6: 127 | H6: 163 | I6: 86 | J6: 45 | K6: 65 | L6: 19 | M6: 27 | N6: 19 | O6: 49 | P6: 4 | Q6: 8 | R6: 26 | S6: 15 | T6: 13 | U6: 0 | V6: 1 | W6: 1 | X6: 0 | Y6: 0 | Z6: 0 | AB6: =SUM(C6:Z6) -> 1014 | AC6: =C$2*C6+D$2*D6+E$2*E6+F$2*F6+G$2*G6+H$2*H6+I$2*I6+J$2*J6+K$2*K6+L$2*L6+M$2*M6+N$2*N6+O$2*O6+P$2*P6+Q$2*Q6+R$2*R6+S$2*S6+T$2*T6+U$2*U6+V$2*V6+W$2*W6+X$2*X6+Y$2*Y6+Z$2*Z6 -> 5538 | AD6: =AC6/AB6 -> 5.4615385 | AF6: Cochabamba | AG6: =+SUM(AB120:AB166) -> 142672 | AH6: =+SUM(AC120:AC166) -> 1510785 | AI6: =+AH6/AG6 -> 10.589219
B7: 010201 | C7: 41 | D7: 26 | E7: 55 | F7: 65 | G7: 67 | H7: 140 | I7: 47 | J7: 32 | K7: 25 | L7: 13 | M7: 12 | N7: 13 | O7: 36 | P7: 4 | Q7: 5 | R7: 28 | S7: 32 | T7: 38 | U7: 0 | V7: 0 | W7: 0 | X7: 0 | Y7: 0 | Z7: 0 | AB7: =SUM(C7:Z7) -> 679 | AC7: =C$2*C7+D$2*D7+E$2*E7+F$2*F7+G$2*G7+H$2*H7+I$2*I7+J$2*J7+K$2*K7+L$2*L7+M$2*M7+N$2*N7+O$2*O7+P$2*P7+Q$2*Q7+R$2*R7+S$2*S7+T$2*T7+U$2*U7+V$2*V7+W$2*W7+X$2*X7+Y$2*Y7+Z$2*Z7 -> 4517 | AD7: =AC7/AB7 -> 6.65243 | AF7: Oruro | AG7: =+SUM(AB167:AB201) -> 41249 | AH7: =+SUM(AC167:AC201) -> 485032 | AI7: =+AH7/AG7 -> 11.758637
B8: 010202 | C8: 71 | D8: 39 | E8: 66 | F8: 82 | G8: 72 | H8: 90 | I8: 46 | J8: 33 | K8: 40 | L8: 19 | M8: 13 | N8: 14 | O8: 54 | P8: 6 | Q8: 6 | R8: 35 | S8: 36 | T8: 46 | U8: 0 | V8: 2 | W8: 0 | X8: 1 | Y8: 0 | Z8: 0 | AB8: =SUM(C8:Z8) -> 771 | AC8: =C$2*C8+D$2*D8+E$2*E8+F$2*F8+G$2*G8+H$2*H8+I$2*I8+J$2*J8+K$2*K8+L$2*L8+M$2*M8+N$2*N8+O$2*O8+P$2*P8+Q$2*Q8+R$2*R8+S$2*S8+T$2*T8+U$2*U8+V$2*V8+W$2*W8+X$2*X8+Y$2*Y8+Z$2*Z8 -> 5189 | AD8: =AC8/AB8 -> 6.7302205 | AF8: Potosi | AG8: =+SUM(AB202:AB241) -> 60777 | AH8: =+SUM(AC202:AC241) -> 581273 | AI8: =+AH8/AG8 -> 9.5640292
B9: 010301 | C9: 42 | D9: 36 | E9: 57 | F9: 81 | G9: 92 | H9: 133 | I9: 55 | J9: 41 | K9: 31 | L9: 24 | M9: 22 | N9: 15 | O9: 92 | P9: 10 | Q9: 5 | R9: 48 | S9: 55 | T9: 54 | U9: 1 | V9: 5 | W9: 1 | X9: 0 | Y9: 0 | Z9: 1 | AB9: =SUM(C9:Z9) -> 901 | AC9: =C$2*C9+D$2*D9+E$2*E9+F$2*F9+G$2*G9+H$2*H9+I$2*I9+J$2*J9+K$2*K9+L$2*L9+M$2*M9+N$2*N9+O$2*O9+P$2*P9+Q$2*Q9+R$2*R9+S$2*S9+T$2*T9+U$2*U9+V$2*V9+W$2*W9+X$2*X9+Y$2*Y9+Z$2*Z9 -> 6870 | AD9: =AC9/AB9 -> 7.6248613 | AF9: Tarija | AG9: =+SUM(AB242:AB252) -> 41716 | AH9: =+SUM(AC242:AC252) -> 431066 | AI9: =+AH9/AG9 -> 10.333349
B10: 010302 | C10: 127 | D10: 38 | E10: 63 | F10: 82 | G10: 111 | H10: 120 | I10: 57 | J10: 50 | K10: 43 | L10: 17 | M10: 28 | N10: 22 | O10: 59 | P10: 6 | Q10: 4 | R10: 45 | S10: 32 | T10: 31 | U10: 2 | V10: 4 | W10: 1 | X10: 0 | Y10: 0 | Z10: 0 | AB10: =SUM(C10:Z10) -> 942 | AC10: =C$2*C10+D$2*D10+E$2*E10+F$2*F10+G$2*G10+H$2*H10+I$2*I10+J$2*J10+K$2*K10+L$2*L10+M$2*M10+N$2*N10+O$2*O10+P$2*P10+Q$2*Q10+R$2*R10+S$2*S10+T$2*T10+U$2*U10+V$2*V10+W$2*W10+X$2*X10+Y$2*Y10+Z$2*Z10 -> 5853 | AD10: =AC10/AB10 -> 6.2133758 | AF10: Santa Cruz | AG10: =+SUM(AB253:AB308) -> 235157 | AH10: =+SUM(AC253:AC308) -> 2520305 | AI10: =+AH10/AG10 -> 10.717542
B11: 010303 | C11: 44 | D11: 19 | E11: 17 | F11: 29 | G11: 28 | H11: 70 | I11: 44 | J11: 23 | K11: 27 | L11: 11 | M11: 21 | N11: 14 | O11: 49 | P11: 4 | Q11: 1 | R11: 36 | S11: 22 | T11: 37 | U11: 1 | V11: 2 | W11: 0 | X11: 0 | Y11: 0 | Z11: 0 | AB11: =SUM(C11:Z11) -> 499 | AC11: =C$2*C11+D$2*D11+E$2*E11+F$2*F11+G$2*G11+H$2*H11+I$2*I11+J$2*J11+K$2*K11+L$2*L11+M$2*M11+N$2*N11+O$2*O11+P$2*P11+Q$2*Q11+R$2*R11+S$2*S11+T$2*T11+U$2*U11+V$2*V11+W$2*W11+X$2*X11+Y$2*Y11+Z$2*Z11 -> 3937 | AD11: =AC11/AB11 -> 7.8897796 | AF11: Beni | AG11: =+SUM(AB309:AB327) -> 33505 | AH11: =+SUM(AC309:AC327) -> 349055 | AI11: =+AH11/AG11 -> 10.417997
B12: 010304 | C12: 40 | D12: 29 | E12: 23 | F12: 40 | G12: 41 | H12: 68 | I12: 33 | J12: 19 | K12: 27 | L12: 18 | M12: 17 | N12: 7 | O12: 32 | P12: 7 | Q12: 5 | R12: 12 | S12: 24 | T12: 16 | U12: 0 | V12: 1 | W12: 0 | X12: 0 | Y12: 0 | Z12: 0 | AB12: =SUM(C12:Z12) -> 459 | AC12: =C$2*C12+D$2*D12+E$2*E12+F$2*F12+G$2*G12+H$2*H12+I$2*I12+J$2*J12+K$2*K12+L$2*L12+M$2*M12+N$2*N12+O$2*O12+P$2*P12+Q$2*Q12+R$2*R12+S$2*S12+T$2*T12+U$2*U12+V$2*V12+W$2*W12+X$2*X12+Y$2*Y12+Z$2*Z12 -> 3055 | AD12: =AC12/AB12 -> 6.6557734 | AF12: Pando | AG12: =+SUM(AB328:AB342) -> 10625 | AH12: =+SUM(AC328:AC342) -> 109031 | AI12: =+AH12/AG12 -> 10.261741
B13: 010401 | C13: 28 | D13: 27 | E13: 54 | F13: 59 | G13: 80 | H13: 140 | I13: 57 | J13: 37 | K13: 35 | L13: 19 | M13: 15 | N13: 13 | O13: 48 | P13: 7 | Q13: 6 | R13: 44 | S13: 50 | T13: 50 | U13: 0 | V13: 3 | W13: 1 | X13: 0 | Y13: 0 | Z13: 0 | AB13: =SUM(C13:Z13) -> 773 | AC13: =C$2*C13+D$2*D13+E$2*E13+F$2*F13+G$2*G13+H$2*H13+I$2*I13+J$2*J13+K$2*K13+L$2*L13+M$2*M13+N$2*N13+O$2*O13+P$2*P13+Q$2*Q13+R$2*R13+S$2*S13+T$2*T13+U$2*U13+V$2*V13+W$2*W13+X$2*X13+Y$2*Y13+Z$2*Z13 -> 5815 | AD13: =AC13/AB13 -> 7.5226391 | AF13: Bolivia | AG13: =SUM(AG4:AG12) -> 831283 | AH13: =SUM(AH4:AH12) -> 8994932 | AI13: =+AH13/AG13 -> 10.820541
B14: 010402 | C14: 35 | D14: 30 | E14: 44 | F14: 56 | G14: 50 | H14: 85 | I14: 56 | J14: 24 | K14: 18 | L14: 9 | M14: 16 | N14: 9 | O14: 34 | P14: 4 | Q14: 5 | R14: 27 | S14: 31 | T14: 29 | U14: 3 | V14: 1 | W14: 0 | X14: 0 | Y14: 0 | Z14: 0 | AB14: =SUM(C14:Z14) -> 566 | AC14: =C$2*C14+D$2*D14+E$2*E14+F$2*F14+G$2*G14+H$2*H14+I$2*I14+J$2*J14+K$2*K14+L$2*L14+M$2*M14+N$2*N14+O$2*O14+P$2*P14+Q$2*Q14+R$2*R14+S$2*S14+T$2*T14+U$2*U14+V$2*V14+W$2*W14+X$2*X14+Y$2*Y14+Z$2*Z14 -> 3896 | AD14: =AC14/AB14 -> 6.8833922 | AF14: Gran Chaco | AG14: =SUM(AB245:AB247) -> 13075 | AH14: =SUM(AC245:AC247) -> 130242 | AI14: =+AH14/AG14 -> 9.9611472
B15: 010403 | C15: 39 | D15: 28 | E15: 42 | F15: 63 | G15: 59 | H15: 59 | I15: 27 | J15: 20 | K15: 31 | L15: 9 | M15: 12 | N15: 7 | O15: 41 | P15: 3 | Q15: 4 | R15: 17 | S15: 27 | T15: 28 | U15: 0 | V15: 1 | W15: 0 | X15: 0 | Y15: 0 | Z15: 0 | AB15: =SUM(C15:Z15) -> 517 | AC15: =C$2*C15+D$2*D15+E$2*E15+F$2*F15+G$2*G15+H$2*H15+I$2*I15+J$2*J15+K$2*K15+L$2*L15+M$2*M15+N$2*N15+O$2*O15+P$2*P15+Q$2*Q15+R$2*R15+S$2*S15+T$2*T15+U$2*U15+V$2*V15+W$2*W15+X$2*X15+Y$2*Y15+Z$2*Z15 -> 3429 | AD15: =AC15/AB15 -> 6.6324952
B16: 010404 | C16: 20 | D16: 12 | E16: 16 | F16: 27 | G16: 23 | H16: 54 | I16: 19 | J16: 18 | K16: 26 | L16: 12 | M16: 14 | N16: 9 | O16: 44 | P16: 3 | Q16: 2 | R16: 31 | S16: 40 | T16: 40 | U16: 1 | V16: 2 | W16: 0 | X16: 0 | Y16: 0 | Z16: 0 | AB16: =SUM(C16:Z16) -> 413 | AC16: =C$2*C16+D$2*D16+E$2*E16+F$2*F16+G$2*G16+H$2*H16+I$2*I16+J$2*J16+K$2*K16+L$2*L16+M$2*M16+N$2*N16+O$2*O16+P$2*P16+Q$2*Q16+R$2*R16+S$2*S16+T$2*T16+U$2*U16+V$2*V16+W$2*W16+X$2*X16+Y$2*Y16+Z$2*Z16 -> 3718 | AD16: =AC16/AB16 -> 9.0024213
B17: 010405 | C17: 14 | D17: 13 | E17: 15 | F17: 19 | G17: 30 | H17: 46 | I17: 19 | J17: 16 | K17: 21 | L17: 4 | M17: 14 | N17: 16 | O17: 39 | P17: 3 | Q17: 1 | R17: 14 | S17: 10 | T17: 23 | U17: 0 | V17: 0 | W17: 0 | X17: 0 | Y17: 0 | Z17: 0 | AB17: =SUM(C17:Z17) -> 317 | AC17: =C$2*C17+D$2*D17+E$2*E17+F$2*F17+G$2*G17+H$2*H17+I$2*I17+J$2*J17+K$2*K17+L$2*L17+M$2*M17+N$2*N17+O$2*O17+P$2*P17+Q$2*Q17+R$2*R17+S$2*S17+T$2*T17+U$2*U17+V$2*V17+W$2*W17+X$2*X17+Y$2*Y17+Z$2*Z17 -> 2478 | AD17: =AC17/AB17 -> 7.8170347
B18: 010501 | C18: 72 | D18: 62 | E18: 86 | F18: 119 | G18: 121 | H18: 222 | I18: 107 | J18: 73 | K18: 71 | L18: 52 | M18: 67 | N18: 76 | O18: 193 | P18: 8 | Q18: 18 | R18: 96 | S18: 148 | T18: 150 | U18: 1 | V18: 7 | W18: 1 | X18: 2 | Y18: 0 | Z18: 1 | AB18: =SUM(C18:Z18) -> 1753 | AC18: =C$2*C18+D$2*D18+E$2*E18+F$2*F18+G$2*G18+H$2*H18+I$2*I18+J$2*J18+K$2*K18+L$2*L18+M$2*M18+N$2*N18+O$2*O18+P$2*P18+Q$2*Q18+R$2*R18+S$2*S18+T$2*T18+U$2*U18+V$2*V18+W$2*W18+X$2*X18+Y$2*Y18+Z$2*Z18 -> 15146 | AD18: =AC18/AB18 -> 8.6400456
B19: 010502 | C19: 36 | D19: 12 | E19: 39 | F19: 46 | G19: 29 | H19: 72 | I19: 43 | J19: 15 | K19: 38 | L19: 30 | M19: 24 | N19: 26 | O19: 72 | P19: 1 | Q19: 2 | R19: 29 | S19: 32 | T19: 41 | U19: 0 | V19: 0 | W19: 0 | X19: 0 | Y19: 0 | Z19: 0 | AB19: =SUM(C19:Z19) -> 587 | AC19: =C$2*C19+D$2*D19+E$2*E19+F$2*F19+G$2*G19+H$2*H19+I$2*I19+J$2*J19+K$2*K19+L$2*L19+M$2*M19+N$2*N19+O$2*O19+P$2*P19+Q$2*Q19+R$2*R19+S$2*S19+T$2*T19+U$2*U19+V$2*V19+W$2*W19+X$2*X19+Y$2*Y19+Z$2*Z19 -> 4716 | AD19: =AC19/AB19 -> 8.0340716
B20: 010601 | C20: 85 | D20: 32 | E20: 69 | F20: 76 | G20: 104 | H20: 141 | I20: 60 | J20: 26 | K20: 35 | L20: 16 | M20: 13 | N20: 17 | O20: 57 | P20: 5 | Q20: 12 | R20: 27 | S20: 31 | T20: 29 | U20: 2 | V20: 3 | W20: 1 | X20: 0 | Y20: 0 | Z20: 0 | AB20: =SUM(C20:Z20) -> 841 | AC20: =C$2*C20+D$2*D20+E$2*E20+F$2*F20+G$2*G20+H$2*H20+I$2*I20+J$2*J20+K$2*K20+L$2*L20+M$2*M20+N$2*N20+O$2*O20+P$2*P20+Q$2*Q20+R$2*R20+S$2*S20+T$2*T20+U$2*U20+V$2*V20+W$2*W20+X$2*X20+Y$2*Y20+Z$2*Z20 -> 5226 | AD20: =AC20/AB20 -> 6.2140309
B21: 010602 | C21: 24 | D21: 19 | E21: 33 | F21: 35 | G21: 48 | H21: 111 | I21: 45 | J21: 49 | K21: 45 | L21: 15 | M21: 26 | N21: 16 | O21: 52 | P21: 4 | Q21: 6 | R21: 20 | S21: 28 | T21: 30 | U21: 1 | V21: 0 | W21: 0 | X21: 0 | Y21: 0 | Z21: 0 | AB21: =SUM(C21:Z21) -> 607 | AC21: =C$2*C21+D$2*D21+E$2*E21+F$2*F21+G$2*G21+H$2*H21+I$2*I21+J$2*J21+K$2*K21+L$2*L21+M$2*M21+N$2*N21+O$2*O21+P$2*P21+Q$2*Q21+R$2*R21+S$2*S21+T$2*T21+U$2*U21+V$2*V21+W$2*W21+X$2*X21+Y$2*Y21+Z$2*Z21 -> 4517 | AD21: =AC21/AB21 -> 7.4415157
