Workbook

Sheet Datos procesados 2012
A1: Depart | B1: Provincia | C1: Municipio | D1: Capital | E1: CodigoINE | F1: Numero de Servicios Básicos | J1: # Hogares | K1: % de hogares con 3 servicios básicos | L1: Número de hogares que carecen de servicios básicos, 2024 | P1: Departamento | Q1: Numero de Servicios Básicos | U1: # hogares | V1: % de hogares con 3 servicios básicos | W1: Número de hogares que carecen de al menos uno de los tres servicios básicos, 2012
F2: .00 | G2: 1.00 | H2: 2.00 | I2: 3.00
F3: Count | G3: Count | H3: Count | I3: Count | Q3: 0 | R3: 1 | S3: 2 | T3: 3
A4: Chuquisaca | B4: Oropeza | C4: Sucre | D4: Sucre | E4: 10101 | F4: 3453 | G4: 4030 | H4: 8093 | I4: 54373 | J4: 69949 | K4: =(I4/J4)*100 -> 77.732348 | L4: 3453 | P4: Chuquisaca | Q4: =+SUM(F4:F32) -> 25961 | R4: =+SUM(G4:G32) -> 24030 | S4: =+SUM(H4:H32) -> 24803 | T4: =+SUM(I4:I32) -> 75287 | U4: =+SUM(J4:J32) -> 150081 | V4: =(T4/U4)*100 -> 50.164245 | W4: =U4-T4 -> 74794
A5: Chuquisaca | B5: Oropeza | C5: Yotala | D5: Yotala | E5: 10102 | F5: 247 | G5: 421 | H5: 790 | I5: 1188 | J5: 2646 | K5: =(I5/J5)*100 -> 44.897959 | L5: 247 | P5: La Paz | Q5: =+SUM(F33:F119) -> 79253 | R5: =+SUM(G33:G119) -> 118358 | S5: =+SUM(H33:H119) -> 205296 | T5: =+SUM(I33:I119) -> 449666 | U5: =+SUM(J33:J119) -> 852573 | V5: =(T5/U5)*100 -> 52.742229 | W5: =U5-T5 -> 402907
A6: Chuquisaca | B6: Oropeza | C6: Poroma | D6: Poroma | E6: 10103 | F6: 2544 | G6: 1585 | H6: 355 | I6: 176 | J6: 4660 | K6: =(I6/J6)*100 -> 3.776824 | L6: 2544 | P6: Cochabamba | Q6: =+SUM(F120:F167) -> 57060 | R6: =+SUM(G120:G167) -> 108872 | S6: =+SUM(H120:H167) -> 132705 | T6: =+SUM(I120:I167) -> 217971 | U6: =+SUM(J120:J167) -> 516608 | V6: =(T6/U6)*100 -> 42.192726 | W6: =U6-T6 -> 298637
A7: Chuquisaca | B7: Azurduy | C7: Villa Azurduy | D7: Villa Azurduy | E7: 10201 | F7: 1252 | G7: 644 | H7: 316 | I7: 326 | J7: 2538 | K7: =(I7/J7)*100 -> 12.84476 | L7: 1252 | P7: Oruro | Q7: =+SUM(F168:F202) -> 21048 | R7: =+SUM(G168:G202) -> 23943 | S7: =+SUM(H168:H202) -> 43752 | T7: =+SUM(I168:I202) -> 63318 | U7: =+SUM(J168:J202) -> 152061 | V7: =(T7/U7)*100 -> 41.639868 | W7: =U7-T7 -> 88743
A8: Chuquisaca | B8: Azurduy | C8: Tarvita | D8: Villa Orías | E8: 10202 | F8: 1292 | G8: 1005 | H8: 672 | I8: 449 | J8: 3418 | K8: =(I8/J8)*100 -> 13.136337 | L8: 1292 | P8: Potosí | Q8: =+SUM(F203:F244) -> 35584 | R8: =+SUM(G203:G244) -> 51949 | S8: =+SUM(H203:H244) -> 66660 | T8: =+SUM(I203:I244) -> 88109 | U8: =+SUM(J203:J244) -> 242302 | V8: =(T8/U8)*100 -> 36.363299 | W8: =U8-T8 -> 154193
A9: Chuquisaca | B9: Zudáñez | C9: Zudañez | D9: Villa Zudáñez | E9: 10301 | F9: 547 | G9: 762 | H9: 558 | I9: 719 | J9: 2586 | K9: =(I9/J9)*100 -> 27.803558 | L9: 547 | P9: Tarija | Q9: =+SUM(F245:F255) -> 4383 | R9: =+SUM(G245:G255) -> 10092 | S9: =+SUM(H245:H255) -> 26966 | T9: =+SUM(I245:I255) -> 84807 | U9: =+SUM(J245:J255) -> 126248 | V9: =(T9/U9)*100 -> 67.174926 | W9: =U9-T9 -> 41441
A10: Chuquisaca | B10: Zudáñez | C10: Presto | D10: Presto | E10: 10302 | F10: 924 | G10: 839 | H10: 482 | I10: 472 | J10: 2717 | K10: =(I10/J10)*100 -> 17.372102 | L10: 924 | P10: Santa Cruz | Q10: =+SUM(F256:F311) -> 17773 | R10: =+SUM(G256:G311) -> 39534 | S10: =+SUM(H256:H311) -> 305275 | T10: =+SUM(I256:I311) -> 282272 | U10: =+SUM(J256:J311) -> 644854 | V10: =(T10/U10)*100 -> 43.773009 | W10: =U10-T10 -> 362582
A11: Chuquisaca | B11: Zudáñez | C11: Villa Mojocoya | D11: Villa de Mojocoya | E11: 10303 | F11: 553 | G11: 524 | H11: 372 | I11: 533 | J11: 1982 | K11: =(I11/J11)*100 -> 26.892028 | L11: 553 | P11: Beni | Q11: =+SUM(F312:F331) -> 7636 | R11: =+SUM(G312:G331) -> 31214 | S11: =+SUM(H312:H331) -> 35542 | T11: =+SUM(I312:I331) -> 19498 | U11: =+SUM(J312:J331) -> 93890 | V11: =(T11/U11)*100 -> 20.766855 | W11: =U11-T11 -> 74392
A12: Chuquisaca | B12: Zudáñez | C12: Icla | D12: Icla | E12: 10304 | F12: 257 | G12: 419 | H12: 434 | I12: 721 | J12: 1831 | K12: =(I12/J12)*100 -> 39.377389 | L12: 257 | P12: Pando | Q12: =+SUM(F332:F346) -> 3033 | R12: =+SUM(G332:G346) -> 6565 | S12: =+SUM(H332:H346) -> 10885 | T12: =+SUM(I332:I346) -> 4882 | U12: =+SUM(J332:J346) -> 25365 | V12: =(T12/U12)*100 -> 19.246994 | W12: =U12-T12 -> 20483
A13: Chuquisaca | B13: Tomina | C13: Padilla | D13: Padilla | E13: 10401 | F13: 770 | G13: 642 | H13: 458 | I13: 940 | J13: 2810 | K13: =(I13/J13)*100 -> 33.451957 | L13: 770 | P13: Gran Chaco | Q13: 801 | R13: 3083 | S13: 8836 | T13: 23702 | U13: 36422 | V13: 65.076053 | W13: 801
A14: Chuquisaca | B14: Tomina | C14: Tomina | D14: Villa de Tomina | E14: 10402 | F14: 206 | G14: 626 | H14: 688 | I14: 593 | J14: 2113 | K14: =(I14/J14)*100 -> 28.064363 | L14: 206 | P14: Bolivia | Q14: =SUM(Q4:Q12) -> 251731 | R14: =SUM(R4:R12) -> 414557 | S14: =SUM(S4:S12) -> 851884 | T14: =SUM(T4:T12) -> 1285810 | U14: =SUM(U4:U12) -> 2803982 | V14: =(T14/U14)*100 -> 45.856571 | W14: =SUM(W4:W12) -> 1518172
A15: Chuquisaca | B15: Tomina | C15: Sopachuy | D15: Villa de Sopachui | E15: 10403 | F15: 651 | G15: 549 | H15: 272 | I15: 538 | J15: 2010 | K15: =(I15/J15)*100 -> 26.766169 | L15: 651
A16: Chuquisaca | B16: Tomina | C16: Villa Alcalá | D16: Alcalá | E16: 10404 | F16: 145 | G16: 374 | H16: 309 | I16: 244 | J16: 1072 | K16: =(I16/J16)*100 -> 22.761194 | L16: 145
A17: Chuquisaca | B17: Tomina | C17: El Villar | D17: El Villar | E17: 10405 | F17: 413 | G17: 260 | H17: 271 | I17: 268 | J17: 1212 | K17: =(I17/J17)*100 -> 22.112211 | L17: 413
A18: Chuquisaca | B18: Hernando Siles | C18: Monteagudo | D18: Monteagudo | E18: 10501 | F18: 983 | G18: 1094 | H18: 1162 | I18: 2840 | J18: 6079 | K18: =(I18/J18)*100 -> 46.71821 | L18: 983
A19: Chuquisaca | B19: Hernando Siles | C19: San Pablo de Huacareta | D19: San Pablo de Huacareta | E19: 10502 | F19: 489 | G19: 649 | H19: 381 | I19: 560 | J19: 2079 | K19: =(I19/J19)*100 -> 26.936027 | L19: 489
A20: Chuquisaca | B20: Yamparáez | C20: Tarabuco | D20: Tarabuco | E20: 10601 | F20: 1052 | G20: 1269 | H20: 1217 | I20: 848 | J20: 4386 | K20: =(I20/J20)*100 -> 19.334245 | L20: 1052
A21: Chuquisaca | B21: Yamparáez | C21: Yamparáez | D21: Yamparáez | E21: 10602 | F21: 972 | G21: 697 | H21: 670 | I21: 611 | J21: 2950 | K21: =(I21/J21)*100 -> 20.711864 | L21: 972
A22: Chuquisaca | B22: Nor Cinti | C22: Camargo | D22: Camargo | E22: 10701 | F22: 636 | G22: 736 | H22: 1136 | I22: 1817 | J22: 4325 | K22: =(I22/J22)*100 -> 42.011561 | L22: 636
A23: Chuquisaca | B23: Nor Cinti | C23: San Lucas | D23: San Lucas | E23: 10702 | F23: 3145 | G23: 2007 | H23: 1570 | I23: 1286 | J23: 8008 | K23: =(I23/J23)*100 -> 16.058941 | L23: 3145
A24: Chuquisaca | B24: Nor Cinti | C24: Incahuasi | D24: Incahuasi | E24: 10703 | F24: 1317 | G24: 653 | H24: 426 | I24: 383 | J24: 2779 | K24: =(I24/J24)*100 -> 13.781936 | L24: 1317
A25: Chuquisaca | B25: Nor Cinti | C25: Villa Charcas | D25: Villa Charcas | E25: 10704 | F25: 1443 | G25: 808 | H25: 674 | I25: 550 | J25: 3475 | K25: =(I25/J25)*100 -> 15.827338 | L25: 1443
A26: Chuquisaca | B26: Belisario Boeto | C26: Villa Serrano | D26: Villa Serrano | E26: 10801 | F26: 480 | G26: 741 | H26: 683 | I26: 1292 | J26: 3196 | K26: =(I26/J26)*100 -> 40.425532 | L26: 480
... A217: Potosí | B217: Chayanta | C217: Ocurí | D217: Ocurí | E217: 50404 | F217: 1480 | G217: 1715 | H217: 1325 | I217: 573 | J217: 5093 | K217: =(I217/J217)*100 -> 11.250736 | L217: 1480
A218: Potosí | B218: Chayanta | C218: San Pedro de Macha | D218: San Pedro de Macha | E218: 50405 | F218: 1242 | G218: 2152 | H218: 2152 | I218: 818 | J218: 6364 | K218: 14.018779 | L218: 1242
A219: Potosí | B219: Chárcas | C219: San Pedro | D219: San Pedro | E219: 50501 | F219: 2967 | G219: 3653 | H219: 1241 | I219: 416 | J219: 8277 | K219: =(I219/J219)*100 -> 5.0259756 | L219: 2967
A220: Potosí | B220: Chárcas | C220: Toro Toro | D220: Toro Toro | E220: 50502 | F220: 906 | G220: 1368 | H220: 699 | I220: 538 | J220: 3511 | K220: =(I220/J220)*100 -> 15.32327 | L220: 906
A221: Potosí | B221: Nor Chichas | C221: Cotagaita | D221: Cotagaita | E221: 50601 | F221: 1796 | G221: 2453 | H221: 3227 | I221: 1995 | J221: 9471 | K221: =(I221/J221)*100 -> 21.064302 | L221: 1796
A222: Potosí | B222: Nor Chichas | C222: Vitiche | D222: Vitiche | E222: 50602 | F222: 495 | G222: 688 | H222: 1191 | I222: 750 | J222: 3124 | K222: =(I222/J222)*100 -> 24.007682 | L222: 495
A223: Potosí | B223: Alonso de Ibáñez | C223: Sacaca | D223: Villa de Sacaca | E223: 50701 | F223: 919 | G223: 1790 | H223: 2139 | I223: 770 | J223: 5618 | K223: =(I223/J223)*100 -> 13.705945 | L223: 919
A224: Potosí | B224: Alonso de Ibáñez | C224: Caripuyo | D224: Caripuyo | E224: 50702 | F224: 247 | G224: 1186 | H224: 1081 | I224: 227 | J224: 2741 | K224: =(I224/J224)*100 -> 8.281649 | L224: 247
A225: Potosí | B225: Sur Chichas | C225: Tupiza | D225: Tupiza | E225: 50801 | F225: 1151 | G225: 1540 | H225: 2761 | I225: 7867 | J225: 13319 | K225: =(I225/J225)*100 -> 59.065996 | L225: 1151
A226: Potosí | B226: Sur Chichas | C226: Atocha | D226: Atocha | E226: 50802 | F226: 176 | G226: 340 | H226: 2332 | I226: 728 | J226: 3576 | K226: =(I226/J226)*100 -> 20.357942 | L226: 176
A227: Potosí | B227: Nor Lipez | C227: Colcha "K" | D227: Villa Martín | E227: 50901 | F227: 393 | G227: 726 | H227: 1273 | I227: 915 | J227: 3307 | K227: =(I227/J227)*100 -> 27.668582 | L227: 393
A228: Potosí | B228: Nor Lipez | C228: San Pedro de Quemes | D228: Villa San Pedro de Quemes | E228: 50902 | F228: 88 | G228: 70 | H228: 136 | I228: 78 | J228: 372 | K228: =(I228/J228)*100 -> 20.967742 | L228: 88
A229: Potosí | B229: Sur Lipez | C229: San Pablo | D229: San Pablo de Lípez | E229: 51001 | F229: 138 | G229: 234 | H229: 354 | I229: 145 | J229: 871 | K229: =(I229/J229)*100 -> 16.647532 | L229: 138
A230: Potosí | B230: Sur Lipez | C230: Mojinete | D230: Mojinete | E230: 51002 | F230: 162 | G230: 74 | H230: 64 | I230: 58 | J230: 358 | K230: =(I230/J230)*100 -> 16.201117 | L230: 162
...

Sheet Datos procesados 2024
A1: Depart | B1: Provincia | C1: Municipio | D1: Capital | E1: CodigoINE | F1: Numero de Servicios Básicos | J1: # Hogares | K1: % de hogares con 3 servicios básicos | L1: Número de hogares que carecen de al menos uno de los tres servicios básicos, 2024 | P1: Departamento | Q1: Numero de Servicios Básicos | U1: # hogares | V1: % de hogares con 3 servicios básicos | W1: Número de hogares que carecen de al menos uno de los tres servicios básicos, 2012
F2: .00 | G2: 1.00 | H2: 2.00 | I2: 3.00
F3: Count | G3: Count | H3: Count | I3: Count | Q3: 0 | R3: 1 | S3: 2 | T3: 3
A4: Chuquisaca | B4: Oropeza | C4: Sucre | D4: Sucre | E4: 10101 | F4: 1401 | G4: 4366 | H4: 9559 | I4: 77205 | J4: 92531 | K4: =(I4/J4)*100 -> 83.436902 | L4: 1401 | P4: Chuquisaca | Q4: =+SUM(F4:F32) -> 11084 | R4: =+SUM(G4:G32) -> 19888 | S4: =+SUM(H4:H32) -> 35053 | T4: =+SUM(I4:I32) -> 118944 | U4: =+SUM(J4:J32) -> 184969 | V4: =(T4/U4)*100 -> 64.304829 | W4: =U4-T4 -> 66025
A5: Chuquisaca | B5: Oropeza | C5: Yotala | D5: Yotala | E5: 10102 | F5: 107 | G5: 304 | H5: 700 | I5: 1945 | J5: 3056 | K5: =(I5/J5)*100 -> 63.645288 | L5: 107 | P5: La Paz | Q5: =+SUM(F33:F119) -> 44442 | R5: =+SUM(G33:G119) -> 101197 | S5: =+SUM(H33:H119) -> 226641 | T5: =+SUM(I33:I119) -> 697558 | U5: =+SUM(J33:J119) -> 1069838 | V5: =(T5/U5)*100 -> 65.202208 | W5: =U5-T5 -> 372280
A6: Chuquisaca | B6: Oropeza | C6: Poroma | D6: Poroma | E6: 10103 | F6: 1195 | G6: 1632 | H6: 1229 | I6: 598 | J6: 4654 | K6: =(I6/J6)*100 -> 12.849162 | L6: 1195 | P6: Cochabamba | Q6: =+SUM(F120:F167) -> 40277 | R6: =+SUM(G120:G167) -> 111567 | S6: =+SUM(H120:H167) -> 178688 | T6: =+SUM(I120:I167) -> 344532 | U6: =+SUM(J120:J167) -> 675064 | V6: =(T6/U6)*100 -> 51.036939 | W6: =U6-T6 -> 330532
A7: Chuquisaca | B7: Azurduy | C7: Villa Azurduy | D7: Villa Azurduy | E7: 10201 | F7: 487 | G7: 699 | H7: 540 | I7: 724 | J7: 2450 | K7: =(I7/J7)*100 -> 29.55102 | L7: 487 | P7: Oruro | Q7: =+SUM(F168:F202) -> 12424 | R7: =+SUM(G168:G202) -> 22102 | S7: =+SUM(H168:H202) -> 51590 | T7: =+SUM(I168:I202) -> 104857 | U7: =+SUM(J168:J202) -> 190973 | V7: =(T7/U7)*100 -> 54.906715 | W7: =U7-T7 -> 86116
A8: Chuquisaca | B8: Azurduy | C8: Tarvita | D8: Villa Orías | E8: 10202 | F8: 688 | G8: 956 | H8: 1415 | I8: 1539 | J8: 4598 | K8: =(I8/J8)*100 -> 33.471074 | L8: 688 | P8: Potosí | Q8: =+SUM(F203:F244) -> 24693 | R8: =+SUM(G203:G244) -> 47119 | S8: =+SUM(H203:H244) -> 91145 | T8: =+SUM(I203:I244) -> 140788 | U8: =+SUM(J203:J244) -> 303745 | V8: =(T8/U8)*100 -> 46.350722 | W8: =U8-T8 -> 162957
A9: Chuquisaca | B9: Zudáñez | C9: Zudañez | D9: Villa Zudáñez | E9: 10301 | F9: 200 | G9: 439 | H9: 1194 | I9: 1354 | J9: 3187 | K9: =(I9/J9)*100 -> 42.485096 | L9: 200 | P9: Tarija | Q9: =+SUM(F245:F255) -> 1913 | R9: =+SUM(G245:G255) -> 9171 | S9: =+SUM(H245:H255) -> 30572 | T9: =+SUM(I245:I255) -> 118598 | U9: =+SUM(J245:J255) -> 160254 | V9: =(T9/U9)*100 -> 74.006265 | W9: =U9-T9 -> 41656
A10: Chuquisaca | B10: Zudáñez | C10: Presto | D10: Presto | E10: 10302 | F10: 401 | G10: 618 | H10: 1016 | I10: 1236 | J10: 3271 | K10: =(I10/J10)*100 -> 37.78661 | L10: 401 | P10: Santa Cruz | Q10: =+SUM(F256:F311) -> 10375 | R10: =+SUM(G256:G311) -> 34490 | S10: =+SUM(H256:H311) -> 330919 | T10: =+SUM(I256:I311) -> 501473 | U10: =+SUM(J256:J311) -> 877257 | V10: =(T10/U10)*100 -> 57.16375 | W10: =U10-T10 -> 375784
A11: Chuquisaca | B11: Zudáñez | C11: Villa Mojocoya | D11: Villa de Mojocoya | E11: 10303 | F11: 158 | G11: 460 | H11: 678 | I11: 1247 | J11: 2543 | K11: =(I11/J11)*100 -> 49.036571 | L11: 158 | P11: Beni | Q11: =+SUM(F312:F331) -> 6135 | R11: =+SUM(G312:G331) -> 39651 | S11: =+SUM(H312:H331) -> 44698 | T11: =+SUM(I312:I331) -> 36184 | U11: =+SUM(J312:J331) -> 126668 | V11: =(T11/U11)*100 -> 28.566015 | W11: =U11-T11 -> 90484
A12: Chuquisaca | B12: Zudáñez | C12: Icla | D12: Icla | E12: 10304 | F12: 241 | G12: 478 | H12: 780 | I12: 1136 | J12: 2635 | K12: =(I12/J12)*100 -> 43.111954 | L12: 241 | P12: Pando | Q12: =+SUM(F332:F346) -> 911 | R12: =+SUM(G332:G346) -> 6313 | S12: =+SUM(H332:H346) -> 16074 | T12: =+SUM(I332:I346) -> 11645 | U12: =+SUM(J332:J346) -> 34943 | V12: =(T12/U12)*100 -> 33.325702 | W12: =U12-T12 -> 23298
A13: Chuquisaca | B13: Tomina | C13: Padilla | D13: Padilla | E13: 10401 | F13: 206 | G13: 489 | H13: 823 | I13: 1668 | J13: 3186 | K13: =(I13/J13)*100 -> 52.354049 | L13: 206 | P13: Gran Chaco | Q13: 373 | R13: 2105 | S13: 9943 | T13: 33611 | U13: 46032 | V13: 73.016597 | W13: 12421
A14: Chuquisaca | B14: Tomina | C14: Tomina | D14: Villa de Tomina | E14: 10402 | F14: 81 | G14: 197 | H14: 657 | I14: 1308 | J14: 2243 | K14: =(I14/J14)*100 -> 58.314757 | L14: 81 | P14: Bolivia | Q14: =SUM(Q4:Q12) -> 152254 | R14: =SUM(R4:R12) -> 391498 | S14: =SUM(S4:S12) -> 1005380 | T14: =SUM(T4:T12) -> 2074579 | U14: =SUM(U4:U12) -> 3623711 | V14: =(T14/U14)*100 -> 57.250123 | W14: =U14-T14 -> 1549132
A15: Chuquisaca | B15: Tomina | C15: Sopachuy | D15: Villa de Sopachui | E15: 10403 | F15: 246 | G15: 550 | H15: 440 | I15: 851 | J15: 2087 | K15: =(I15/J15)*100 -> 40.776234 | L15: 246
A16: Chuquisaca | B16: Tomina | C16: Villa Alcalá | D16: Alcalá | E16: 10404 | F16: 22 | G16: 111 | H16: 346 | I16: 710 | J16: 1189 | K16: =(I16/J16)*100 -> 59.714045 | L16: 22
A17: Chuquisaca | B17: Tomina | C17: El Villar | D17: El Villar | E17: 10405 | F17: 141 | G17: 227 | H17: 353 | I17: 718 | J17: 1439 | K17: =(I17/J17)*100 -> 49.895761 | L17: 141
A18: Chuquisaca | B18: Hernando Siles | C18: Monteagudo | D18: Monteagudo | E18: 10501 | F18: 400 | G18: 687 | H18: 1546 | I18: 5109 | J18: 7742 | K18: =(I18/J18)*100 -> 65.9907 | L18: 400
A19: Chuquisaca | B19: Hernando Siles | C19: San Pablo de Huacareta | D19: San Pablo de Huacareta | E19: 10502 | F19: 71 | G19: 406 | H19: 710 | I19: 1114 | J19: 2301 | K19: =(I19/J19)*100 -> 48.413733 | L19: 71
A20: Chuquisaca | B20: Yamparáez | C20: Tarabuco | D20: Tarabuco | E20: 10601 | F20: 247 | G20: 711 | H20: 1415 | I20: 1906 | J20: 4279 | K20: =(I20/J20)*100 -> 44.543118 | L20: 247
A21: Chuquisaca | B21: Yamparáez | C21: Yamparáez | D21: Yamparáez | E21: 10602 | F21: 255 | G21: 565 | H21: 872 | I21: 1377 | J21: 3069 | K21: =(I21/J21)*100 -> 44.868035 | L21: 255
A22: Chuquisaca | B22: Nor Cinti | C22: Camargo | D22: Camargo | E22: 10701 | F22: 314 | G22: 541 | H22: 1503 | I22: 2689 | J22: 5047 | K22: =(I22/J22)*100 -> 53.279176 | L22: 314
A23: Chuquisaca | B23: Nor Cinti | C23: San Lucas | D23: San Lucas | E23: 10702 | F23: 1247 | G23: 1744 | H23: 2766 | I23: 2894 | J23: 8651 | K23: =(I23/J23)*100 -> 33.45278 | L23: 1247
A24: Chuquisaca | B24: Nor Cinti | C24: Incahuasi | D24: Incahuasi | E24: 10703 | F24: 1037 | G24: 888 | H24: 1011 | I24: 1135 | J24: 4071 | K24: =(I24/J24)*100 -> 27.880128 | L24: 1037
A25: Chuquisaca | B25: Nor Cinti | C25: Villa Charcas | D25: Villa Charcas | E25: 10704 | F25: 735 | G25: 686 | H25: 1113 | I25: 1466 | J25: 4000 | K25: =(I25/J25)*100 -> 36.65 | L25: 735
A26: Chuquisaca | B26: Belisario Boeto | C26: Villa Serrano | D26: Villa Serrano | E26: 10801 | F26: 119 | G26: 373 | H26: 800 | I26: 1895 | J26: 3187 | K26: =(I26/J26)*100 -> 59.460307 | L26: 119
... A346: Pando | B346: Federico Román | C346: Santos Mercado | D346: Santos Mercado | E346: 90503 | F346: 24 | G346: 125 | H346: 362 | I346: 90 | J346: 601 | K346: =(I346/J346)*100 -> 14.975042 | L346: 24
E347: Gran Chaco | F347: =SUM(F248:F250) -> 373 | G347: =SUM(G248:G250) -> 2105 | H347: =SUM(H248:H250) -> 9943 | I347: =SUM(I248:I250) -> 33611 | J347: =SUM(J248:J250) -> 46032 | K347: =(I347/J347)*100 -> 73.016597 | L347: =SUM(L248:L250) -> 373

Sheet Indicador_MUN
A1: id | B1: Municipio | C1: % de hogares con 3 servicios básicos 2012 | D1: % de hogares con 3 servicios básicos 2024
A2: 10101 | B2: Sucre | C2: 77.732348 | D2: 83.436902
A3: 10102 | B3: Yotala | C3: 44.897959 | D3: 63.645288
A4: 10103 | B4: Poroma | C4: 3.776824 | D4: 12.849162
A5: 10201 | B5: Villa Azurduy | C5: 12.84476 | D5: 29.55102
A6: 10202 | B6: Tarvita | C6: 13.136337 | D6: 33.471074
A7: 10301 | B7: Zudañez | C7: 27.803558 | D7: 42.485096
A8: 10302 | B8: Presto | C8: 17.372102 | D8: 37.78661
A9: 10303 | B9: Villa Mojocoya | C9: 26.892028 | D9: 49.036571
A10: 10304 | B10: Icla | C10: 39.377389 | D10: 43.111954
A11: 10401 | B11: Padilla | C11: 33.451957 | D11: 52.354049
A12: 10402 | B12: Tomina | C12: 28.064363 | D12: 58.314757
A13: 10403 | B13: Sopachuy | C13: 26.766169 | D13: 40.776234
... A344: 90503 | B344: Santos Mercado | C344: 8.3690987 | D344: 14.975042

Sheet Absoluto_MUN
A1: id | B1: Municipio | C1: Número de hogares que carecen de servicios básicos 2012 | D1: Número de hogares que carecen de servicios básicos 2024
A2: 10101 | B2: Sucre | C2: 3453 | D2: 1401
A3: 10102 | B3: Yotala | C3: 247 | D3: 107
A4: 10103 | B4: Poroma | C4: 2544 | D4: 1195
A5: 10201 | B5: Villa Azurduy | C5: 1252 | D5: 487
A6: 10202 | B6: Tarvita | C6: 1292 | D6: 688
A7: 10301 | B7: Zudañez | C7: 547 | D7: 200
A8: 10302 | B8: Presto | C8: 924 | D8: 401
A9: 10303 | B9: Villa Mojocoya | C9: 553 | D9: 158
A10: 10304 | B10: Icla | C10: 257 | D10: 241
A11: 10401 | B11: Padilla | C11: 770 | D11: 206
A12: 10402 | B12: Tomina | C12: 206 | D12: 81
A13: 10403 | B13: Sopachuy | C13: 651 | D13: 246
... A344: 90503 | B344: Santos Mercado | C344: 67 | D344: 24

Sheet Indicador_DEP
A1: id_departamento | B1: Departamento | C1: % de hogares con 3 servicios básicos 2012 | D1: % de hogares con 3 servicios básicos 2024
A4: 1 | B4: Chuquisaca | C4: 50.164245 | D4: 64.304829
A5: 2 | B5: La Paz | C5: 52.742229 | D5: 65.202208
A6: 3 | B6: Cochabamba | C6: 42.192726 | D6: 51.036939
A7: 4 | B7: Oruro | C7: 41.639868 | D7: 54.906715
A8: 5 | B8: Potosí | C8: 36.363299 | D8: 46.350722
A9: 6 | B9: Tarija | C9: 67.174926 | D9: 74.006265
A10: 7 | B10: Santa Cruz | C10: 43.773009 | D10: 57.16375
A11: 8 | B11: Beni | C11: 20.766855 | D11: 28.566015
A12: 9 | B12: Pando | C12: 19.246994 | D12: 33.325702
A13: 10 | B13: Gran Chaco | C13: 65.076053 | D13: 73.016597
A14: 11 | B14: Bolivia | C14: 45.856571 | D14: 57.250123

Sheet Absoluto_DEP
A1: id_departamento | B1: Departamento | C1: Número de hogares que no tienen servicios básicos, 2012 | D1: Número de hogares que no tienen servicios básicos, 2024
A2: 1 | B2: Chuquisaca | C2: 25961 | D2: 11084
A3: 2 | B3: La Paz | C3: 79253 | D3: 44442
A4: 3 | B4: Cochabamba | C4: 57060 | D4: 40277
A5: 4 | B5: Oruro | C5: 21048 | D5: 12424
A6: 5 | B6: Potosí | C6: 35584 | D6: 24693
A7: 6 | B7: Tarija | C7: 4383 | D7: 1913
A8: 7 | B8: Santa Cruz | C8: 17773 | D8: 10375
A9: 8 | B9: Beni | C9: 7636 | D9: 6135
A10: 9 | B10: Pando | C10: 3033 | D10: 911
A11: 10 | B11: Gran Chaco | C11: 801 | D11: 373
A12: 11 | B12: Bolivia | C12: 251731 | D12: 152254

Sheet Umbral
A1: ODS | B1: Indicador | C1: Meta Alcanzada max | D1: Meta Alcanzada min | E1: Próximo a Alcanzarse max | F1: Próximo a Alcanzarse min | G1: Quedan Retos Importantes max | H1: Quedan Retos Importantes min | I1: Quedan Retos Grandes max | J1: Quedan Retos Grandes min
A2: 1 | B2: Acceso a los 3 servicios básicos, 2024 (% de hogares) | C2: 100 | D2: 85 | E2: 85 | F2: 68 | G2: 68 | H2: 50 | I2: 50 | J2: 0

Sheet Graficos
A1: Categoría | B1: 2012 | C1: 2024
A2: ODS alcanzado | B2: =COUNTIF( Clasificación!D2:D344, "Verde") -> 1 | C2: =COUNTIF(Clasificación!F2:F344, "Verde") -> 2
A3: Próximo a alcanzarse | B3: =COUNTIF(Clasificación!D2:D344, "Amarillo") -> 7 | C3: =COUNTIF(Clasificación!F2:F344, "Amarillo") -> 32
A4: Quedan retos importantes | B4: =COUNTIF(Clasificación!D2:D344, "Naranja") -> 26 | C4: =COUNTIF(Clasificación!F2:F344, "Naranja") -> 82
A5: Quedan retos grandes | B5: =COUNTIF(Clasificación!D2:D344, "Rojo") -> 309 | C5: =COUNTIF(Clasificación!F2:F344, "Rojo") -> 227

Sheet Mapas

Sheet Clasificación
A1: Codigo | B1: Municipio | C1: sdg1_4_acceso a 3_servicios_basicos, 2012 | D1: Umbral 2012 | E1: sdg1_4_acceso a 3_servicios_basicos, 2024 | F1: Umbral 2012
A2: 10101 | B2: Sucre | C2: 77.817713 | D2: =IF(C2<=50,"Rojo", IF(C2<=68,"Naranja", IF(C2<=85,"Amarillo","Verde"))) -> Amarillo | E2: 83.436902 | F2: =IF(E2<=50,"Rojo", IF(E2<=68,"Naranja", IF(E2<=85,"Amarillo","Verde"))) -> Amarillo
A3: 10102 | B3: Yotala | C3: 44.897959 | D3: =IF(C3<=50,"Rojo", IF(C3<=68,"Naranja", IF(C3<=85,"Amarillo","Verde"))) -> Rojo | E3: 63.645288 | F3: =IF(E3<=50,"Rojo", IF(E3<=68,"Naranja", IF(E3<=85,"Amarillo","Verde"))) -> Naranja
A4: 10103 | B4: Poroma | C4: 4.1879469 | D4: =IF(C4<=50,"Rojo", IF(C4<=68,"Naranja", IF(C4<=85,"Amarillo","Verde"))) -> Rojo | E4: 12.849162 | F4: =IF(E4<=50,"Rojo", IF(E4<=68,"Naranja", IF(E4<=85,"Amarillo","Verde"))) -> Rojo
A5: 10201 | B5: Azurduy | C5: 12.84476 | D5: =IF(C5<=50,"Rojo", IF(C5<=68,"Naranja", IF(C5<=85,"Amarillo","Verde"))) -> Rojo | E5: 29.55102 | F5: =IF(E5<=50,"Rojo", IF(E5<=68,"Naranja", IF(E5<=85,"Amarillo","Verde"))) -> Rojo
A6: 10202 | B6: Tarvita | C6: 13.136337 | D6: =IF(C6<=50,"Rojo", IF(C6<=68,"Naranja", IF(C6<=85,"Amarillo","Verde"))) -> Rojo | E6: 33.471074 | F6: =IF(E6<=50,"Rojo", IF(E6<=68,"Naranja", IF(E6<=85,"Amarillo","Verde"))) -> Rojo
A7: 10301 | B7: Zudáñez | C7: 27.803558 | D7: =IF(C7<=50,"Rojo", IF(C7<=68,"Naranja", IF(C7<=85,"Amarillo","Verde"))) -> Rojo | E7: 42.485096 | F7: =IF(E7<=50,"Rojo", IF(E7<=68,"Naranja", IF(E7<=85,"Amarillo","Verde"))) -> Rojo
A8: 10302 | B8: Presto | C8: 17.372102 | D8: =IF(C8<=50,"Rojo", IF(C8<=68,"Naranja", IF(C8<=85,"Amarillo","Verde"))) -> Rojo | E8: 37.78661 | F8: =IF(E8<=50,"Rojo", IF(E8<=68,"Naranja", IF(E8<=85,"Amarillo","Verde"))) -> Rojo
A9: 10303 | B9: Mojocoya | C9: 26.892028 | D9: =IF(C9<=50,"Rojo", IF(C9<=68,"Naranja", IF(C9<=85,"Amarillo","Verde"))) -> Rojo | E9: 49.036571 | F9: =IF(E9<=50,"Rojo", IF(E9<=68,"Naranja", IF(E9<=85,"Amarillo","Verde"))) -> Rojo
A10: 10304 | B10: Icla | C10: 39.377389 | D10: =IF(C10<=50,"Rojo", IF(C10<=68,"Naranja", IF(C10<=85,"Amarillo","Verde"))) -> Rojo | E10: 43.111954 | F10: =IF(E10<=50,"Rojo", IF(E10<=68,"Naranja", IF(E10<=85,"Amarillo","Verde"))) -> Rojo
A11: 10401 | B11: Padilla | C11: 33.451957 | D11: =IF(C11<=50,"Rojo", IF(C11<=68,"Naranja", IF(C11<=85,"Amarillo","Verde"))) -> Rojo | E11: 52.354049 | F11: =IF(E11<=50,"Rojo", IF(E11<=68,"Naranja", IF(E11<=85,"Amarillo","Verde"))) -> Naranja
A12: 10402 | B12: Tomina | C12: 28.064363 | D12: =IF(C12<=50,"Rojo", IF(C12<=68,"Naranja", IF(C12<=85,"Amarillo","Verde"))) -> Rojo | E12: 58.314757 | F12: =IF(E12<=50,"Rojo", IF(E12<=68,"Naranja", IF(E12<=85,"Amarillo","Verde"))) -> Naranja
A13: 10403 | B13: Sopachuy | C13: 26.766169 | D13: =IF(C13<=50,"Rojo", IF(C13<=68,"Naranja", IF(C13<=85,"Amarillo","Verde"))) -> Rojo | E13: 40.776234 | F13: =IF(E13<=50,"Rojo", IF(E13<=68,"Naranja", IF(E13<=85,"Amarillo","Verde"))) -> Rojo
... A344: 90503 | B344: Santos Mercado | C344: 8.3690987 | D344: =IF(C344<=50,"Rojo", IF(C344<=68,"Naranja", IF(C344<=85,"Amarillo","Verde"))) -> Rojo | E344: 14.975042 | F344: =IF(E344<=50,"Rojo", IF(E344<=68,"Naranja", IF(E344<=85,"Amarillo","Verde"))) -> Rojo
