Workbook

Sheet  2012 MORT INFANTIL CENSO
A1: id | B1: DEPARTAMENTO | C1: PROVINCIA | D1: MUNICIPIO | E1: Tasa de mortalidad infantil (< 1 año) (por 1,000 nacidos vivos) 2012 (CENSO) | F1: Número de niños fallecidos antes de cumplir 1 año 2012 (CENSO) | G1: CENSO NACIDOS VIVOS (CENSO) | J1: Departamento | K1: Número de niños fallecidos antes de cumplir 1 año 2012 | L1: NACIDOS VIVOS 2012 | M1: Tasa de mortalidad infantil (< 1 año) (por 1,000 nacidos vivos) 2012
A2: 10101 | B2: Chuquisaca | C2: Oropeza | D2: Sucre | E2: =(F2/G2)*1000 -> 21.000981 | F2: 107 | G2: 5095 | J2: Chuquisaca | K2: =SUM(F2:F30) -> 287 | L2: =SUM(G2:G30) -> 11564 | M2: =(K2/L2)*1000 -> 24.818402
A3: 10102 | B3: Chuquisaca | C3: Oropeza | D3: Yotala | E3: =(F3/G3)*1000 -> 23.668639 | F3: 4 | G3: 169 | J3: La Paz | K3: =+SUM(F31:F117) -> 1725 | L3: =+SUM(G31:G117) -> 54260 | M3: =(K3/L3)*1000 -> 31.791375
A4: 10103 | B4: Chuquisaca | C4: Oropeza | D4: Poroma | E4: =(F4/G4)*1000 -> 33.163265 | F4: 13 | G4: 392 | J4: Cochabamba | K4: =+SUM(F118:F165) -> 911 | L4: =+SUM(G118:G165) -> 37795 | M4: =(K4/L4)*1000 -> 24.103717
A5: 10201 | B5: Chuquisaca | C5: Azurduy | D5: Villa Azurduy | E5: =(F5/G5)*1000 -> 26.200873 | F5: 6 | G5: 229 | J5: Oruro | K5: =+SUM(F166:F200) -> 209 | L5: =+SUM(G166:G200) -> 10072 | M5: =(K5/L5)*1000 -> 20.750596
A6: 10202 | B6: Chuquisaca | C6: Azurduy | D6: Tarvita | E6: =(F6/G6)*1000 -> 21.582734 | F6: 6 | G6: 278 | J6: Potosi | K6: =+SUM(F201:F242) -> 770 | L6: =+SUM(G201:G242) -> 18587 | M6: =(K6/L6)*1000 -> 41.426804
A7: 10301 | B7: Chuquisaca | C7: Zudáñez | D7: Zudañez | E7: =(F7/G7)*1000 -> 36.199095 | F7: 8 | G7: 221 | J7: Tarija | K7: =+SUM(F243:F253) -> 157 | L7: =+SUM(G243:G253) -> 9314 | M7: =(K7/L7)*1000 -> 16.856345
A8: 10302 | B8: Chuquisaca | C8: Zudáñez | D8: Presto | E8: =(F8/G8)*1000 -> 58.181818 | F8: 16 | G8: 275 | J8: Santa Cruz | K8: =+SUM(F254:F309) -> 965 | L8: =+SUM(G254:G309) -> 62306 | M8: =(K8/L8)*1000 -> 15.488075
A9: 10303 | B9: Chuquisaca | C9: Zudáñez | D9: Villa Mojocoya | E9: =(F9/G9)*1000 -> 53.030303 | F9: 7 | G9: 132 | J9: Beni | K9: =+SUM(F310:F329) -> 322 | L9: =+SUM(G310:G329) -> 12026 | M9: =(K9/L9)*1000 -> 26.77532
A10: 10304 | B10: Chuquisaca | C10: Zudáñez | D10: Icla | E10: =(F10/G10)*1000 -> 14.388489 | F10: 2 | G10: 139 | J10: Pando | K10: =+SUM(F330:F344) -> 15 | L10: =+SUM(G330:G344) -> 3404 | M10: =(K10/L10)*1000 -> 4.4065805
A11: 10401 | B11: Chuquisaca | C11: Tomina | D11: Padilla | E11: =(F11/G11)*1000 -> 37.634409 | F11: 7 | G11: 186 | J11: Bolivia | K11: =SUM(K2:K10) -> 5361 | L11: =SUM(L2:L10) -> 219328 | M11: =(K11/L11)*1000 -> 24.442844
A12: 10402 | B12: Chuquisaca | C12: Tomina | D12: Tomina | E12: =(F12/G12)*1000 -> 30.30303 | F12: 6 | G12: 198 | J12: Gran Chaco | K12: 69 | L12: 3036 | M12: =(K12/L12)*1000 -> 22.727273
A13: 10403 | B13: Chuquisaca | C13: Tomina | D13: Sopachuy | E13: =(F13/G13)*1000 -> 15.503876 | F13: 2 | G13: 129
A14: 10404 | B14: Chuquisaca | C14: Tomina | D14: Villa Alcalá | E14: =(F14/G14)*1000 -> 0 | F14: 0 | G14: 64
A15: 10405 | B15: Chuquisaca | C15: Tomina | D15: El Villar | E15: =(F15/G15)*1000 -> 28.985507 | F15: 2 | G15: 69
A16: 10501 | B16: Chuquisaca | C16: Hernando Siles | D16: Monteagudo | E16: =(F16/G16)*1000 -> 35.789474 | F16: 17 | G16: 475
A17: 10502 | B17: Chuquisaca | C17: Hernando Siles | D17: San Pablo de Huacareta | E17: =(F17/G17)*1000 -> 12.048193 | F17: 2 | G17: 166
A18: 10601 | B18: Chuquisaca | C18: Yamparáez | D18: Tarabuco | E18: =(F18/G18)*1000 -> 42.071197 | F18: 13 | G18: 309
A19: 10602 | B19: Chuquisaca | C19: Yamparáez | D19: Yamparáez | E19: =(F19/G19)*1000 -> 13.157895 | F19: 2 | G19: 152
A20: 10701 | B20: Chuquisaca | C20: Nor Cinti | D20: Camargo | E20: =(F20/G20)*1000 -> 10.452962 | F20: 3 | G20: 287
A21: 10702 | B21: Chuquisaca | C21: Nor Cinti | D21: San Lucas | E21: =(F21/G21)*1000 -> 31.563845 | F21: 22 | G21: 697
A22: 10703 | B22: Chuquisaca | C22: Nor Cinti | D22: Incahuasi | E22: =(F22/G22)*1000 -> 26.470588 | F22: 9 | G22: 340
A23: 10704 | B23: Chuquisaca | C23: Nor Cinti | D23: Villa Charcas | E23: =(F23/G23)*1000 -> 41.564792 | F23: 17 | G23: 409
A24: 10801 | B24: Chuquisaca | C24: Belisario Boeto | D24: Villa Serrano | E24: =(F24/G24)*1000 -> 5 | F24: 1 | G24: 200
... A178: 40503 | B178: Oruro | C178: Litoral | D178: Cruz de Machacamarca | E178: =(F178/G178)*1000 -> 58.823529 | F178: 2 | G178: 34
A179: 40504 | B179: Oruro | C179: Litoral | D179: Yunguyo del Litoral | E179: =(F179/G179)*1000 -> 0 | G179: 8
A180: 40505 | B180: Oruro | C180: Litoral | D180: Esmeralda | E180: =(F180/G180)*1000 -> 0 | F180: 0 | G180: 60
A181: 40601 | B181: Oruro | C181: Poopó | D181: Poopó | E181: =(F181/G181)*1000 -> 84.033613 | F181: 10 | G181: 119
A182: 40602 | B182: Oruro | C182: Poopó | D182: Pazña | E182: =(F182/G182)*1000 -> 26.785714 | F182: 3 | G182: 112
A183: 40603 | B183: Oruro | C183: Poopó | D183: Antequera | E183: =(F183/G183)*1000 -> 16.393443 | F183: 1 | G183: 61
A184: 40701 | B184: Oruro | C184: Pantaleón Dalence | D184: Huanuni | E184: =(F184/G184)*1000 -> 18.975332 | F184: 10 | G184: 527
A185: 40702 | B185: Oruro | C185: Pantaleón Dalence | D185: Machacamarca | E185: =(F185/G185)*1000 -> 22.727273 | F185: 2 | G185: 88
A186: 40801 | B186: Oruro | C186: Ladislao Cabrera | D186: Salinas de Garcí Mendoza | E186: =(F186/G186)*1000 -> 35.714286 | F186: 7 | G186: 196
A187: 40802 | B187: Oruro | C187: Ladislao Cabrera | D187: Pampa Aullagas | E187: =(F187/G187)*1000 -> 0 | F187: 0 | G187: 64
A188: 40901 | B188: Oruro | C188: Sabaya | D188: Sabaya | E188: =(F188/G188)*1000 -> 22.59887 | F188: 4 | G188: 177
A189: 40902 | B189: Oruro | C189: Sabaya | D189: Coipasa | E189: =(F189/G189)*1000 -> 0 | F189: 0 | G189: 18
A190: 40903 | B190: Oruro | C190: Sabaya | D190: Chipaya | E190: =(F190/G190)*1000 -> 58.823529 | F190: 3 | G190: 51
A191: 41001 | B191: Oruro | C191: Saucarí | D191: Toledo | E191: =(F191/G191)*1000 -> 27.586207 | F191: 4 | G191: 145
... A198: 41502 | B198: Oruro | C198: Mejillones | D198: Todos Santos | E198: =(F198/G198)*1000 -> 0 | F198: 0 | G198: 20
A199: 41503 | B199: Oruro | C199: Mejillones | D199: Carangas | E199: =(F199/G199)*1000 -> 0 | G199: 15
...

Sheet  2024 MORT INFA
A1: id | B1: DEPARTAMENTO | C1: PROVINCIA | D1: MUNICIPIO | E1: Tasa de mortalidad infantil (< 1 año) (por 1,000 nacidos vivos) 2019-2023 (CENSO) | F1: Número de niños fallecidos antes de cumplir 1 año (2019-2023) (CENSO) | G1: CENSO NACIDOS VIVOS (CENSO)(2019-2023) | H1: Número de niños fallecidos antes de cumplir 1 año (CENSO) PROMEDIO | I1: CENSO NACIDOS VIVOS (CENSO) PROMEDIO | L1: Departamento | M1: Número de niños fallecidos antes de cumplir 1 año (2019-2023) | N1: NACIDOS VIVOS (2019-2023) | O1: Tasa de mortalidad infantil (< 1 año) (por 1,000 nacidos vivos) 2019-2023
A2: 10101 | B2: Chuquisaca | C2: Oropeza | D2: Sucre | E2: =(F2/G2)*1000 -> 7.1390953 | F2: 122 | G2: 17089 | H2: =F2/5 -> 24.4 | I2: =G2/5 -> 3417.8 | L2: Chuquisaca | M2: =SUM(F2:F30) -> 330 | N2: =SUM(G2:G30) -> 35806 | O2: =(M2/N2)*1000 -> 9.2163325
A3: 10102 | B3: Chuquisaca | C3: Oropeza | D3: Yotala | E3: =(F3/G3)*1000 -> 17.34104 | F3: 9 | G3: 519 | H3: =F3/5 -> 1.8 | I3: =G3/5 -> 103.8 | L3: La Paz | M3: =+SUM(F31:F117) -> 2288 | N3: =+SUM(G31:G117) -> 175213 | O3: =(M3/N3)*1000 -> 13.058392
A4: 10103 | B4: Chuquisaca | C4: Oropeza | D4: Poroma | E4: =(F4/G4)*1000 -> 18.454441 | F4: 16 | G4: 867 | H4: =F4/5 -> 3.2 | I4: =G4/5 -> 173.4 | L4: Cochabamba | M4: =+SUM(F118:F165) -> 1317 | N4: =+SUM(G118:G165) -> 128674 | O4: =(M4/N4)*1000 -> 10.235168
A5: 10201 | B5: Chuquisaca | C5: Azurduy | D5: Villa Azurduy | E5: =(F5/G5)*1000 -> 15.296367 | F5: 8 | G5: 523 | H5: =F5/5 -> 1.6 | I5: =G5/5 -> 104.6 | L5: Oruro | M5: =+SUM(F166:F200) -> 455 | N5: =+SUM(G166:G200) -> 35024 | O5: =(M5/N5)*1000 -> 12.991092
A6: 10202 | B6: Chuquisaca | C6: Azurduy | D6: Tarvita | E6: =(F6/G6)*1000 -> 10.587103 | F6: 11 | G6: 1039 | H6: =F6/5 -> 2.2 | I6: =G6/5 -> 207.8 | L6: Potosi | M6: =+SUM(F201:F242) -> 979 | N6: =+SUM(G201:G242) -> 57031 | O6: =(M6/N6)*1000 -> 17.166103
A7: 10301 | B7: Chuquisaca | C7: Zudáñez | D7: Zudañez | E7: =(F7/G7)*1000 -> 3.7313433 | F7: 3 | G7: 804 | H7: =F7/5 -> 0.6 | I7: =G7/5 -> 160.8 | L7: Tarija | M7: =+SUM(F243:F253) -> 201 | N7: =+SUM(G243:G253) -> 31547 | O7: =(M7/N7)*1000 -> 6.3714458
A8: 10302 | B8: Chuquisaca | C8: Zudáñez | D8: Presto | E8: =(F8/G8)*1000 -> 10.269576 | F8: 8 | G8: 779 | H8: =F8/5 -> 1.6 | I8: =G8/5 -> 155.8 | L8: Santa Cruz | M8: =+SUM(F254:F309) -> 1631 | N8: =+SUM(G254:G309) -> 210592 | O8: =(M8/N8)*1000 -> 7.7448336
A9: 10303 | B9: Chuquisaca | C9: Zudáñez | D9: Villa Mojocoya | E9: =(F9/G9)*1000 -> 9.1407678 | F9: 5 | G9: 547 | H9: =F9/5 -> 1 | I9: =G9/5 -> 109.4 | L9: Beni | M9: =+SUM(F310:F329) -> 336 | N9: =+SUM(G310:G329) -> 36199 | O9: =(M9/N9)*1000 -> 9.2820244
A10: 10304 | B10: Chuquisaca | C10: Zudáñez | D10: Icla | E10: =(F10/G10)*1000 -> 9.6339114 | F10: 5 | G10: 519 | H10: =F10/5 -> 1 | I10: =G10/5 -> 103.8 | L10: Pando | M10: =+SUM(F330:F344) -> 71 | N10: =+SUM(G330:G344) -> 9512 | O10: =(M10/N10)*1000 -> 7.4642557
A11: 10401 | B11: Chuquisaca | C11: Tomina | D11: Padilla | E11: =(F11/G11)*1000 -> 5.1369863 | F11: 3 | G11: 584 | H11: =F11/5 -> 0.6 | I11: =G11/5 -> 116.8 | L11: Bolivia | M11: =SUM(M2:M10) -> 7608 | N11: =SUM(N2:N10) -> 719598 | O11: =(M11/N11)*1000 -> 10.57257
A12: 10402 | B12: Chuquisaca | C12: Tomina | D12: Tomina | E12: =(F12/G12)*1000 -> 5.5045872 | F12: 3 | G12: 545 | H12: =F12/5 -> 0.6 | I12: =G12/5 -> 109
A13: 10403 | B13: Chuquisaca | C13: Tomina | D13: Sopachuy | E13: =(F13/G13)*1000 -> 2.3364486 | F13: 1 | G13: 428 | H13: =F13/5 -> 0.2 | I13: =G13/5 -> 85.6
A14: 10404 | B14: Chuquisaca | C14: Tomina | D14: Villa Alcalá | E14: =(F14/G14)*1000 -> 4.9019608 | F14: 1 | G14: 204 | H14: =F14/5 -> 0.2 | I14: =G14/5 -> 40.8
A15: 10405 | B15: Chuquisaca | C15: Tomina | D15: El Villar | E15: =(F15/G15)*1000 -> 11.83432 | F15: 4 | G15: 338 | H15: =F15/5 -> 0.8 | I15: =G15/5 -> 67.6
A16: 10501 | B16: Chuquisaca | C16: Hernando Siles | D16: Monteagudo | E16: =(F16/G16)*1000 -> 6.4102564 | F16: 9 | G16: 1404 | H16: =F16/5 -> 1.8 | I16: =G16/5 -> 280.8 | L16: ID | M16: Departamento | N16: MORTALIDAD INFANTIL (1q0) 2008 | O16: MORTALIDAD INFANTIL (1q0) 2023 * | P16: Diferencia 2008 | Q16: Diferencia 2023 | R16: Nacidos vivos ENDSA 2008 Número de caso sin ponderar | S16: Nacidos vivos ENDSA 2008 Número de casos ponderador | T16: Nacidos vivos EDSA 2023 Número de caso sin ponderar | U16: Nacidos vivos EDSA 2023 Número de casos ponderador
A17: 10502 | B17: Chuquisaca | C17: Hernando Siles | D17: San Pablo de Huacareta | E17: =(F17/G17)*1000 -> 8.5287846 | F17: 4 | G17: 469 | H17: =F17/5 -> 0.8 | I17: =G17/5 -> 93.8 | L17: 1 | M17: Chuquisaca | N17: 22 | O17: 8 | P17: ='Indicador_DEP '!C2-N17 -> 0 | Q17: ='Indicador_DEP '!D2-O17 -> 0 | R17: 1536 | S17: 964 | T17: 571 | U17: 370
A18: 10601 | B18: Chuquisaca | C18: Yamparáez | D18: Tarabuco | E18: =(F18/G18)*1000 -> 18.232819 | F18: 13 | G18: 713 | H18: =F18/5 -> 2.6 | I18: =G18/5 -> 142.6 | L18: 2 | M18: La Paz | N18: 59 | O18: 15 | P18: ='Indicador_DEP '!C3-N18 -> 0 | Q18: ='Indicador_DEP '!D3-O18 -> 2 | R18: 3325 | S18: 5129 | T18: 1226 | U18: 1738
A19: 10602 | B19: Chuquisaca | C19: Yamparáez | D19: Yamparáez | E19: =(F19/G19)*1000 -> 6.5217391 | F19: 3 | G19: 460 | H19: =F19/5 -> 0.6 | I19: =G19/5 -> 92 | L19: 3 | M19: Cochabamba | N19: 57 | O19: 6 | P19: ='Indicador_DEP '!C4-N19 -> 0 | Q19: ='Indicador_DEP '!D4-O19 -> 5 | R19: 2276 | S19: 3081 | T19: 974 | U19: 1257
A20: 10701 | B20: Chuquisaca | C20: Nor Cinti | D20: Camargo | E20: =(F20/G20)*1000 -> 13.414634 | F20: 11 | G20: 820 | H20: =F20/5 -> 2.2 | I20: =G20/5 -> 164 | L20: 4 | M20: Oruro | N20: 51 | O20: 29 | P20: ='Indicador_DEP '!C5-N20 -> 0 | Q20: ='Indicador_DEP '!D5-O20 -> 2 | R20: 1565 | S20: 937 | T20: 628 | U20: 291
A21: 10702 | B21: Chuquisaca | C21: Nor Cinti | D21: San Lucas | E21: =(F21/G21)*1000 -> 15.960374 | F21: 29 | G21: 1817 | H21: =F21/5 -> 5.8 | I21: =G21/5 -> 363.4 | L21: 5 | M21: Potosí | N21: 91 | O21: 21 | P21: ='Indicador_DEP '!C6-N21 -> 0 | Q21: ='Indicador_DEP '!D6-O21 -> 21 | R21: 1779 | S21: 1634 | T21: 727 | U21: 509
A22: 10703 | B22: Chuquisaca | C22: Nor Cinti | D22: Incahuasi | E22: =(F22/G22)*1000 -> 15.355086 | F22: 16 | G22: 1042 | H22: =F22/5 -> 3.2 | I22: =G22/5 -> 208.4 | L22: 6 | M22: Tarija | N22: 33 | O22: 21 | P22: ='Indicador_DEP '!C7-N22 -> 0 | Q22: ='Indicador_DEP '!D7-O22 -> 4 | R22: 1717 | S22: 831 | T22: 527 | U22: 355
A23: 10704 | B23: Chuquisaca | C23: Nor Cinti | D23: Villa Charcas | E23: =(F23/G23)*1000 -> 8.8932806 | F23: 9 | G23: 1012 | H23: =F23/5 -> 1.8 | I23: =G23/5 -> 202.4 | L23: 7 | M23: Santa Cruz | N23: 21 | O23: 6 | P23: ='Indicador_DEP '!C8-N23 -> 0 | Q23: ='Indicador_DEP '!D8-O23 -> 2 | R23: 2933 | S23: 3717 | T23: 1112 | U23: 2087
A24: 10801 | B24: Chuquisaca | C24: Belisario Boeto | D24: Villa Serrano | E24: =(F24/G24)*1000 -> 9.8231827 | F24: 5 | G24: 509 | H24: =F24/5 -> 1 | I24: =G24/5 -> 101.8 | L24: 8 | M24: Beni | N24: 34 | O24: 13 | P24: ='Indicador_DEP '!C9-N24 -> 0 | Q24: ='Indicador_DEP '!D9-O24 -> 11 | R24: 545 | S24: 1431 | T24: 639 | U24: 331
A25: 10901 | B25: Chuquisaca | C25: Sur Cinti | D25: Villa Abecia | E25: =(F25/G25)*1000 -> 3.30033 | F25: 1 | G25: 303 | H25: =F25/5 -> 0.2 | I25: =G25/5 -> 60.6 | L25: 9 | M25: Pando | N25: =43 -> 43 | O25: 10 | P25: ='Indicador_DEP '!C10-N25 -> 0 | Q25: ='Indicador_DEP '!D10-O25 -> 0 | R25: 749 | S25: 99 | T25: 657 | U25: 106
A26: 10902 | B26: Chuquisaca | C26: Sur Cinti | D26: Culpina | E26: =(F26/G26)*1000 -> 15.015015 | F26: 15 | G26: 999 | H26: =F26/5 -> 3 | I26: =G26/5 -> 199.8 | L26: 11 | M26: Bolivia | N26: 50 | O26: 12 | P26: ='Indicador_DEP '!C12-N26 -> 0 | Q26: ='Indicador_DEP '!D12-O26 -> 4 | R26: 16939 | S26: 16939 | T26: 7061 | U26: 7043
A27: 10903 | B27: Chuquisaca | C27: Sur Cinti | D27: Las Carreras | E27: =(F27/G27)*1000 -> 4.1666667 | F27: 1 | G27: 240 | H27: =F27/5 -> 0.2 | I27: =G27/5 -> 48 | L27: (*) Con coeficiente de variación superior a 20% emplearlo solo de forma referencial | M27: urbano | N27: 36 | O27: 9 | Q27: Urbano | R27: 10905 | S27: 11183 | T27: 4821 | U27: 4905
A28: 11001 | B28: Chuquisaca | C28: Luis Calvo | D28: Villa Vaca Guzman | E28: =(F28/G28)*1000 -> 6.2992126 | F28: 4 | G28: 635 | H28: =F28/5 -> 0.8 | I28: =G28/5 -> 127 | M28: Rural | N28: 67 | O28: 17 | Q28: Rural | R28: 6034 | S28: 5756 | T28: 2240 | U28: 2137
A29: 11002 | B29: Chuquisaca | C29: Luis Calvo | D29: Huacaya | E29: =(F29/G29)*1000 -> 17.964072 | F29: 3 | G29: 167 | H29: =F29/5 -> 0.6 | I29: =G29/5 -> 33.4
A30: 11003 | B30: Chuquisaca | C30: Luis Calvo | D30: Macharetí | E30: =(F30/G30)*1000 -> 18.561485 | F30: 8 | G30: 431 | H30: =F30/5 -> 1.6 | I30: =G30/5 -> 86.2
A31: 20101 | B31: La Paz | C31: Murillo | D31: Nuestra Señora de La Paz | E31: =(F31/G31)*1000 -> 10.194625 | F31: 352 | G31: 34528 | H31: =F31/5 -> 70.4 | I31: =G31/5 -> 6905.6
A32: 20102 | B32: La Paz | C32: Murillo | D32: Palca | E32: =(F32/G32)*1000 -> 17.275748 | F32: 26 | G32: 1505 | H32: =F32/5 -> 5.2 | I32: =G32/5 -> 301
A33: 20103 | B33: La Paz | C33: Murillo | D33: Mecapaca | E33: =(F33/G33)*1000 -> 12.100259 | F33: 14 | G33: 1157 | H33: =F33/5 -> 2.8 | I33: =G33/5 -> 231.4
A34: 20104 | B34: La Paz | C34: Murillo | D34: Achocalla | E34: =(F34/G34)*1000 -> 13.062908 | F34: 38 | G34: 2909 | H34: =F34/5 -> 7.6 | I34: =G34/5 -> 581.8
A35: 20105 | B35: La Paz | C35: Murillo | D35: El Alto | E35: =(F35/G35)*1000 -> 13.18608 | F35: 751 | G35: 56954 | H35: =F35/5 -> 150.2 | I35: =G35/5 -> 11390.8
A36: 20201 | B36: La Paz | C36: Omasuyos | D36: Achacachi | E36: =(F36/G36)*1000 -> 16.406563 | F36: 41 | G36: 2499 | H36: =F36/5 -> 8.2 | I36: =G36/5 -> 499.8
A37: 20202 | B37: La Paz | C37: Omasuyos | D37: Ancoraimes | E37: =(F37/G37)*1000 -> 13.398295 | F37: 11 | G37: 821 | H37: =F37/5 -> 2.2 | I37: =G37/5 -> 164.2
A38: 20203 | B38: La Paz | C38: Omasuyos | D38: Chua Cocani | E38: =(F38/G38)*1000 -> 18.018018 | F38: 6 | G38: 333 | H38: =F38/5 -> 1.2 | I38: =G38/5 -> 66.6
A39: 20204 | B39: La Paz | C39: Omasuyos | D39: Huarina | E39: =(F39/G39)*1000 -> 14.354067 | F39: 6 | G39: 418 | H39: =F39/5 -> 1.2 | I39: =G39/5 -> 83.6
A40: 20205 | B40: La Paz | C40: Omasuyos | D40: Santiago de Huata | E40: =(F40/G40)*1000 -> 7.2463768 | F40: 3 | G40: 414 | H40: =F40/5 -> 0.6 | I40: =G40/5 -> 82.8
...

Sheet Datos procesados_EDSA_y_Cen2012
A1: id | B1: DEPARTAMENTO | C1: PROVINCIA | D1: MUNICIPIO | E1: Número de niños fallecidos antes de cumplir 1 año (CENSO) PROMEDIO | F1: CENSO NACIDOS VIVOS (CENSO) PROMEDIO | G1: Porcentaje de fallecidos por municipio | H1: Estimados fallecidos por municipio con EDSA | I1: Porcentaje de nacidos por municipio | J1: Estimados nacidos por municipio con EDSA | K1: Tasa de mortalidad acorde a EDSA distribuido por censo 2024 | M1: id_departamento | N1: Departamento | O1: Tasa de mortalidad infantil (< 1 año) (por 1,000 nacidos vivos) 2012 | P1: Tasa de mortalidad infantil (< 1 año) (por 1,000 nacidos vivos) 2024 | Q1: Departamento | R1: Número de niños fallecidos antes de cumplir 1 año 2012 CENSO | S1: CENSO NACIDOS VIVOS 2012 | T1: MORTALIDAD INFANTIL (1q0) 2008
A2: 10101 | B2: Chuquisaca | C2: Oropeza | D2: Sucre | E2: 107 | F2: 5095 | G2: =E2/$R$2 -> 0.3728223 | H2: =$S$17*G2 -> 7.9068153 | I2: =F2/$S$2 -> 0.44059149 | J2: =I2*$U$17 -> 424.7302 | K2: =1000*H2/J2 -> 18.616089 | M2: 1 | N2: Chuquisaca | O2: 24.818402 | P2: 8.8076422 | Q2: Chuquisaca | R2: 287 | S2: 11564 | T2: 22
A3: 10102 | B3: Chuquisaca | C3: Oropeza | D3: Yotala | E3: 4 | F3: 169 | G3: =E3/$R$2 -> 0.013937282 | H3: =$S$17*G3 -> 0.29558188 | I3: =F3/$S$2 -> 0.01461432 | J3: =I3*$U$17 -> 14.088205 | K3: =1000*H3/J3 -> 20.980805 | M3: 2 | N3: La Paz | O3: 31.791375 | P3: 12.522002 | Q3: La Paz | R3: 1725 | S3: 54260 | T3: 59
A4: 10103 | B4: Chuquisaca | C4: Oropeza | D4: Poroma | E4: 13 | F4: 392 | G4: =E4/$R$2 -> 0.045296167 | H4: =$S$17*G4 -> 0.96064112 | I4: =F4/$S$2 -> 0.033898305 | J4: =I4*$U$17 -> 32.677966 | K4: =1000*H4/J4 -> 29.397213 | M4: 3 | N4: Cochabamba | O4: 24.103717 | P4: 9.8247123 | Q4: Cochabamba | R4: 911 | S4: 37795 | T4: 57
A5: 10201 | B5: Chuquisaca | C5: Azurduy | D5: Villa Azurduy | E5: 6 | F5: 229 | G5: =E5/$R$2 -> 0.020905923 | H5: =$S$17*G5 -> 0.44337282 | I5: =F5/$S$2 -> 0.019802836 | J5: =I5*$U$17 -> 19.089934 | K5: =1000*H5/J5 -> 23.225477 | M5: 4 | N5: Oruro | O5: 20.750596 | P5: 12.381883 | Q5: Oruro | R5: 209 | S5: 10072 | T5: 51
A6: 10202 | B6: Chuquisaca | C6: Azurduy | D6: Tarvita | E6: 6 | F6: 278 | G6: =E6/$R$2 -> 0.020905923 | H6: =$S$17*G6 -> 0.44337282 | I6: =F6/$S$2 -> 0.024040125 | J6: =I6*$U$17 -> 23.17468 | K6: =1000*H6/J6 -> 19.131777 | M6: 5 | N6: Potosí | O6: 41.426804 | P6: 16.377842 | Q6: Potosi | R6: 770 | S6: 18587 | T6: 91
A7: 10301 | B7: Chuquisaca | C7: Zudáñez | D7: Zudañez | E7: 8 | F7: 221 | G7: =E7/$R$2 -> 0.027874564 | H7: =$S$17*G7 -> 0.59116376 | I7: =F7/$S$2 -> 0.019111034 | J7: =I7*$U$17 -> 18.423037 | K7: =1000*H7/J7 -> 32.08829 | M7: 6 | N7: Tarija | O7: 16.856345 | P7: 6.115097 | Q7: Tarija | R7: 157 | S7: 9314 | T7: 33
A8: 10302 | B8: Chuquisaca | C8: Zudáñez | D8: Presto | E8: 16 | F8: 275 | G8: =E8/$R$2 -> 0.055749129 | H8: =$S$17*G8 -> 1.1823275 | I8: =F8/$S$2 -> 0.023780699 | J8: =I8*$U$17 -> 22.924594 | K8: =1000*H8/J8 -> 51.574634 | M8: 7 | N8: Santa Cruz | O8: 15.488075 | P8: 7.3922008 | Q8: Santa Cruz | R8: 965 | S8: 62306 | T8: 21
A9: 10303 | B9: Chuquisaca | C9: Zudáñez | D9: Villa Mojocoya | E9: 7 | F9: 132 | G9: =E9/$R$2 -> 0.024390244 | H9: =$S$17*G9 -> 0.51726829 | I9: =F9/$S$2 -> 0.011414735 | J9: =I9*$U$17 -> 11.003805 | K9: =1000*H9/J9 -> 47.00813 | M9: 8 | N9: Beni | O9: 26.77532 | P9: 8.8360995 | Q9: Beni | R9: 322 | S9: 12026 | T9: 34
A10: 10304 | B10: Chuquisaca | C10: Zudáñez | D10: Icla | E10: 2 | F10: 139 | G10: =E10/$R$2 -> 0.0069686411 | H10: =$S$17*G10 -> 0.14779094 | I10: =F10/$S$2 -> 0.012020062 | J10: =I10*$U$17 -> 11.58734 | K10: =1000*H10/J10 -> 12.754518 | M10: 9 | N10: Pando | O10: 4.4065805 | P10: 7.2927073 | Q10: Pando | R10: 15 | S10: 3404 | T10: =43 -> 43
A11: 10401 | B11: Chuquisaca | C11: Tomina | D11: Padilla | E11: 7 | F11: 186 | G11: =E11/$R$2 -> 0.024390244 | H11: =$S$17*G11 -> 0.51726829 | I11: =F11/$S$2 -> 0.0160844 | J11: =I11*$U$17 -> 15.505361 | K11: =1000*H11/J11 -> 33.360608 | M11: 10 | N11: Gran Chaco | O11: 22.727273 | P11: 8.2292574 | Q11: Gran Chaco | R11: 69 | S11: 3036 | T11: =SUM(H246:H248)/SUM(J246:J248)*1000 -> 44.493631
A12: 10402 | B12: Chuquisaca | C12: Tomina | D12: Tomina | E12: 6 | F12: 198 | G12: =E12/$R$2 -> 0.020905923 | H12: =$S$17*G12 -> 0.44337282 | I12: =F12/$S$2 -> 0.017122103 | J12: =I12*$U$17 -> 16.505707 | K12: =1000*H12/J12 -> 26.861789 | M12: 11 | N12: Bolivia | O12: 24.442844 | P12: 10.114268 | Q12: Bolivia | R12: 5361 | S12: 219328 | T12: 50
A13: 10403 | B13: Chuquisaca | C13: Tomina | D13: Sopachuy | E13: 2 | F13: 129 | G13: =E13/$R$2 -> 0.0069686411 | H13: =$S$17*G13 -> 0.14779094 | I13: =F13/$S$2 -> 0.01115531 | J13: =I13*$U$17 -> 10.753718 | K13: =1000*H13/J13 -> 13.743241
A14: 10404 | B14: Chuquisaca | C14: Tomina | D14: Villa Alcalá | E14: 0 | F14: 64 | G14: =E14/$R$2 -> 0 | H14: =$S$17*G14 -> 0 | I14: =F14/$S$2 -> 0.0055344172 | J14: =I14*$U$17 -> 5.3351781 | K14: =1000*H14/J14 -> 0
A15: 10405 | B15: Chuquisaca | C15: Tomina | D15: El Villar | E15: 2 | F15: 69 | G15: =E15/$R$2 -> 0.0069686411 | H15: =$S$17*G15 -> 0.14779094 | I15: =F15/$S$2 -> 0.0059667935 | J15: =I15*$U$17 -> 5.7519889 | K15: =1000*H15/J15 -> 25.693885
A16: 10501 | B16: Chuquisaca | C16: Hernando Siles | D16: Monteagudo | E16: 17 | F16: 475 | G16: =E16/$R$2 -> 0.059233449 | H16: =$S$17*G16 -> 1.256223 | I16: =F16/$S$2 -> 0.041075752 | J16: =I16*$U$17 -> 39.597025 | K16: =1000*H16/J16 -> 31.725186 | M16: ID | N16: Departamento | O16: MORTALIDAD INFANTIL (1q0) 2008 | P16: MORTALIDAD INFANTIL (1q0) 2023 * | Q16: Diferencia 2008 | R16: Diferencia 2023 | S16: Defunciones aproximadas con EDSA 2023 | T16: Nacidos vivos ENDSA 2008 Número de caso sin ponderar | U16: Nacidos vivos ENDSA 2008 Número de casos ponderador
A17: 10502 | B17: Chuquisaca | C17: Hernando Siles | D17: San Pablo de Huacareta | E17: 2 | F17: 166 | G17: =E17/$R$2 -> 0.0069686411 | H17: =$S$17*G17 -> 0.14779094 | I17: =F17/$S$2 -> 0.014354894 | J17: =I17*$U$17 -> 13.838118 | K17: =1000*H17/J17 -> 10.679988 | M17: 1 | N17: Chuquisaca | O17: 22 | P17: 8 | Q17: =O2-O17 -> 2.8184019 | R17: =P2-P17 -> 0.80764216 | S17: =O17*U17/1000 -> 21.208 | T17: 1536 | U17: 964
A18: 10601 | B18: Chuquisaca | C18: Yamparáez | D18: Tarabuco | E18: 13 | F18: 309 | G18: =E18/$R$2 -> 0.045296167 | H18: =$S$17*G18 -> 0.96064112 | I18: =F18/$S$2 -> 0.026720858 | J18: =I18*$U$17 -> 25.758907 | K18: =1000*H18/J18 -> 37.293551 | M18: 2 | N18: La Paz | O18: 59 | P18: 15 | Q18: =O3-O18 -> -27.208625 | R18: =P3-P18 -> -2.4779982 | S18: =O18*U18/1000 -> 302.611 | T18: 3325 | U18: 5129
A19: 10602 | B19: Chuquisaca | C19: Yamparáez | D19: Yamparáez | E19: 2 | F19: 152 | G19: =E19/$R$2 -> 0.0069686411 | H19: =$S$17*G19 -> 0.14779094 | I19: =F19/$S$2 -> 0.013144241 | J19: =I19*$U$17 -> 12.671048 | K19: =1000*H19/J19 -> 11.663671 | M19: 3 | N19: Cochabamba | O19: 57 | P19: 6 | Q19: =O4-O19 -> -32.896283 | R19: =P4-P19 -> 3.8247123 | S19: =O19*U19/1000 -> 175.617 | T19: 2276 | U19: 3081
A20: 10701 | B20: Chuquisaca | C20: Nor Cinti | D20: Camargo | E20: 3 | F20: 287 | G20: =E20/$R$2 -> 0.010452962 | H20: =$S$17*G20 -> 0.22168641 | I20: =F20/$S$2 -> 0.024818402 | J20: =I20*$U$17 -> 23.924939 | K20: =1000*H20/J20 -> 9.2659131 | M20: 4 | N20: Oruro | O20: 51 | P20: 29 | Q20: =O5-O20 -> -30.249404 | R20: =P5-P20 -> -16.618117 | S20: =O20*U20/1000 -> 47.787 | T20: 1565 | U20: 937
A21: 10702 | B21: Chuquisaca | C21: Nor Cinti | D21: San Lucas | E21: 22 | F21: 697 | G21: =E21/$R$2 -> 0.076655052 | H21: =$S$17*G21 -> 1.6257003 | I21: =F21/$S$2 -> 0.060273262 | J21: =I21*$U$17 -> 58.103424 | K21: =1000*H21/J21 -> 27.979424 | M21: 5 | N21: Potosí | O21: 91 | P21: 21 | Q21: =O6-O21 -> -49.573196 | R21: =P6-P21 -> -4.6221577 | S21: =O21*U21/1000 -> 148.694 | T21: 1779 | U21: 1634
A22: 10703 | B22: Chuquisaca | C22: Nor Cinti | D22: Incahuasi | E22: 9 | F22: 340 | G22: =E22/$R$2 -> 0.031358885 | H22: =$S$17*G22 -> 0.66505923 | I22: =F22/$S$2 -> 0.029401591 | J22: =I22*$U$17 -> 28.343134 | K22: =1000*H22/J22 -> 23.464562 | M22: 6 | N22: Tarija | O22: 33 | P22: 21 | Q22: =O7-O22 -> -16.143655 | R22: =P7-P22 -> -14.884903 | S22: =O22*U22/1000 -> 27.423 | T22: 1717 | U22: 831
A23: 10704 | B23: Chuquisaca | C23: Nor Cinti | D23: Villa Charcas | E23: 17 | F23: 409 | G23: =E23/$R$2 -> 0.059233449 | H23: =$S$17*G23 -> 1.256223 | I23: =F23/$S$2 -> 0.035368385 | J23: =I23*$U$17 -> 34.095123 | K23: =1000*H23/J23 -> 36.844654 | M23: 7 | N23: Santa Cruz | O23: 21 | P23: 6 | Q23: =O8-O23 -> -5.511925 | R23: =P8-P23 -> 1.3922008 | S23: =O23*U23/1000 -> 78.057 | T23: 2933 | U23: 3717
A24: 10801 | B24: Chuquisaca | C24: Belisario Boeto | D24: Villa Serrano | E24: 1 | F24: 200 | G24: =E24/$R$2 -> 0.0034843206 | H24: =$S$17*G24 -> 0.07389547 | I24: =F24/$S$2 -> 0.017295054 | J24: =I24*$U$17 -> 16.672432 | K24: =1000*H24/J24 -> 4.4321951 | M24: 8 | N24: Beni | O24: 34 | P24: 13 | Q24: =O9-O24 -> -7.2246799 | R24: =P9-P24 -> -4.1639005 | S24: =O24*U24/1000 -> 48.654 | T24: 545 | U24: 1431
A25: 10901 | B25: Chuquisaca | C25: Sur Cinti | D25: Villa Abecia | E25: 1 | F25: 66 | G25: =E25/$R$2 -> 0.0034843206 | H25: =$S$17*G25 -> 0.07389547 | I25: =F25/$S$2 -> 0.0057073677 | J25: =I25*$U$17 -> 5.5019025 | K25: =1000*H25/J25 -> 13.430894 | M25: 9 | N25: Pando | O25: =43 -> 43 | P25: 10 | Q25: =O10-O25 -> -38.59342 | R25: =P10-P25 -> -2.7072927 | S25: =O25*U25/1000 -> 4.257 | T25: 749 | U25: 99
A26: 10902 | B26: Chuquisaca | C26: Sur Cinti | D26: Culpina | E26: 7 | F26: 410 | G26: =E26/$R$2 -> 0.024390244 | H26: =$S$17*G26 -> 0.51726829 | I26: =F26/$S$2 -> 0.03545486 | J26: =I26*$U$17 -> 34.178485 | K26: =1000*H26/J26 -> 15.134325 | M26: 11 | N26: Bolivia | O26: 50 | P26: 12 | Q26: =O12-O26 -> -25.557156 | R26: =P12-P26 -> -1.885732 | S26: =O26*U26/1000 -> 846.95 | T26: 16939 | U26: 16939
A27: 10903 | B27: Chuquisaca | C27: Sur Cinti | D27: Las Carreras | E27: 1 | F27: 69 | G27: =E27/$R$2 -> 0.0034843206 | H27: =$S$17*G27 -> 0.07389547 | I27: =F27/$S$2 -> 0.0059667935 | J27: =I27*$U$17 -> 5.7519889 | K27: =1000*H27/J27 -> 12.846942 | M27: (*) Con coeficiente de variación superior a 20% emplearlo solo de forma referencial | N27: urbano | O27: 36 | P27: 9 | S27: =O27*U27/1000 -> 402.588 | T27: 10905 | U27: 11183
A28: 11001 | B28: Chuquisaca | C28: Luis Calvo | D28: Villa Vaca Guzman | E28: 4 | F28: 206 | G28: =E28/$R$2 -> 0.013937282 | H28: =$S$17*G28 -> 0.29558188 | I28: =F28/$S$2 -> 0.017813905 | J28: =I28*$U$17 -> 17.172605 | K28: =1000*H28/J28 -> 17.212408 | N28: Rural | O28: 67 | P28: 17 | S28: =O28*U28/1000 -> 385.652 | T28: 6034 | U28: 5756
A29: 11002 | B29: Chuquisaca | C29: Luis Calvo | D29: Huacaya | E29: 1 | F29: 59 | G29: =E29/$R$2 -> 0.0034843206 | H29: =$S$17*G29 -> 0.07389547 | I29: =F29/$S$2 -> 0.0051020408 | J29: =I29*$U$17 -> 4.9183673 | K29: =1000*H29/J29 -> 15.02439
A30: 11003 | B30: Chuquisaca | C30: Luis Calvo | D30: Macharetí | E30: 1 | F30: 143 | G30: =E30/$R$2 -> 0.0034843206 | H30: =$S$17*G30 -> 0.07389547 | I30: =F30/$S$2 -> 0.012365963 | J30: =I30*$U$17 -> 11.920789 | K30: =1000*H30/J30 -> 6.1988743
A31: 20101 | B31: La Paz | C31: Murillo | D31: Nuestra Señora de La Paz | E31: 398 | F31: 12733 | G31: =E31/$R$3 -> 0.23072464 | H31: =$S$18*G31 -> 69.819813 | I31: =F31/$S$3 -> 0.23466642 | J31: =I31*$U$18 -> 1203.6041 | K31: =1000*H31/J31 -> 58.008954
A32: 20102 | B32: La Paz | C32: Murillo | D32: Palca | E32: 23 | F32: 376 | G32: =E32/$R$3 -> 0.013333333 | H32: =$S$18*G32 -> 4.0348133 | I32: =F32/$S$3 -> 0.0069295982 | J32: =I32*$U$18 -> 35.541909 | K32: =1000*H32/J32 -> 113.52269
A33: 20103 | B33: La Paz | C33: Murillo | D33: Mecapaca | E33: 11 | F33: 293 | G33: =E33/$R$3 -> 0.0063768116 | H33: =$S$18*G33 -> 1.9296933 | I33: =F33/$S$3 -> 0.0053999263 | J33: =I33*$U$18 -> 27.696222 | K33: =1000*H33/J33 -> 69.673522
A34: 20104 | B34: La Paz | C34: Murillo | D34: Achocalla | E34: 25 | F34: 467 | G34: =E34/$R$3 -> 0.014492754 | H34: =$S$18*G34 -> 4.3856667 | I34: =F34/$S$3 -> 0.0086067084 | J34: =I34*$U$18 -> 44.143808 | K34: =1000*H34/J34 -> 99.349533
A35: 20105 | B35: La Paz | C35: Murillo | D35: El Alto | E35: 575 | F35: 19194 | G35: =E35/$R$3 -> 0.33333333 | H35: =$S$18*G35 -> 100.87033 | I35: =F35/$S$3 -> 0.35374125 | J35: =I35*$U$18 -> 1814.3389 | K35: =1000*H35/J35 -> 55.596193
A36: 20201 | B36: La Paz | C36: Omasuyos | D36: Achacachi | E36: 3 | F36: 792 | G36: =E36/$R$3 -> 0.0017391304 | H36: =$S$18*G36 -> 0.52628 | I36: =F36/$S$3 -> 0.014596388 | J36: =I36*$U$18 -> 74.864873 | K36: =1000*H36/J36 -> 7.0297321
A37: 20202 | B37: La Paz | C37: Omasuyos | D37: Ancoraimes | E37: 7 | F37: 218 | G37: =E37/$R$3 -> 0.004057971 | H37: =$S$18*G37 -> 1.2279867 | I37: =F37/$S$3 -> 0.0040176926 | J37: =I37*$U$18 -> 20.606745 | K37: =1000*H37/J37 -> 59.59149
A38: 20203 | B38: La Paz | C38: Omasuyos | D38: Chua Cocani | E38: 3 | F38: 99 | G38: =E38/$R$3 -> 0.0017391304 | H38: =$S$18*G38 -> 0.52628 | I38: =F38/$S$3 -> 0.0018245485 | J38: =I38*$U$18 -> 9.3581091 | K38: =1000*H38/J38 -> 56.237857
A39: 20204 | B39: La Paz | C39: Omasuyos | D39: Huarina | E39: 4 | F39: 110 | G39: =E39/$R$3 -> 0.0023188406 | H39: =$S$18*G39 -> 0.70170667 | I39: =F39/$S$3 -> 0.0020272761 | J39: =I39*$U$18 -> 10.397899 | K39: =1000*H39/J39 -> 67.485428
A40: 20205 | B40: La Paz | C40: Omasuyos | D40: Santiago de Huata | E40: 0 | F40: 58 | G40: =E40/$R$3 -> 0 | H40: =$S$18*G40 -> 0 | I40: =F40/$S$3 -> 0.0010689274 | J40: =I40*$U$18 -> 5.4825286 | K40: =1000*H40/J40 -> 0
...

Sheet Datos procesados_EDSA_y_Cen2024
A1: id | B1: DEPARTAMENTO | C1: PROVINCIA | D1: MUNICIPIO | E1: Número de niños fallecidos antes de cumplir 1 año (2019-2023) (CENSO) | F1: CENSO NACIDOS VIVOS (CENSO)(2019-2023) | G1: Porcentaje de fallecidos por municipio | H1: Estimados fallecidos por municipio con EDSA | I1: Porcentaje de nacidos por municipio | J1: Estimados nacidos por municipio con EDSA | K1: Tasa de mortalidad acorde a EDSA distribuido por censo 2024 | M1: id_departamento | N1: Departamento | O1: Tasa de mortalidad infantil (< 1 año) (por 1,000 nacidos vivos) 2012 | P1: Tasa de mortalidad infantil (< 1 año) (por 1,000 nacidos vivos) 2024 | Q1: Departamento | R1: Número de niños fallecidos antes de cumplir 1 año 2012 CENSO | S1: NACIDOS VIVOS (2019-2023) | T1: MORTALIDAD INFANTIL (1q0) 2023 *
A2: 10101 | B2: Chuquisaca | C2: Oropeza | D2: Sucre | E2: 122 | F2: 17089 | G2: =E2/$R$2 -> 0.36969697 | H2: =$S$17*G2 -> 1.094303 | I2: =F2/$S$2 -> 0.47726638 | J2: =I2*$U$17 -> 176.58856 | K2: =1000*H2/J2 -> 6.1969078 | M2: 1 | N2: Chuquisaca | O2: 24.818402 | P2: 8.8076422 | Q2: Chuquisaca | R2: 330 | S2: 35806 | T2: 8
A3: 10102 | B3: Chuquisaca | C3: Oropeza | D3: Yotala | E3: 9 | F3: 519 | G3: =E3/$R$2 -> 0.027272727 | H3: =$S$17*G3 -> 0.080727273 | I3: =F3/$S$2 -> 0.014494777 | J3: =I3*$U$17 -> 5.3630676 | K3: =1000*H3/J3 -> 15.052444 | M3: 2 | N3: La Paz | O3: 31.791375 | P3: 12.522002 | Q3: La Paz | R3: 2288 | S3: 175213 | T3: 17
A4: 10103 | B4: Chuquisaca | C4: Oropeza | D4: Poroma | E4: 16 | F4: 867 | G4: =E4/$R$2 -> 0.048484848 | H4: =$S$17*G4 -> 0.14351515 | I4: =F4/$S$2 -> 0.024213819 | J4: =I4*$U$17 -> 8.959113 | K4: =1000*H4/J4 -> 16.018902 | M4: 3 | N4: Cochabamba | O4: 24.103717 | P4: 9.8247123 | Q4: Cochabamba | R4: 1317 | S4: 128674 | T4: 11
A5: 10201 | B5: Chuquisaca | C5: Azurduy | D5: Villa Azurduy | E5: 8 | F5: 523 | G5: =E5/$R$2 -> 0.024242424 | H5: =$S$17*G5 -> 0.071757576 | I5: =F5/$S$2 -> 0.014606491 | J5: =I5*$U$17 -> 5.4044015 | K5: =1000*H5/J5 -> 13.277617 | M5: 4 | N5: Oruro | O5: 20.750596 | P5: 12.381883 | Q5: Oruro | R5: 455 | S5: 35024 | T5: 31
A6: 10202 | B6: Chuquisaca | C6: Azurduy | D6: Tarvita | E6: 11 | F6: 1039 | G6: =E6/$R$2 -> 0.033333333 | H6: =$S$17*G6 -> 0.098666667 | I6: =F6/$S$2 -> 0.029017483 | J6: =I6*$U$17 -> 10.736469 | K6: =1000*H6/J6 -> 9.189862 | M6: 5 | N6: Potosí | O6: 41.426804 | P6: 16.377842 | Q6: Potosi | R6: 979 | S6: 57031 | T6: 42
A7: 10301 | B7: Chuquisaca | C7: Zudáñez | D7: Zudañez | E7: 3 | F7: 804 | G7: =E7/$R$2 -> 0.0090909091 | H7: =$S$17*G7 -> 0.026909091 | I7: =F7/$S$2 -> 0.022454337 | J7: =I7*$U$17 -> 8.3081048 | K7: =1000*H7/J7 -> 3.2388964 | M7: 6 | N7: Tarija | O7: 16.856345 | P7: 6.115097 | Q7: Tarija | R7: 201 | S7: 31547 | T7: 25
A8: 10302 | B8: Chuquisaca | C8: Zudáñez | D8: Presto | E8: 8 | F8: 779 | G8: =E8/$R$2 -> 0.024242424 | H8: =$S$17*G8 -> 0.071757576 | I8: =F8/$S$2 -> 0.02175613 | J8: =I8*$U$17 -> 8.0497682 | K8: =1000*H8/J8 -> 8.9142413 | M8: 7 | N8: Santa Cruz | O8: 15.488075 | P8: 7.3922008 | Q8: Santa Cruz | R8: 1631 | S8: 210592 | T8: 8
A9: 10303 | B9: Chuquisaca | C9: Zudáñez | D9: Villa Mojocoya | E9: 5 | F9: 547 | G9: =E9/$R$2 -> 0.015151515 | H9: =$S$17*G9 -> 0.044848485 | I9: =F9/$S$2 -> 0.015276769 | J9: =I9*$U$17 -> 5.6524046 | K9: =1000*H9/J9 -> 7.9344081 | M9: 8 | N9: Beni | O9: 26.77532 | P9: 8.8360995 | Q9: Beni | R9: 336 | S9: 36199 | T9: 24
A10: 10304 | B10: Chuquisaca | C10: Zudáñez | D10: Icla | E10: 5 | F10: 519 | G10: =E10/$R$2 -> 0.015151515 | H10: =$S$17*G10 -> 0.044848485 | I10: =F10/$S$2 -> 0.014494777 | J10: =I10*$U$17 -> 5.3630676 | K10: =1000*H10/J10 -> 8.3624686 | M10: 9 | N10: Pando | O10: 4.4065805 | P10: 7.2927073 | Q10: Pando | R10: 71 | S10: 9512 | T10: 10
A11: 10401 | B11: Chuquisaca | C11: Tomina | D11: Padilla | E11: 3 | F11: 584 | G11: =E11/$R$2 -> 0.0090909091 | H11: =$S$17*G11 -> 0.026909091 | I11: =F11/$S$2 -> 0.016310116 | J11: =I11*$U$17 -> 6.0347428 | K11: =1000*H11/J11 -> 4.4590286 | M11: 10 | N11: Gran Chaco | O11: 22.727273 | P11: 8.2292574 | Q11: Gran Chaco | R11: =SUM(E246:E248) -> 85 | S11: =SUM(F246:F248) -> 10329 | T11: =SUM(H246:H248)/SUM(J246:J248)*1000 -> 27.123264
A12: 10402 | B12: Chuquisaca | C12: Tomina | D12: Tomina | E12: 3 | F12: 545 | G12: =E12/$R$2 -> 0.0090909091 | H12: =$S$17*G12 -> 0.026909091 | I12: =F12/$S$2 -> 0.015220913 | J12: =I12*$U$17 -> 5.6317377 | K12: =1000*H12/J12 -> 4.7781151 | M12: 11 | N12: Bolivia | O12: 24.442844 | P12: 10.114268 | Q12: Bolivia | R12: 7608 | S12: 719598 | T12: 16
A13: 10403 | B13: Chuquisaca | C13: Tomina | D13: Sopachuy | E13: 1 | F13: 428 | G13: =E13/$R$2 -> 0.003030303 | H13: =$S$17*G13 -> 0.008969697 | I13: =F13/$S$2 -> 0.011953304 | J13: =I13*$U$17 -> 4.4227224 | K13: =1000*H13/J13 -> 2.028094
A14: 10404 | B14: Chuquisaca | C14: Tomina | D14: Villa Alcalá | E14: 1 | F14: 204 | G14: =E14/$R$2 -> 0.003030303 | H14: =$S$17*G14 -> 0.008969697 | I14: =F14/$S$2 -> 0.0056973692 | J14: =I14*$U$17 -> 2.1080266 | K14: =1000*H14/J14 -> 4.2550208
A15: 10405 | B15: Chuquisaca | C15: Tomina | D15: El Villar | E15: 4 | F15: 338 | G15: =E15/$R$2 -> 0.012121212 | H15: =$S$17*G15 -> 0.035878788 | I15: =F15/$S$2 -> 0.0094397587 | J15: =I15*$U$17 -> 3.4927107 | K15: =1000*H15/J15 -> 10.272476
A16: 10501 | B16: Chuquisaca | C16: Hernando Siles | D16: Monteagudo | E16: 9 | F16: 1404 | G16: =E16/$R$2 -> 0.027272727 | H16: =$S$17*G16 -> 0.080727273 | I16: =F16/$S$2 -> 0.039211305 | J16: =I16*$U$17 -> 14.508183 | K16: =1000*H16/J16 -> 5.564258 | M16: ID | N16: Departamento | O16: MORTALIDAD INFANTIL (1q0) 2008 | P16: MORTALIDAD INFANTIL (1q0) 2023 * | Q16: Diferencia 2008 | R16: Diferencia 2023 | S16: Defunciones aproximadas con EDSA 2023 | T16: Nacidos vivos EDSA 2023 Número de caso sin ponderar | U16: Nacidos vivos EDSA 2023 Número de casos ponderador
A17: 10502 | B17: Chuquisaca | C17: Hernando Siles | D17: San Pablo de Huacareta | E17: 4 | F17: 469 | G17: =E17/$R$2 -> 0.012121212 | H17: =$S$17*G17 -> 0.035878788 | I17: =F17/$S$2 -> 0.013098363 | J17: =I17*$U$17 -> 4.8463945 | K17: =1000*H17/J17 -> 7.4031918 | M17: 1 | N17: Chuquisaca | O17: 22 | P17: 8 | Q17: =O2-O17 -> 2.8184019 | R17: =P2-P17 -> 0.80764216 | S17: =P17*U17/1000 -> 2.96 | T17: 571 | U17: 370
A18: 10601 | B18: Chuquisaca | C18: Yamparáez | D18: Tarabuco | E18: 13 | F18: 713 | G18: =E18/$R$2 -> 0.039393939 | H18: =$S$17*G18 -> 0.11660606 | I18: =F18/$S$2 -> 0.019912864 | J18: =I18*$U$17 -> 7.3677596 | K18: =1000*H18/J18 -> 15.826529 | M18: 2 | N18: La Paz | O18: 59 | P18: 15 | Q18: =O3-O18 -> -27.208625 | R18: =P3-P18 -> -2.4779982 | S18: =P18*U18/1000 -> 26.07 | T18: 1226 | U18: 1738
A19: 10602 | B19: Chuquisaca | C19: Yamparáez | D19: Yamparáez | E19: 3 | F19: 460 | G19: =E19/$R$2 -> 0.0090909091 | H19: =$S$17*G19 -> 0.026909091 | I19: =F19/$S$2 -> 0.012847009 | J19: =I19*$U$17 -> 4.7533933 | K19: =1000*H19/J19 -> 5.6610277 | M19: 3 | N19: Cochabamba | O19: 57 | P19: 6 | Q19: =O4-O19 -> -32.896283 | R19: =P4-P19 -> 3.8247123 | S19: =P19*U19/1000 -> 7.542 | T19: 974 | U19: 1257
A20: 10701 | B20: Chuquisaca | C20: Nor Cinti | D20: Camargo | E20: 11 | F20: 820 | G20: =E20/$R$2 -> 0.033333333 | H20: =$S$17*G20 -> 0.098666667 | I20: =F20/$S$2 -> 0.02290119 | J20: =I20*$U$17 -> 8.4734402 | K20: =1000*H20/J20 -> 11.644228 | M20: 4 | N20: Oruro | O20: 51 | P20: 29 | Q20: =O5-O20 -> -30.249404 | R20: =P5-P20 -> -16.618117 | S20: =P20*U20/1000 -> 8.439 | T20: 628 | U20: 291
A21: 10702 | B21: Chuquisaca | C21: Nor Cinti | D21: San Lucas | E21: 29 | F21: 1817 | G21: =E21/$R$2 -> 0.087878788 | H21: =$S$17*G21 -> 0.26012121 | I21: =F21/$S$2 -> 0.050745685 | J21: =I21*$U$17 -> 18.775903 | K21: =1000*H21/J21 -> 13.853992 | M21: 5 | N21: Potosí | O21: 91 | P21: 21 | Q21: =O6-O21 -> -49.573196 | R21: =P6-P21 -> -4.6221577 | S21: =P21*U21/1000 -> 10.689 | T21: 727 | U21: 509
A22: 10703 | B22: Chuquisaca | C22: Nor Cinti | D22: Incahuasi | E22: 16 | F22: 1042 | G22: =E22/$R$2 -> 0.048484848 | H22: =$S$17*G22 -> 0.14351515 | I22: =F22/$S$2 -> 0.029101268 | J22: =I22*$U$17 -> 10.767469 | K22: =1000*H22/J22 -> 13.328587 | M22: 6 | N22: Tarija | O22: 33 | P22: 21 | Q22: =O7-O22 -> -16.143655 | R22: =P7-P22 -> -14.884903 | S22: =P22*U22/1000 -> 7.455 | T22: 527 | U22: 355
A23: 10704 | B23: Chuquisaca | C23: Nor Cinti | D23: Villa Charcas | E23: 9 | F23: 1012 | G23: =E23/$R$2 -> 0.027272727 | H23: =$S$17*G23 -> 0.080727273 | I23: =F23/$S$2 -> 0.02826342 | J23: =I23*$U$17 -> 10.457465 | K23: =1000*H23/J23 -> 7.7195832 | M23: 7 | N23: Santa Cruz | O23: 21 | P23: 6 | Q23: =O8-O23 -> -5.511925 | R23: =P8-P23 -> 1.3922008 | S23: =P23*U23/1000 -> 12.522 | T23: 1112 | U23: 2087
A24: 10801 | B24: Chuquisaca | C24: Belisario Boeto | D24: Villa Serrano | E24: 5 | F24: 509 | G24: =E24/$R$2 -> 0.015151515 | H24: =$S$17*G24 -> 0.044848485 | I24: =F24/$S$2 -> 0.014215495 | J24: =I24*$U$17 -> 5.259733 | K24: =1000*H24/J24 -> 8.5267607 | M24: 8 | N24: Beni | O24: 34 | P24: 13 | Q24: =O9-O24 -> -7.2246799 | R24: =P9-P24 -> -4.1639005 | S24: =P24*U24/1000 -> 4.303 | T24: 639 | U24: 331
A25: 10901 | B25: Chuquisaca | C25: Sur Cinti | D25: Villa Abecia | E25: 1 | F25: 303 | G25: =E25/$R$2 -> 0.003030303 | H25: =$S$17*G25 -> 0.008969697 | I25: =F25/$S$2 -> 0.0084622689 | J25: =I25*$U$17 -> 3.1310395 | K25: =1000*H25/J25 -> 2.8647665 | M25: 9 | N25: Pando | O25: =43 -> 43 | P25: 10 | Q25: =O10-O25 -> -38.59342 | R25: =P10-P25 -> -2.7072927 | S25: =P25*U25/1000 -> 1.06 | T25: 657 | U25: 106
A26: 10902 | B26: Chuquisaca | C26: Sur Cinti | D26: Culpina | E26: 15 | F26: 999 | G26: =E26/$R$2 -> 0.045454545 | H26: =$S$17*G26 -> 0.13454545 | I26: =F26/$S$2 -> 0.027900352 | J26: =I26*$U$17 -> 10.32313 | K26: =1000*H26/J26 -> 13.033397 | M26: 11 | N26: Bolivia | O26: 50 | P26: 12 | Q26: =O12-O26 -> -25.557156 | R26: =P12-P26 -> -1.885732 | S26: =P26*U26/1000 -> 84.516 | T26: 7061 | U26: 7043
A27: 10903 | B27: Chuquisaca | C27: Sur Cinti | D27: Las Carreras | E27: 1 | F27: 240 | G27: =E27/$R$2 -> 0.003030303 | H27: =$S$17*G27 -> 0.008969697 | I27: =F27/$S$2 -> 0.0067027872 | J27: =I27*$U$17 -> 2.4800313 | K27: =1000*H27/J27 -> 3.6167677 | M27: (*) Con coeficiente de variación superior a 20% emplearlo solo de forma referencial | N27: urbano | O27: 36 | P27: 9 | S27: =P27*U27/1000 -> 44.145 | T27: 4821 | U27: 4905
A28: 11001 | B28: Chuquisaca | C28: Luis Calvo | D28: Villa Vaca Guzman | E28: 4 | F28: 635 | G28: =E28/$R$2 -> 0.012121212 | H28: =$S$17*G28 -> 0.035878788 | I28: =F28/$S$2 -> 0.017734458 | J28: =I28*$U$17 -> 6.5617494 | K28: =1000*H28/J28 -> 5.4678692 | N28: Rural | O28: 67 | P28: 17 | S28: =P28*U28/1000 -> 36.329 | T28: 2240 | U28: 2137
A29: 11002 | B29: Chuquisaca | C29: Luis Calvo | D29: Huacaya | E29: 3 | F29: 167 | G29: =E29/$R$2 -> 0.0090909091 | H29: =$S$17*G29 -> 0.026909091 | I29: =F29/$S$2 -> 0.0046640228 | J29: =I29*$U$17 -> 1.7256884 | K29: =1000*H29/J29 -> 15.59325
A30: 11003 | B30: Chuquisaca | C30: Luis Calvo | D30: Macharetí | E30: 8 | F30: 431 | G30: =E30/$R$2 -> 0.024242424 | H30: =$S$17*G30 -> 0.071757576 | I30: =F30/$S$2 -> 0.012037089 | J30: =I30*$U$17 -> 4.4537228 | K30: =1000*H30/J30 -> 16.111819
A31: 20101 | B31: La Paz | C31: Murillo | D31: Nuestra Señora de La Paz | E31: 352 | F31: 34528 | G31: =E31/$R$3 -> 0.15384615 | H31: =$S$18*G31 -> 4.0107692 | I31: =F31/$S$3 -> 0.197063 | J31: =I31*$U$18 -> 342.4955 | K31: =1000*H31/J31 -> 11.710429
A32: 20102 | B32: La Paz | C32: Murillo | D32: Palca | E32: 26 | F32: 1505 | G32: =E32/$R$3 -> 0.011363636 | H32: =$S$18*G32 -> 0.29625 | I32: =F32/$S$3 -> 0.0085895453 | J32: =I32*$U$18 -> 14.92863 | K32: =1000*H32/J32 -> 19.84442
A33: 20103 | B33: La Paz | C33: Murillo | D33: Mecapaca | E33: 14 | F33: 1157 | G33: =E33/$R$3 -> 0.0061188811 | H33: =$S$18*G33 -> 0.15951923 | I33: =F33/$S$3 -> 0.0066033913 | J33: =I33*$U$18 -> 11.476694 | K33: =1000*H33/J33 -> 13.899406
A34: 20104 | B34: La Paz | C34: Murillo | D34: Achocalla | E34: 38 | F34: 2909 | G34: =E34/$R$3 -> 0.016608392 | H34: =$S$18*G34 -> 0.43298077 | I34: =F34/$S$3 -> 0.016602649 | J34: =I34*$U$18 -> 28.855405 | K34: =1000*H34/J34 -> 15.005188
A35: 20105 | B35: La Paz | C35: Murillo | D35: El Alto | E35: 751 | F35: 56954 | G35: =E35/$R$3 -> 0.32823427 | H35: =$S$18*G35 -> 8.5570673 | I35: =F35/$S$3 -> 0.32505579 | J35: =I35*$U$18 -> 564.94696 | K35: =1000*H35/J35 -> 15.146674
A36: 20201 | B36: La Paz | C36: Omasuyos | D36: Achacachi | E36: 41 | F36: 2499 | G36: =E36/$R$3 -> 0.01791958 | H36: =$S$18*G36 -> 0.46716346 | I36: =F36/$S$3 -> 0.01426264 | J36: =I36*$U$18 -> 24.788469 | K36: =1000*H36/J36 -> 18.845999
A37: 20202 | B37: La Paz | C37: Omasuyos | D37: Ancoraimes | E37: 11 | F37: 821 | G37: =E37/$R$3 -> 0.0048076923 | H37: =$S$18*G37 -> 0.12533654 | I37: =F37/$S$3 -> 0.0046857254 | J37: =I37*$U$18 -> 8.1437907 | K37: =1000*H37/J37 -> 15.390442
A38: 20203 | B38: La Paz | C38: Omasuyos | D38: Chua Cocani | E38: 6 | F38: 333 | G38: =E38/$R$3 -> 0.0026223776 | H38: =$S$18*G38 -> 0.068365385 | I38: =F38/$S$3 -> 0.0019005439 | J38: =I38*$U$18 -> 3.3031453 | K38: =1000*H38/J38 -> 20.697056
A39: 20204 | B39: La Paz | C39: Omasuyos | D39: Huarina | E39: 6 | F39: 418 | G39: =E39/$R$3 -> 0.0026223776 | H39: =$S$18*G39 -> 0.068365385 | I39: =F39/$S$3 -> 0.0023856677 | J39: =I39*$U$18 -> 4.1462905 | K39: =1000*H39/J39 -> 16.488325
A40: 20205 | B40: La Paz | C40: Omasuyos | D40: Santiago de Huata | E40: 3 | F40: 414 | G40: =E40/$R$3 -> 0.0013111888 | H40: =$S$18*G40 -> 0.034182692 | I40: =F40/$S$3 -> 0.0023628384 | J40: =I40*$U$18 -> 4.1066131 | K40: =1000*H40/J40 -> 8.3238161
...

Sheet Indicador_MUN
A1: id | B1: MUNICIPIO | C1: Tasa de mortalidad acorde a EDSA distribuido por censo 2012 | D1: Tasa de mortalidad acorde a EDSA distribuido por censo 2024
A2: 10101 | B2: Sucre | C2: 18.616089 | D2: 6.1969078
A3: 10102 | B3: Yotala | C3: 20.980805 | D3: 15.052444
A4: 10103 | B4: Poroma | C4: 29.397213 | D4: 16.018902
A5: 10201 | B5: Villa Azurduy | C5: 23.225477 | D5: 13.277617
A6: 10202 | B6: Tarvita | C6: 19.131778 | D6: 9.189862
A7: 10301 | B7: Zudañez | C7: 32.08829 | D7: 3.2388964
A8: 10302 | B8: Presto | C8: 51.574634 | D8: 8.9142413
A9: 10303 | B9: Villa Mojocoya | C9: 47.00813 | D9: 7.9344081
A10: 10304 | B10: Icla | C10: 12.754518 | D10: 8.3624686
A11: 10401 | B11: Padilla | C11: 33.360608 | D11: 4.4590286
A12: 10402 | B12: Tomina | C12: 26.861789 | D12: 4.7781151
A13: 10403 | B13: Sopachuy | C13: 13.743241 | D13: 2.028094
... A344: 90503 | B344: Santos Mercado | C344: 0 | D344: 29.937839

Sheet INFANTIL Absoluto_MUN
A1: id | B1: MUNICIPIO | C1: INFANTIL Número de niños fallecidos antes de cumplir 1 año 2012 | D1: INFANTIL Número de niños fallecidos antes de cumplir 1 año 2024
A2: 10101 | B2: Sucre | C2: 106 | D2: 132
A3: 10102 | B3: Yotala | C3: 4 | D3: 9
A4: 10103 | B4: Poroma | C4: 14 | D4: 17
A5: 10201 | B5: Villa Azurduy | C5: 6 | D5: 9
A6: 10202 | B6: Tarvita | C6: 6 | D6: 12
A7: 10301 | B7: Zudañez | C7: 8 | D7: 3
A8: 10302 | B8: Presto | C8: 16 | D8: 8
A9: 10303 | B9: Villa Mojocoya | C9: 7 | D9: 5
A10: 10304 | B10: Icla | C10: 2 | D10: 5
A11: 10401 | B11: Padilla | C11: 7 | D11: 3
A12: 10402 | B12: Tomina | C12: 6 | D12: 3
A13: 10403 | B13: Sopachuy | C13: 2 | D13: 3
... A344: 90503 | B344: Santos Mercado | C344: 0 | D344: 4
C345: 0

Sheet NIÑEZ Absoluto_MUN 
A1: id | B1: MUNICIPIO | C1: NIÑEZ Número de niños fallecidos antes de cumplir 5 años 2012 | D1: NIÑEZ Número de niños fallecidos antes de cumplir 5 años 2024
A2: 10101 | B2: Sucre | C2: 222 | D2: 233
A3: 10102 | B3: Yotala | C3: 10 | D3: 7
A4: 10103 | B4: Poroma | C4: 36 | D4: 16
A5: 10201 | B5: Villa Azurduy | C5: 12 | D5: 3
A6: 10202 | B6: Tarvita | C6: 24 | D6: 16
A7: 10301 | B7: Zudañez | C7: 13 | D7: 4
A8: 10302 | B8: Presto | C8: 34 | D8: 10
A9: 10303 | B9: Villa Mojocoya | C9: 13 | D9: 3
A10: 10304 | B10: Icla | C10: 4 | D10: 3
A11: 10401 | B11: Padilla | C11: 8 | D11: 11
A12: 10402 | B12: Tomina | C12: 10 | D12: 13
A13: 10403 | B13: Sopachuy | C13: 2 | D13: 5
... A344: 90503 | B344: Santos Mercado | C344: 6 | D344: 14
C345: 0

Sheet Absoluto_MUN
A1: id | B1: MUNICIPIO | C1: Número de niños fallecidos antes de cumplir 1 año 2012 | D1: Número de niños fallecidos antes de cumplir 1 año 2024
A2: 10101 | B2: Sucre
A3: 10102 | B3: Yotala
A4: 10103 | B4: Poroma
A5: 10201 | B5: Villa Azurduy
A6: 10202 | B6: Tarvita
A7: 10301 | B7: Zudañez
A8: 10302 | B8: Presto
A9: 10303 | B9: Villa Mojocoya
A10: 10304 | B10: Icla
A11: 10401 | B11: Padilla
A12: 10402 | B12: Tomina
A13: 10403 | B13: Sopachuy
... A344: 90503 | B344: Santos Mercado

Sheet Indicador_DEP 
A1: id_departamento | B1: Departamento | C1: Tasa de mortalidad INFANTIL (< 1 año) (por 1,000 nacidos vivos) EDSA 2008 | D1: Tasa de mortalidad INFANTIL (< 1 año) (por 1,000 nacidos vivos) EDSA 2023
A2: 1 | B2: Chuquisaca | C2: 22 | D2: 8
A3: 2 | B3: La Paz | C3: 59 | D3: 17
A4: 3 | B4: Cochabamba | C4: 57 | D4: 11
A5: 4 | B5: Oruro | C5: 51 | D5: 31
A6: 5 | B6: Potosí | C6: 91 | D6: 42
A7: 6 | B7: Tarija | C7: 33 | D7: 25
A8: 7 | B8: Santa Cruz | C8: 21 | D8: 8
A9: 8 | B9: Beni | C9: 34 | D9: 24
A10: 9 | B10: Pando | C10: 43 | D10: 10
A11: 10 | B11: Gran Chaco | C11: 44.493631 | D11: 27.123264
A12: 11 | B12: Bolivia | C12: 50 | D12: 16

Sheet Absoluto_DEP
A1: id_departamento | B1: Departamento | C1: Número de niños fallecidos antes de cumplir 1 año 2012 | D1: Número de niños fallecidos antes de cumplir 1 año 2024
A2: 1 | B2: Chuquisaca
A3: 2 | B3: La Paz
A4: 3 | B4: Cochabamba
A5: 4 | B5: Oruro
A6: 5 | B6: Potosí
A7: 6 | B7: Tarija
A8: 7 | B8: Santa Cruz
A9: 8 | B9: Beni
A10: 9 | B10: Pando
A11: 10 | B11: Gran Chaco
A12: 11 | B12: Bolivia

Sheet Umbral
A1: ODS | B1: Indicador | C1: Meta Alcanzada max | D1: Meta Alcanzada min | E1: Próximo a Alcanzarse max | F1: Próximo a Alcanzarse min | G1: Quedan Retos Importantes max | H1: Quedan Retos Importantes min | I1: Quedan Retos Grandes max | J1: Quedan Retos Grandes min | K1: Criterio Umbral Verde
A2: 3 | B2: Tasa de mortalidad infantil (< 1 año) (por 1,000 nacidos vivos) | C2: 0 | D2: 12 | E2: 12 | F2: 16 | G2: 16 | H2: 20 | I2: 20 | J2: 400 | K2: Atlas Municipal de los ODS 2020

Sheet Mapa
