Workbook

Sheet Datos originales
B1: Cuadro N° 10. INDICADOR COMPLEMENTARIO ODS 7.1.2
B2: BOLIVIA: POBLACIÓN EN VIVIENDAS PARTICULARES Y PORCENTAJE DE POBLACIÓN QUE UTILIZA COMBUSTIBLE LIMPIO PARA COCINAR(1) POR CATEGORIAS SELECCIONADAS, SEGÚN DEPARTAMENTO, PROVINCIA, MUNICIPIO O TERRITORIO INDÍGENA ORIGINARIO CAMPESINO (TIOC) Y ÁREA, CENSOS 2012 Y 2024
B3: (En número y porcentaje)
H5: 2012 | J5: 2024
B6: N° | C6: NIVEL | D6: DEPARTAMENTO | E6: PROVINCIA | F6: MUNICIPIO/TIOC | G6: ÁREA | H6: POBLACIÓN EN VIVIENDAS PARTICULARES | I6: PORCENTAJE DE POBLACIÓN QUE UTILIZA COMBUSTIBLE LIMPIO PARA COCINAR | J6: POBLACIÓN EN VIVIENDAS PARTICULARES | K6: PORCENTAJE DE POBLACIÓN QUE UTILIZA COMBUSTIBLE LIMPIO PARA COCINAR
B8: 1 | C8: País | G8: Bolivia | H8: 9750629 | I8: 75.470526 | J8: 11049568 | K8: 83.758243
B9: 2 | C9: País | G9: Urbana | H9: 6569842 | I9: 96.599203 | J9: 7612780 | K9: 98.427276
B10: 3 | C10: País | G10: Rural | H10: 3180787 | I10: 31.829733 | J10: 3436788 | K10: 51.265077
B11: 4 | C11: Departamento | D11: Chuquisaca | G11: Chuquisaca | H11: 562160 | I11: 56.840401 | J11: 589329 | K11: 68.431216
B12: 5 | C12: Departamento | D12: Chuquisaca | G12: Urbana | H12: 271230 | I12: 97.481105 | J12: 324620 | K12: 98.418458
B13: 6 | C13: Departamento | D13: Chuquisaca | G13: Rural | H13: 290930 | I13: 18.951638 | J13: 264709 | K13: 31.657027
B14: 7 | C14: Provincia | D14: Chuquisaca | E14: Oropeza | G14: Oropeza | H14: 277803 | I14: 85.757173 | J14: 310516 | K14: 90.40758
B15: 8 | C15: Provincia | D15: Chuquisaca | E15: Oropeza | G15: Urbana | H15: 230384 | I15: 98.750347 | J15: 267643 | K15: 99.093569
B16: 9 | C16: Provincia | D16: Chuquisaca | E16: Oropeza | G16: Rural | H16: 47419 | I16: 22.630169 | J16: 42873 | K16: 36.183612
B17: 10 | C17: Municipio/TIOC | D17: Chuquisaca | E17: Oropeza | F17: Sucre | G17: Sucre | H17: 252503 | I17: 92.192568 | J17: 288058 | K17: 94.741684
B18: 11 | C18: Municipio/TIOC | D18: Chuquisaca | E18: Oropeza | F18: Sucre | G18: Urbana | H18: 230384 | I18: 98.750347 | J18: 267643 | K18: 99.093569
B19: 12 | C19: Municipio/TIOC | D19: Chuquisaca | E19: Oropeza | F19: Sucre | G19: Rural | H19: 22119 | I19: 23.888964 | J19: 20415 | K19: 37.687975
B20: 13 | C20: Municipio/TIOC | D20: Chuquisaca | E20: Oropeza | F20: Yotala | G20: Yotala | H20: 9025 | I20: 53.31856 | J20: 8903 | K20: 74.31203
B21: 14 | C21: Municipio/TIOC | D21: Chuquisaca | E21: Oropeza | F21: Yotala | G21: Urbana
B22: 15 | C22: Municipio/TIOC | D22: Chuquisaca | E22: Oropeza | F22: Yotala | G22: Rural | H22: 9025 | I22: 53.31856 | J22: 8903 | K22: 74.31203
B23: 16 | C23: Municipio/TIOC | D23: Chuquisaca | E23: Oropeza | F23: Poroma | G23: Poroma | H23: 16275 | I23: 3.9016897 | J23: 13555 | K23: 8.8749539
B24: 17 | C24: Municipio/TIOC | D24: Chuquisaca | E24: Oropeza | F24: Poroma | G24: Urbana
B25: 18 | C25: Municipio/TIOC | D25: Chuquisaca | E25: Oropeza | F25: Poroma | G25: Rural | H25: 16275 | I25: 3.9016897 | J25: 13555 | K25: 8.8749539
B26: 19 | C26: Provincia | D26: Chuquisaca | E26: Azurduy | G26: Azurduy | H26: 24398 | I26: 11.668989 | J26: 24479 | K26: 27.962744
B27: 20 | C27: Provincia | D27: Chuquisaca | E27: Azurduy | G27: Urbana
B28: 21 | C28: Provincia | D28: Chuquisaca | E28: Azurduy | G28: Rural | H28: 24398 | I28: 11.668989 | J28: 24479 | K28: 27.962744
B29: 22 | C29: Municipio/TIOC | D29: Chuquisaca | E29: Azurduy | F29: Azurduy | G29: Azurduy | H29: 10335 | I29: 10.333817 | J29: 7808 | K29: 19.851434
B30: 23 | C30: Municipio/TIOC | D30: Chuquisaca | E30: Azurduy | F30: Azurduy | G30: Urbana
B31: 24 | C31: Municipio/TIOC | D31: Chuquisaca | E31: Azurduy | F31: Azurduy | G31: Rural | H31: 10335 | I31: 10.333817 | J31: 7808 | K31: 19.851434
B32: 25 | C32: Municipio/TIOC | D32: Chuquisaca | E32: Azurduy | F32: Tarvita | G32: Tarvita | H32: 14063 | I32: 12.650217 | J32: 16671 | K32: 31.761742
B33: 26 | C33: Municipio/TIOC | D33: Chuquisaca | E33: Azurduy | F33: Tarvita | G33: Urbana
B34: 27 | C34: Municipio/TIOC | D34: Chuquisaca | E34: Azurduy | F34: Tarvita | G34: Rural | H34: 14063 | I34: 12.650217 | J34: 16671 | K34: 31.761742
B35: 28 | C35: Provincia | D35: Chuquisaca | E35: Zudáñez | G35: Zudáñez | H35: 38187 | I35: 24.432399 | J35: 43922 | K35: 35.845362
B36: 29 | C36: Provincia | D36: Chuquisaca | E36: Zudáñez | G36: Urbana | H36: 6225 | I36: 77.783132 | J36: 9483 | K36: 93.019087
B37: 30 | C37: Provincia | D37: Chuquisaca | E37: Zudáñez | G37: Rural | H37: 31962 | I37: 14.041674 | J37: 34439 | K37: 20.10221
B38: 31 | C38: Municipio/TIOC | D38: Chuquisaca | E38: Zudáñez | F38: Zudáñez | G38: Zudáñez | H38: 10894 | I38: 32.274647 | J38: 13446 | K38: 36.501562
B39: 32 | C39: Municipio/TIOC | D39: Chuquisaca | E39: Zudáñez | F39: Zudáñez | G39: Urbana | H39: 3772 | I39: 83.64263 | J39: 4604 | K39: 92.85404
B40: 33 | C40: Municipio/TIOC | D40: Chuquisaca | E40: Zudáñez | F40: Zudáñez | G40: Rural | H40: 7122 | I40: 5.0688009 | J40: 8842 | K40: 7.1590138
B41: 34 | C41: Municipio/TIOC | D41: Chuquisaca | E41: Zudáñez | F41: Presto | G41: Presto | H41: 11791 | I41: 18.607412 | J41: 12443 | K41: 31.857269
B42: 35 | C42: Municipio/TIOC | D42: Chuquisaca | E42: Zudáñez | F42: Presto | G42: Urbana | H42: 2453 | I42: 68.772931 | J42: 2191 | K42: 88.224555
...

Sheet Datos procesados
C1: 2012 | F1: 2024
A2: Codigo | B2: Municipio | C2: Población en viviendas particulares, 2012 | D2: Porcentaje de población que utiliza combustible limpio para cocinar, 2012 | E2: Población sin energía limpia para cocinar, 2012 | F2: Población en viviendas particulares, 2024 | G2: Porcentaje de población que utiliza combustible limpio para cocinar, 2024 | H2: Población sin energía limpia para cocinar, 2024 | J2: Departamento | K2: Población en viviendas particulares, 2012 | L2: Porcentaje de población que utiliza combustible limpio para cocinar, 2012 | M2: Población sin energía limpia para cocinar, 2012 | N2: Población en viviendas particulares, 2024 | O2: Porcentaje de población que utiliza combustible limpio para cocinar, 2024 | P2: Población sin energía limpia para cocinar, 2024
A3: 10101 | B3: Sucre | C3: 252503 | D3: 92.192568 | E3: =C3-(C3*(D3/100)) -> 19714 | F3: 288058 | G3: 94.741684 | H3: =F3-(F3*(G3/100)) -> 15147 | J3: Chuquisaca | K3: 562160 | L3: 56.840401 | M3: =K3-(K3*(L3/100)) -> 242626 | N3: 589329 | O3: 68.431216 | P3: =N3-(N3*(O3/100)) -> 186044
A4: 10102 | B4: Yotala | C4: 9025 | D4: 53.31856 | E4: =C4-(C4*(D4/100)) -> 4213 | F4: 8903 | G4: 74.31203 | H4: =F4-(F4*(G4/100)) -> 2287 | J4: La Paz | K4: 2653413 | L4: 76.458471 | M4: =K4-(K4*(L4/100)) -> 624654 | N4: 2947200 | O4: 83.640405 | P4: =N4-(N4*(O4/100)) -> 482150
A5: 10103 | B5: Poroma | C5: 16275 | D5: 3.9016897 | E5: =C5-(C5*(D5/100)) -> 15640 | F5: 13555 | G5: 8.8749539 | H5: =F5-(F5*(G5/100)) -> 12352 | J5: Cochabamba | K5: 1720331 | L5: 77.134575 | M5: =K5-(K5*(L5/100)) -> 393361 | N5: 1968192 | O5: 85.508629 | P5: =N5-(N5*(O5/100)) -> 285218
A6: 10201 | B6: Azurduy | C6: 10335 | D6: 10.333817 | E6: =C6-(C6*(D6/100)) -> 9267 | F6: 7808 | G6: 19.851434 | H6: =F6-(F6*(G6/100)) -> 6258 | J6: Oruro | K6: 483358 | L6: 74.175663 | M6: =K6-(K6*(L6/100)) -> 124824 | N6: 557463 | O6: 81.835566 | P6: =N6-(N6*(O6/100)) -> 101260
A7: 10202 | B7: Tarvita | C7: 14063 | D7: 12.650217 | E7: =C7-(C7*(D7/100)) -> 12284 | F7: 16671 | G7: 31.761742 | H7: =F7-(F7*(G7/100)) -> 11376 | J7: Potosí | K7: 810141 | L7: 53.356761 | M7: =K7-(K7*(L7/100)) -> 377876 | N7: 841628 | O7: 64.204851 | P7: =N7-(N7*(O7/100)) -> 301262
A8: 10301 | B8: Zudáñez | C8: 10894 | D8: 32.274647 | E8: =C8-(C8*(D8/100)) -> 7378 | F8: 13446 | G8: 36.501562 | H8: =F8-(F8*(G8/100)) -> 8538 | J8: Tarija | K8: 458961 | L8: 77.919039 | M8: =K8-(K8*(L8/100)) -> 101343 | N8: 519512 | O8: 87.491146 | P8: =N8-(N8*(O8/100)) -> 64985
A9: 10302 | B9: Presto | C9: 11791 | D9: 18.607412 | E9: =C9-(C9*(D9/100)) -> 9597 | F9: 12443 | G9: 31.857269 | H9: =F9-(F9*(G9/100)) -> 8479 | J9: Santa Cruz | K9: 2556717 | L9: 86.780704 | M9: =K9-(K9*(L9/100)) -> 337980 | N9: 3029443 | O9: 92.338427 | P9: =N9-(N9*(O9/100)) -> 232103
A10: 10303 | B10: Mojocoya | C10: 7922 | D10: 31.305226 | E10: =C10-(C10*(D10/100)) -> 5442 | F10: 8995 | G10: 49.961089 | H10: =F10-(F10*(G10/100)) -> 4501 | J10: Beni | K10: 403141 | L10: 64.579638 | M10: =K10-(K10*(L10/100)) -> 142794 | N10: 469834 | O10: 76.139445 | P10: =N10-(N10*(O10/100)) -> 112105
A11: 10304 | B11: Icla | C11: 7580 | D11: 15.039578 | E11: =C11-(C11*(D11/100)) -> 6440 | F11: 9038 | G11: 26.311131 | H11: =F11-(F11*(G11/100)) -> 6660 | J11: Pando | K11: 102407 | L11: 54.768717 | M11: =K11-(K11*(L11/100)) -> 46320 | N11: 126967 | O11: 76.752227 | P11: =N11-(N11*(O11/100)) -> 29517
A12: 10401 | B12: Padilla | C12: 10039 | D12: 32.821994 | E12: =C12-(C12*(D12/100)) -> 6744 | F12: 8989 | G12: 49.404828 | H12: =F12-(F12*(G12/100)) -> 4548 | J12: Bolivia | K12: 9750629 | L12: 75.470526 | M12: =K12-(K12*(L12/100)) -> 2391778 | N12: 11049568 | O12: 83.758243 | P12: =N12-(N12*(O12/100)) -> 1794644
A13: 10402 | B13: Tomina | C13: 8273 | D13: 20.971836 | E13: =C13-(C13*(D13/100)) -> 6538 | F13: 8428 | G13: 33.068344 | H13: =F13-(F13*(G13/100)) -> 5641 | J13: Gran Chaco | K13: =SUM(C247:C249) -> 137374 | L13: =100-((M13/K13)*100) -> 78.090468 | M13: =SUM(E247:E249) -> 30098 | N13: =SUM(F247:F249) -> 153712 | O13: =100-((P13/N13)*100) -> 86.785027 | P13: =SUM(H247:H249) -> 20313
A14: 10403 | B14: Sopachuy | C14: 7146 | D14: 23.467674 | E14: =C14-(C14*(D14/100)) -> 5469 | F14: 6872 | G14: 31.388242 | H14: =F14-(F14*(G14/100)) -> 4715
A15: 10404 | B15: Alcalá | C15: 4829 | D15: 30.234003 | E15: =C15-(C15*(D15/100)) -> 3369 | F15: 3743 | G15: 43.52124 | H15: =F15-(F15*(G15/100)) -> 2114
A16: 10405 | B16: El Villar | C16: 4283 | D16: 18.958674 | E16: =C16-(C16*(D16/100)) -> 3471 | F16: 5624 | G16: 23.275249 | H16: =F16-(F16*(G16/100)) -> 4315
A17: 10501 | B17: Monteagudo | C17: 23158 | D17: 51.787719 | E17: =C17-(C17*(D17/100)) -> 11165 | F17: 24007 | G17: 67.513642 | H17: =F17-(F17*(G17/100)) -> 7799
A18: 10502 | B18: Huacareta | C18: 7965 | D18: 24.984306 | E18: =C18-(C18*(D18/100)) -> 5975 | F18: 7016 | G18: 37.742303 | H18: =F18-(F18*(G18/100)) -> 4368
A19: 10601 | B19: Tarabuco | C19: 16671 | D19: 27.388879 | E19: =C19-(C19*(D19/100)) -> 12105 | F19: 13110 | G19: 45.514874 | H19: =F19-(F19*(G19/100)) -> 7143
A20: 10602 | B20: Yamparáez | C20: 9838 | D20: 30.351698 | E20: =C20-(C20*(D20/100)) -> 6852 | F20: 8359 | G20: 54.193085 | H20: =F20-(F20*(G20/100)) -> 3829
A21: 10701 | B21: Camargo | C21: 14936 | D21: 46.411355 | E21: =C21-(C21*(D21/100)) -> 8004 | F21: 14219 | G21: 60.292566 | H21: =F21-(F21*(G21/100)) -> 5646
A22: 10702 | B22: San Lucas | C22: 32142 | D22: 24.463319 | E22: =C22-(C22*(D22/100)) -> 24279 | F22: 26515 | G22: 43.809165 | H22: =F22-(F22*(G22/100)) -> 14899
A23: 10703 | B23: Incahuasi | C23: 12849 | D23: 20.281734 | E23: =C23-(C23*(D23/100)) -> 10243 | F23: 15967 | G23: 37.220517 | H23: =F23-(F23*(G23/100)) -> 10024
A24: 10704 | B24: Villa Charcas | C24: 15656 | D24: 31.432039 | E24: =C24-(C24*(D24/100)) -> 10735 | F24: 14145 | G24: 49.848003 | H24: =F24-(F24*(G24/100)) -> 7094
A25: 10801 | B25: Villa Serrano | C25: 10876 | D25: 31.463773 | E25: =C25-(C25*(D25/100)) -> 7454 | F25: 8941 | G25: 44.838385 | H25: =F25-(F25*(G25/100)) -> 4932
... A345: 90503 | B345: Santos Mercado | C345: 1956 | D345: 5.2658487 | E345: =C345-(C345*(D345/100)) -> 1853 | F345: 2270 | G345: 42.599119 | H345: =F345-(F345*(G345/100)) -> 1303

Sheet Indicador_MUN
A1: Codigo | B1: Municipio | C1: sdg7_1_energia_limpia_cocinar_2012 | D1: sdg7_1_energia_limpia_cocinar_2024
A2: 10101 | B2: Sucre | C2: 92.192568 | D2: 94.741684
A3: 10102 | B3: Yotala | C3: 53.31856 | D3: 74.31203
A4: 10103 | B4: Poroma | C4: 3.9016897 | D4: 8.8749539
A5: 10201 | B5: Azurduy | C5: 10.333817 | D5: 19.851434
A6: 10202 | B6: Tarvita | C6: 12.650217 | D6: 31.761742
A7: 10301 | B7: Zudáñez | C7: 32.274647 | D7: 36.501562
A8: 10302 | B8: Presto | C8: 18.607412 | D8: 31.857269
A9: 10303 | B9: Mojocoya | C9: 31.305226 | D9: 49.961089
A10: 10304 | B10: Icla | C10: 15.039578 | D10: 26.311131
A11: 10401 | B11: Padilla | C11: 32.821994 | D11: 49.404828
A12: 10402 | B12: Tomina | C12: 20.971836 | D12: 33.068344
A13: 10403 | B13: Sopachuy | C13: 23.467674 | D13: 31.388242
... A344: 90503 | B344: Santos Mercado | C344: 5.2658487 | D344: 42.599119

Sheet Absoluto_MUN
A1: Codigo | B1: Municipio | C1: sdg7_1_energia_limpia_cocinar_abs_2012 | D1: sdg7_1_energia_limpia_cocinar_abs_2024
A2: 10101 | B2: Sucre | C2: 19714 | D2: 15147
A3: 10102 | B3: Yotala | C3: 4213 | D3: 2287
A4: 10103 | B4: Poroma | C4: 15640 | D4: 12352
A5: 10201 | B5: Azurduy | C5: 9267 | D5: 6258
A6: 10202 | B6: Tarvita | C6: 12284 | D6: 11376
A7: 10301 | B7: Zudáñez | C7: 7378 | D7: 8538
A8: 10302 | B8: Presto | C8: 9597 | D8: 8479
A9: 10303 | B9: Mojocoya | C9: 5442 | D9: 4501
A10: 10304 | B10: Icla | C10: 6440 | D10: 6660
A11: 10401 | B11: Padilla | C11: 6744 | D11: 4548
A12: 10402 | B12: Tomina | C12: 6538 | D12: 5641
A13: 10403 | B13: Sopachuy | C13: 5469 | D13: 4715
... A344: 90503 | B344: Santos Mercado | C344: 1853 | D344: 1303

Sheet Indicador_DEP
A1: id_departamento | B1: Departamento | C1: sdg7_1_energia_limpia_cocinar_2012 | D1: sdg7_1_energia_limpia_cocinar_2024
A2: 1 | B2: Chuquisaca | C2: 56.840401 | D2: 68.431216
A3: 2 | B3: La Paz | C3: 76.458471 | D3: 83.640405
A4: 3 | B4: Cochabamba | C4: 77.134575 | D4: 85.508629
A5: 4 | B5: Oruro | C5: 74.175663 | D5: 81.835566
A6: 5 | B6: Potosí | C6: 53.356761 | D6: 64.204851
A7: 6 | B7: Tarija | C7: 77.919039 | D7: 87.491146
A8: 7 | B8: Santa Cruz | C8: 86.780704 | D8: 92.338427
A9: 8 | B9: Beni | C9: 64.579638 | D9: 76.139445
A10: 9 | B10: Pando | C10: 54.768717 | D10: 76.752227
A11: 10 | B11: Gran Chaco | C11: 78.090468 | D11: 86.785027
A12: 11 | B12: Bolivia | C12: 75.470526 | D12: 83.758243

Sheet Absoluto_DEP
A1: id_departamento | B1: Departamento | C1: sdg7_1_energia_limpia_cocinar_abs_2012 | D1: sdg7_1_energia_limpia_cocinar_abs_2024
A2: 1 | B2: Chuquisaca | C2: 242626 | D2: 186044
A3: 2 | B3: La Paz | C3: 624654 | D3: 482150
A4: 3 | B4: Cochabamba | C4: 393361 | D4: 285218
A5: 4 | B5: Oruro | C5: 124824 | D5: 101260
A6: 5 | B6: Potosí | C6: 377876 | D6: 301262
A7: 6 | B7: Tarija | C7: 101343 | D7: 64985
A8: 7 | B8: Santa Cruz | C8: 337980 | D8: 232103
A9: 8 | B9: Beni | C9: 142794 | D9: 112105
A10: 9 | B10: Pando | C10: 46320 | D10: 29517
A11: 10 | B11: Gran Chaco | C11: 30098 | D11: 20313
A12: 11 | B12: Bolivia | C12: 2391778 | D12: 1794644

Sheet Umbral
A1: ODS | B1: Indicador | C1: Meta Alcanzada max | D1: Meta Alcanzada min | E1: Próximo a Alcanzarse max | F1: Próximo a Alcanzarse min | G1: Quedan Retos Importantes max | H1: Quedan Retos Importantes min | I1: Quedan Retos Grandes max | J1: Quedan Retos Grandes min | K1: Criterio Umbral Verde
A2: 7 | B2: Energía limpia para cocinar | C2: 100 | D2: 85 | E2: 85 | F2: 67.5 | G2: 67.5 | H2: 50 | I2: 50 | J2: 0 | K2: SDG Index Global

Sheet Graficos
A1: Departamento | B1: PORCENTAJE DE POBLACIÓN QUE UTILIZA COMBUSTIBLE LIMPIO PARA COCINAR, 2012 | C1: PORCENTAJE DE POBLACIÓN QUE NO UTILIZA COMBUSTIBLE LIMPIO PARA COCINAR, 2012 | D1: PORCENTAJE DE POBLACIÓN QUE UTILIZA COMBUSTIBLE LIMPIO PARA COCINAR, 2024 | E1: PORCENTAJE DE POBLACIÓN QUE NO UTILIZA COMBUSTIBLE LIMPIO PARA COCINAR, 2024 | G1: Categoría | H1: 2012 (cantidad de municipios) | I1: 2024 (cantidad de municipios) | J1: Diferencia
A2: Chuquisaca | B2: 56.840401 | C2: =100-B2 -> 43.159599 | D2: 68.431216 | E2: =100-D2 -> 31.568784 | G2: ODS alcanzado | H2: =COUNTIF(Mapa!D2:D344, "Verde") -> 35 | I2: =COUNTIF(Mapa!F2:F344, "Verde") -> 70 | J2: =I2-H2 -> 35
A3: La Paz | B3: 76.458471 | C3: =100-B3 -> 23.541529 | D3: 83.640405 | E3: =100-D3 -> 16.359596 | G3: Próximo a alcanzarse | H3: =COUNTIF(Mapa!D2:D344, "Amarillo") -> 38 | I3: =COUNTIF(Mapa!F2:F344, "Amarillo") -> 82 | J3: =I3-H3 -> 44
A4: Cochabamba | B4: 77.134575 | C4: =100-B4 -> 22.865425 | D4: 85.508629 | E4: =100-D4 -> 14.491371 | G4: Quedan retos importantes | H4: =COUNTIF(Mapa!D2:D344, "Naranja") -> 44 | I4: =COUNTIF(Mapa!F2:F344, "Naranja") -> 70 | J4: =I4-H4 -> 26
A5: Oruro | B5: 74.175663 | C5: =100-B5 -> 25.824337 | D5: 81.835566 | E5: =100-D5 -> 18.164434 | G5: Quedan retos grandes | H5: =COUNTIF(Mapa!D2:D344, "Rojo") -> 226 | I5: =COUNTIF(Mapa!F2:F344, "Rojo") -> 121 | J5: =I5-H5 -> -105
A6: Potosí | B6: 53.356761 | C6: =100-B6 -> 46.643239 | D6: 64.204851 | E6: =100-D6 -> 35.795149
A7: Tarija | B7: 77.919039 | C7: =100-B7 -> 22.080961 | D7: 87.491146 | E7: =100-D7 -> 12.508854
A8: Santa Cruz | B8: 86.780704 | C8: =100-B8 -> 13.219297 | D8: 92.338427 | E8: =100-D8 -> 7.6615734
A9: Beni | B9: 64.579638 | C9: =100-B9 -> 35.420362 | D9: 76.139445 | E9: =100-D9 -> 23.860555
A10: Pando | B10: 54.768717 | C10: =100-B10 -> 45.231283 | D10: 76.752227 | E10: =100-D10 -> 23.247773
A11: Bolivia | B11: 75.470526 | C11: =100-B11 -> 24.529474 | D11: 83.758243 | E11: =100-D11 -> 16.241757

Sheet Mapa
A1: Codigo | B1: Municipio | C1: sdg7_1_energia_limpia_cocinar, 2012 | D1: Umbral 2012 | E1: sdg7_1_energia_limpia_cocinar, 2024 | F1: Umbral 2024
A2: 10101 | B2: Sucre | C2: 92.192568 | D2: =IF(C2<=50,"Rojo", IF(C2<=67.5,"Naranja", IF(C2<=85,"Amarillo","Verde"))) -> Verde | E2: 94.741684 | F2: =IF(E2<=50,"Rojo", IF(E2<=67.5,"Naranja", IF(E2<=85,"Amarillo","Verde"))) -> Verde
A3: 10102 | B3: Yotala | C3: 53.31856 | D3: =IF(C3<=50,"Rojo", IF(C3<=67.5,"Naranja", IF(C3<=85,"Amarillo","Verde"))) -> Naranja | E3: 74.31203 | F3: =IF(E3<=50,"Rojo", IF(E3<=67.5,"Naranja", IF(E3<=85,"Amarillo","Verde"))) -> Amarillo
A4: 10103 | B4: Poroma | C4: 3.9016897 | D4: =IF(C4<=50,"Rojo", IF(C4<=67.5,"Naranja", IF(C4<=85,"Amarillo","Verde"))) -> Rojo | E4: 8.8749539 | F4: =IF(E4<=50,"Rojo", IF(E4<=67.5,"Naranja", IF(E4<=85,"Amarillo","Verde"))) -> Rojo
A5: 10201 | B5: Azurduy | C5: 10.333817 | D5: =IF(C5<=50,"Rojo", IF(C5<=67.5,"Naranja", IF(C5<=85,"Amarillo","Verde"))) -> Rojo | E5: 19.851434 | F5: =IF(E5<=50,"Rojo", IF(E5<=67.5,"Naranja", IF(E5<=85,"Amarillo","Verde"))) -> Rojo
A6: 10202 | B6: Tarvita | C6: 12.650217 | D6: =IF(C6<=50,"Rojo", IF(C6<=67.5,"Naranja", IF(C6<=85,"Amarillo","Verde"))) -> Rojo | E6: 31.761742 | F6: =IF(E6<=50,"Rojo", IF(E6<=67.5,"Naranja", IF(E6<=85,"Amarillo","Verde"))) -> Rojo
A7: 10301 | B7: Zudáñez | C7: 32.274647 | D7: =IF(C7<=50,"Rojo", IF(C7<=67.5,"Naranja", IF(C7<=85,"Amarillo","Verde"))) -> Rojo | E7: 36.501562 | F7: =IF(E7<=50,"Rojo", IF(E7<=67.5,"Naranja", IF(E7<=85,"Amarillo","Verde"))) -> Rojo
A8: 10302 | B8: Presto | C8: 18.607412 | D8: =IF(C8<=50,"Rojo", IF(C8<=67.5,"Naranja", IF(C8<=85,"Amarillo","Verde"))) -> Rojo | E8: 31.857269 | F8: =IF(E8<=50,"Rojo", IF(E8<=67.5,"Naranja", IF(E8<=85,"Amarillo","Verde"))) -> Rojo
A9: 10303 | B9: Mojocoya | C9: 31.305226 | D9: =IF(C9<=50,"Rojo", IF(C9<=67.5,"Naranja", IF(C9<=85,"Amarillo","Verde"))) -> Rojo | E9: 49.961089 | F9: =IF(E9<=50,"Rojo", IF(E9<=67.5,"Naranja", IF(E9<=85,"Amarillo","Verde"))) -> Rojo
A10: 10304 | B10: Icla | C10: 15.039578 | D10: =IF(C10<=50,"Rojo", IF(C10<=67.5,"Naranja", IF(C10<=85,"Amarillo","Verde"))) -> Rojo | E10: 26.311131 | F10: =IF(E10<=50,"Rojo", IF(E10<=67.5,"Naranja", IF(E10<=85,"Amarillo","Verde"))) -> Rojo
A11: 10401 | B11: Padilla | C11: 32.821994 | D11: =IF(C11<=50,"Rojo", IF(C11<=67.5,"Naranja", IF(C11<=85,"Amarillo","Verde"))) -> Rojo | E11: 49.404828 | F11: =IF(E11<=50,"Rojo", IF(E11<=67.5,"Naranja", IF(E11<=85,"Amarillo","Verde"))) -> Rojo
A12: 10402 | B12: Tomina | C12: 20.971836 | D12: =IF(C12<=50,"Rojo", IF(C12<=67.5,"Naranja", IF(C12<=85,"Amarillo","Verde"))) -> Rojo | E12: 33.068344 | F12: =IF(E12<=50,"Rojo", IF(E12<=67.5,"Naranja", IF(E12<=85,"Amarillo","Verde"))) -> Rojo
A13: 10403 | B13: Sopachuy | C13: 23.467674 | D13: =IF(C13<=50,"Rojo", IF(C13<=67.5,"Naranja", IF(C13<=85,"Amarillo","Verde"))) -> Rojo | E13: 31.388242 | F13: =IF(E13<=50,"Rojo", IF(E13<=67.5,"Naranja", IF(E13<=85,"Amarillo","Verde"))) -> Rojo
... A344: 90503 | B344: Santos Mercado | C344: 5.2658487 | D344: =IF(C344<=50,"Rojo", IF(C344<=67.5,"Naranja", IF(C344<=85,"Amarillo","Verde"))) -> Rojo | E344: 42.599119 | F344: =IF(E344<=50,"Rojo", IF(E344<=67.5,"Naranja", IF(E344<=85,"Amarillo","Verde"))) -> Rojo
