Workbook

Sheet Datos_originales
A1: Etiquetas de fila | B1: Departamento | C1: Municipio | D1: Sin bosque 2011 | E1: Forest cover 2011 | F1: Deforestación promedio 2012-2014 | G1: Deforestación promedio 2022-2024 | H1: Deforestation 2012 | I1: Deforestation 2013 | J1: Deforestation 2014 | K1: Deforestation 2015 | L1: Deforestation 2016 | M1: Deforestation 2017 | N1: Deforestation 2018 | O1: Deforestation 2019 | P1: Deforestation 2020 | Q1: Deforestation 2021 | R1: Deforestation 2022 | S1: Deforestation 2023 | T1: Deforestation 2024 | U1: Forest Loss 2012 | V1: Forest Loss 2013 | W1: Forest Loss 2014 | X1: Forest Loss 2015 | Y1: Forest Loss 2016 | Z1: Forest Loss 2017 | AA1: Forest Loss 2018 | AB1: Forest Loss 2019 | AC1: Forest Loss 2020 | AD1: Forest Loss 2021 | AE1: Forest Loss 2022 | AF1: Forest Loss 2023 | AG1: Forest Loss 2024 | AH1: Tasa deforestación 2012 | AI1: Tasa deforestación 2013 | AJ1: Tasa deforestación 2014 | AK1: Tasa deforestación 2015 | AL1: Tasa deforestación 2016 | AM1: Tasa deforestación 2017 | AN1: Tasa deforestación 2018 | AO1: Tasa deforestación 2019 | AP1: Tasa deforestación 2020 | AQ1: Tasa deforestación 2021 | AR1: Tasa deforestación 2022 | AS1: Tasa deforestación 2023 | AT1: Tasa deforestación 2024 | AU1: Tasa de pérdida de bosque 2012 | AV1: Tasa de pérdida de bosque 2013 | AW1: Tasa de pérdida de bosque 2014 | AX1: Tasa de pérdida de bosque 2015 | AY1: Tasa de pérdida de bosque 2016 | AZ1: Tasa de pérdida de bosque 2017 | BA1: Tasa de pérdida de bosque 2018 | BB1: Tasa de pérdida de bosque 2019 | BC1: Tasa de pérdida de bosque 2020 | BD1: Tasa de pérdida de bosque 2021 | BE1: Tasa de pérdida de bosque 2022 | BF1: Tasa de pérdida de bosque 2023 | BG1: Tasa de pérdida de bosque 2024
A2: 10101 | B2: Chuquisaca | C2: Sucre | D2: =IF(Datos_originales!$E2<1000,"Bosque menor a 1000 ha",Datos_originales!$E2) -> 17890.56 | E2: 17890.56 | F2: =AVERAGE(Datos_originales!$H58:$J58) -> 51.45 | G2: =AVERAGE(Datos_originales!$R58:$T58) -> 131.46 | H2: 0.72 | I2: 1.98 | J2: 2.79 | K2: 1.26 | L2: 3.15 | M2: 2.7 | N2: 1.08 | O2: 0.45 | P2: 1.8 | Q2: 0.72 | R2: 0.09 | S2: 28.8 | T2: 20.07 | U2: 34.56 | V2: 19.53 | W2: 233.73 | X2: 5.58 | Y2: 7.2 | Z2: 11.7 | AA2: 14.4 | AB2: 7.65 | AC2: 41.22 | AD2: 3.87 | AE2: 1.08 | AF2: 44.64 | AG2: 527.58 | AH2: =Datos_originales!$H58/Datos_originales!$E58 -> 0.00087309196 | AI2: =Datos_originales!$I58/Datos_originales!$E58 -> 0.00089021141 | AJ2: =Datos_originales!$J58/Datos_originales!$E58 -> 0.00090577455 | AK2: =Datos_originales!$K58/Datos_originales!$E58 -> 0.00051358351 | AL2: =Datos_originales!$L58/Datos_originales!$E58 -> 0.00069722852 | AM2: =Datos_originales!$M58/Datos_originales!$E58 -> 0.00033616375 | AN2: =Datos_originales!$N58/Datos_originales!$E58 -> 0.00081083941 | AO2: =Datos_originales!$O58/Datos_originales!$E58 -> 0.0003875221 | AP2: =Datos_originales!$P58/Datos_originales!$E58 -> 0.0012388257 | AQ2: =Datos_originales!$Q58/Datos_originales!$E58 -> 0.00015407505 | AR2: =Datos_originales!$R58/Datos_originales!$E58 -> 0.00039063473 | AS2: =Datos_originales!$S58/Datos_originales!$E58 -> 0.0035483951 | AT2: =Datos_originales!$T58/Datos_originales!$E58 -> 0.0028807366 | AU2: =Datos_originales!$U58/Datos_originales!$E58 -> 0.0057178964 | AV2: =Datos_originales!$V58/Datos_originales!$E58 -> 0.0022691053 | AW2: =Datos_originales!$W58/Datos_originales!$E58 -> 0.0032713713 | AX2: =Datos_originales!$X58/Datos_originales!$E58 -> 0.0014411464 | AY2: =Datos_originales!$Y58/Datos_originales!$E58 -> 0.0011843547 | AZ2: =Datos_originales!$Z58/Datos_originales!$E58 -> 0.00053070296 | BA2: =Datos_originales!$AA58/Datos_originales!$E58 -> 0.0012575014 | BB2: =Datos_originales!$AB58/Datos_originales!$E58 -> 0.0038814463 | BC2: =Datos_originales!$AC58/Datos_originales!$E58 -> 0.0018146617 | BD2: =Datos_originales!$AD58/Datos_originales!$E58 -> 0.00058984287 | BE2: =Datos_originales!$AE58/Datos_originales!$E58 -> 0.00056649817 | BF2: =Datos_originales!$AF58/Datos_originales!$E58 -> 0.0041475759 | BG2: =Datos_originales!$AG58/Datos_originales!$E58 -> 0.016377089
A3: 10102 | B3: Chuquisaca | C3: Yotala | D3: =IF(Datos_originales!$E3<1000,"Bosque menor a 1000 ha",Datos_originales!$E3) -> 1252.89 | E3: 1252.89 | F3: =AVERAGE(Datos_originales!$H128:$J128) -> 0.03 | G3: =AVERAGE(Datos_originales!$R128:$T128) -> 0.75 | H3: 1.26 | I3: 0.99 | J3: 1.35 | K3: 1.71 | L3: 1.62 | M3: 1.17 | N3: 0.45 | O3: 1.8 | P3: 0.81 | Q3: 0.63 | R3: 0 | S3: 2.07 | T3: 4.68 | U3: 3.69 | V3: 3.96 | W3: 24.03 | X3: 2.7 | Y3: 2.61 | Z3: 1.44 | AA3: 1.08 | AB3: 2.34 | AC3: 1.17 | AD3: 1.62 | AE3: 0.18 | AF3: 2.52 | AG3: 8.73 | AH3: =Datos_originales!$H128/Datos_originales!$E128 -> 0 | AI3: =Datos_originales!$I128/Datos_originales!$E128 -> 0.00068870523 | AJ3: =Datos_originales!$J128/Datos_originales!$E128 -> 0 | AK3: =Datos_originales!$K128/Datos_originales!$E128 -> 0 | AL3: =Datos_originales!$L128/Datos_originales!$E128 -> 0 | AM3: =Datos_originales!$M128/Datos_originales!$E128 -> 0 | AN3: =Datos_originales!$N128/Datos_originales!$E128 -> 0 | AO3: =Datos_originales!$O128/Datos_originales!$E128 -> 0 | AP3: =Datos_originales!$P128/Datos_originales!$E128 -> 0 | AQ3: =Datos_originales!$Q128/Datos_originales!$E128 -> 0.0061983471 | AR3: =Datos_originales!$R128/Datos_originales!$E128 -> 0.0061983471 | AS3: =Datos_originales!$S128/Datos_originales!$E128 -> 0.010330579 | AT3: =Datos_originales!$T128/Datos_originales!$E128 -> 0.00068870523 | AU3: =Datos_originales!$U128/Datos_originales!$E128 -> 0.0061983471 | AV3: =Datos_originales!$V128/Datos_originales!$E128 -> 0.0048209366 | AW3: =Datos_originales!$W128/Datos_originales!$E128 -> 0.013774105 | AX3: =Datos_originales!$X128/Datos_originales!$E128 -> 0.0013774105 | AY3: =Datos_originales!$Y128/Datos_originales!$E128 -> 0.0055096419 | AZ3: =Datos_originales!$Z128/Datos_originales!$E128 -> 0.034435262 | BA3: =Datos_originales!$AA128/Datos_originales!$E128 -> 0.074380165 | BB3: =Datos_originales!$AB128/Datos_originales!$E128 -> 0.035123967 | BC3: =Datos_originales!$AC128/Datos_originales!$E128 -> 0.0061983471 | BD3: =Datos_originales!$AD128/Datos_originales!$E128 -> 0.0075757576 | BE3: =Datos_originales!$AE128/Datos_originales!$E128 -> 0.0068870523 | BF3: =Datos_originales!$AF128/Datos_originales!$E128 -> 0.07369146 | BG3: =Datos_originales!$AG128/Datos_originales!$E128 -> 0.0013774105
A4: 10103 | B4: Chuquisaca | C4: Poroma | D4: =IF(Datos_originales!$E4<1000,"Bosque menor a 1000 ha",Datos_originales!$E4) -> 26070.66 | E4: 26070.66 | F4: =AVERAGE(Datos_originales!$H229:$J229) -> 0 | G4: =AVERAGE(Datos_originales!$R229:$T229) -> 0 | H4: 0.45 | I4: 0 | J4: 0.09 | K4: 0 | L4: 1.44 | M4: 0 | N4: 0.18 | O4: 0.9 | P4: 0.54 | Q4: 0 | R4: 0.09 | S4: 7.11 | T4: 0.54 | U4: 53.46 | V4: 32.49 | W4: 270 | X4: 10.71 | Y4: 8.73 | Z4: 11.07 | AA4: 16.56 | AB4: 41.94 | AC4: 103.59 | AD4: 0.72 | AE4: 1.98 | AF4: 67.23 | AG4: 3.51 | AH4: =Datos_originales!$H229/Datos_originales!$E229 -> #DIV/0! | AI4: =Datos_originales!$I229/Datos_originales!$E229 -> #DIV/0! | AJ4: =Datos_originales!$J229/Datos_originales!$E229 -> #DIV/0! | AK4: =Datos_originales!$K229/Datos_originales!$E229 -> #DIV/0! | AL4: =Datos_originales!$L229/Datos_originales!$E229 -> #DIV/0! | AM4: =Datos_originales!$M229/Datos_originales!$E229 -> #DIV/0! | AN4: =Datos_originales!$N229/Datos_originales!$E229 -> #DIV/0! | AO4: =Datos_originales!$O229/Datos_originales!$E229 -> #DIV/0! | AP4: =Datos_originales!$P229/Datos_originales!$E229 -> #DIV/0! | AQ4: =Datos_originales!$Q229/Datos_originales!$E229 -> #DIV/0! | AR4: =Datos_originales!$R229/Datos_originales!$E229 -> #DIV/0! | AS4: =Datos_originales!$S229/Datos_originales!$E229 -> #DIV/0! | AT4: =Datos_originales!$T229/Datos_originales!$E229 -> #DIV/0! | AU4: =Datos_originales!$U229/Datos_originales!$E229 -> #DIV/0! | AV4: =Datos_originales!$V229/Datos_originales!$E229 -> #DIV/0! | AW4: =Datos_originales!$W229/Datos_originales!$E229 -> #DIV/0! | AX4: =Datos_originales!$X229/Datos_originales!$E229 -> #DIV/0! | AY4: =Datos_originales!$Y229/Datos_originales!$E229 -> #DIV/0! | AZ4: =Datos_originales!$Z229/Datos_originales!$E229 -> #DIV/0! | BA4: =Datos_originales!$AA229/Datos_originales!$E229 -> #DIV/0! | BB4: =Datos_originales!$AB229/Datos_originales!$E229 -> #DIV/0! | BC4: =Datos_originales!$AC229/Datos_originales!$E229 -> #DIV/0! | BD4: =Datos_originales!$AD229/Datos_originales!$E229 -> #DIV/0! | BE4: =Datos_originales!$AE229/Datos_originales!$E229 -> #DIV/0! | BF4: =Datos_originales!$AF229/Datos_originales!$E229 -> #DIV/0! | BG4: =Datos_originales!$AG229/Datos_originales!$E229 -> #DIV/0!
A5: 10201 | B5: Chuquisaca | C5: Azurduy | D5: =IF(Datos_originales!$E5<1000,"Bosque menor a 1000 ha",Datos_originales!$E5) -> 93727.26 | E5: 93727.26 | F5: =AVERAGE(Datos_originales!$H178:$J178) -> 0 | G5: =AVERAGE(Datos_originales!$R178:$T178) -> 0 | H5: 24.84 | I5: 57.96 | J5: 103.59 | K5: 61.38 | L5: 77.22 | M5: 143.91 | N5: 105.66 | O5: 82.35 | P5: 128.79 | Q5: 47.25 | R5: 95.58 | S5: 512.64 | T5: 244.62 | U5: 43.74 | V5: 80.46 | W5: 544.41 | X5: 75.87 | Y5: 89.91 | Z5: 153.18 | AA5: 116.28 | AB5: 104.58 | AC5: 143.01 | AD5: 63.45 | AE5: 174.51 | AF5: 572.31 | AG5: 252.36 | AH5: =Datos_originales!$H178/Datos_originales!$E178 -> #DIV/0! | AI5: =Datos_originales!$I178/Datos_originales!$E178 -> #DIV/0! | AJ5: =Datos_originales!$J178/Datos_originales!$E178 -> #DIV/0! | AK5: =Datos_originales!$K178/Datos_originales!$E178 -> #DIV/0! | AL5: =Datos_originales!$L178/Datos_originales!$E178 -> #DIV/0! | AM5: =Datos_originales!$M178/Datos_originales!$E178 -> #DIV/0! | AN5: =Datos_originales!$N178/Datos_originales!$E178 -> #DIV/0! | AO5: =Datos_originales!$O178/Datos_originales!$E178 -> #DIV/0! | AP5: =Datos_originales!$P178/Datos_originales!$E178 -> #DIV/0! | AQ5: =Datos_originales!$Q178/Datos_originales!$E178 -> #DIV/0! | AR5: =Datos_originales!$R178/Datos_originales!$E178 -> #DIV/0! | AS5: =Datos_originales!$S178/Datos_originales!$E178 -> #DIV/0! | AT5: =Datos_originales!$T178/Datos_originales!$E178 -> #DIV/0! | AU5: =Datos_originales!$U178/Datos_originales!$E178 -> #DIV/0! | AV5: =Datos_originales!$V178/Datos_originales!$E178 -> #DIV/0! | AW5: =Datos_originales!$W178/Datos_originales!$E178 -> #DIV/0! | AX5: =Datos_originales!$X178/Datos_originales!$E178 -> #DIV/0! | AY5: =Datos_originales!$Y178/Datos_originales!$E178 -> #DIV/0! | AZ5: =Datos_originales!$Z178/Datos_originales!$E178 -> #DIV/0! | BA5: =Datos_originales!$AA178/Datos_originales!$E178 -> #DIV/0! | BB5: =Datos_originales!$AB178/Datos_originales!$E178 -> #DIV/0! | BC5: =Datos_originales!$AC178/Datos_originales!$E178 -> #DIV/0! | BD5: =Datos_originales!$AD178/Datos_originales!$E178 -> #DIV/0! | BE5: =Datos_originales!$AE178/Datos_originales!$E178 -> #DIV/0! | BF5: =Datos_originales!$AF178/Datos_originales!$E178 -> #DIV/0! | BG5: =Datos_originales!$AG178/Datos_originales!$E178 -> #DIV/0!
A6: 10202 | B6: Chuquisaca | C6: Tarvita | D6: =IF(Datos_originales!$E6<1000,"Bosque menor a 1000 ha",Datos_originales!$E6) -> 39639.24 | E6: 39639.24 | F6: =AVERAGE(Datos_originales!$H208:$J208) -> 0 | G6: =AVERAGE(Datos_originales!$R208:$T208) -> 0 | H6: 6.75 | I6: 17.91 | J6: 21.33 | K6: 18.36 | L6: 12.06 | M6: 34.02 | N6: 23.31 | O6: 47.16 | P6: 38.52 | Q6: 23.94 | R6: 3.78 | S6: 130.59 | T6: 43.56 | U6: 20.52 | V6: 43.11 | W6: 417.69 | X6: 44.1 | Y6: 27.72 | Z6: 41.13 | AA6: 43.02 | AB6: 81.63 | AC6: 49.77 | AD6: 31.41 | AE6: 169.74 | AF6: 182.88 | AG6: 45 | AH6: =Datos_originales!$H208/Datos_originales!$E208 -> #DIV/0! | AI6: =Datos_originales!$I208/Datos_originales!$E208 -> #DIV/0! | AJ6: =Datos_originales!$J208/Datos_originales!$E208 -> #DIV/0! | AK6: =Datos_originales!$K208/Datos_originales!$E208 -> #DIV/0! | AL6: =Datos_originales!$L208/Datos_originales!$E208 -> #DIV/0! | AM6: =Datos_originales!$M208/Datos_originales!$E208 -> #DIV/0! | AN6: =Datos_originales!$N208/Datos_originales!$E208 -> #DIV/0! | AO6: =Datos_originales!$O208/Datos_originales!$E208 -> #DIV/0! | AP6: =Datos_originales!$P208/Datos_originales!$E208 -> #DIV/0! | AQ6: =Datos_originales!$Q208/Datos_originales!$E208 -> #DIV/0! | AR6: =Datos_originales!$R208/Datos_originales!$E208 -> #DIV/0! | AS6: =Datos_originales!$S208/Datos_originales!$E208 -> #DIV/0! | AT6: =Datos_originales!$T208/Datos_originales!$E208 -> #DIV/0! | AU6: =Datos_originales!$U208/Datos_originales!$E208 -> #DIV/0! | AV6: =Datos_originales!$V208/Datos_originales!$E208 -> #DIV/0! | AW6: =Datos_originales!$W208/Datos_originales!$E208 -> #DIV/0! | AX6: =Datos_originales!$X208/Datos_originales!$E208 -> #DIV/0! | AY6: =Datos_originales!$Y208/Datos_originales!$E208 -> #DIV/0! | AZ6: =Datos_originales!$Z208/Datos_originales!$E208 -> #DIV/0! | BA6: =Datos_originales!$AA208/Datos_originales!$E208 -> #DIV/0! | BB6: =Datos_originales!$AB208/Datos_originales!$E208 -> #DIV/0! | BC6: =Datos_originales!$AC208/Datos_originales!$E208 -> #DIV/0! | BD6: =Datos_originales!$AD208/Datos_originales!$E208 -> #DIV/0! | BE6: =Datos_originales!$AE208/Datos_originales!$E208 -> #DIV/0! | BF6: =Datos_originales!$AF208/Datos_originales!$E208 -> #DIV/0! | BG6: =Datos_originales!$AG208/Datos_originales!$E208 -> #DIV/0!
A7: 10301 | B7: Chuquisaca | C7: Zudáñez | D7: =IF(Datos_originales!$E7<1000,"Bosque menor a 1000 ha",Datos_originales!$E7) -> 9395.1 | E7: 9395.1 | F7: =AVERAGE(Datos_originales!$H221:$J221) -> 0 | G7: =AVERAGE(Datos_originales!$R221:$T221) -> 0 | H7: 0.09 | I7: 0 | J7: 0.09 | K7: 0 | L7: 0.18 | M7: 0 | N7: 0.18 | O7: 0.63 | P7: 0.63 | Q7: 0 | R7: 0.09 | S7: 10.53 | T7: 3.87 | U7: 8.73 | V7: 6.93 | W7: 143.28 | X7: 1.26 | Y7: 13.32 | Z7: 18.45 | AA7: 73.8 | AB7: 74.88 | AC7: 75.33 | AD7: 0.09 | AE7: 0.81 | AF7: 39.15 | AG7: 4.32 | AH7: =Datos_originales!$H221/Datos_originales!$E221 -> 0 | AI7: =Datos_originales!$I221/Datos_originales!$E221 -> 0 | AJ7: =Datos_originales!$J221/Datos_originales!$E221 -> 0 | AK7: =Datos_originales!$K221/Datos_originales!$E221 -> 0 | AL7: =Datos_originales!$L221/Datos_originales!$E221 -> 0 | AM7: =Datos_originales!$M221/Datos_originales!$E221 -> 0 | AN7: =Datos_originales!$N221/Datos_originales!$E221 -> 0 | AO7: =Datos_originales!$O221/Datos_originales!$E221 -> 0 | AP7: =Datos_originales!$P221/Datos_originales!$E221 -> 0 | AQ7: =Datos_originales!$Q221/Datos_originales!$E221 -> 0 | AR7: =Datos_originales!$R221/Datos_originales!$E221 -> 0 | AS7: =Datos_originales!$S221/Datos_originales!$E221 -> 0 | AT7: =Datos_originales!$T221/Datos_originales!$E221 -> 0 | AU7: =Datos_originales!$U221/Datos_originales!$E221 -> 0.0044742729 | AV7: =Datos_originales!$V221/Datos_originales!$E221 -> 0 | AW7: =Datos_originales!$W221/Datos_originales!$E221 -> 0.026845638 | AX7: =Datos_originales!$X221/Datos_originales!$E221 -> 0 | AY7: =Datos_originales!$Y221/Datos_originales!$E221 -> 0 | AZ7: =Datos_originales!$Z221/Datos_originales!$E221 -> 0 | BA7: =Datos_originales!$AA221/Datos_originales!$E221 -> 0 | BB7: =Datos_originales!$AB221/Datos_originales!$E221 -> 0 | BC7: =Datos_originales!$AC221/Datos_originales!$E221 -> 0.0022371365 | BD7: =Datos_originales!$AD221/Datos_originales!$E221 -> 0 | BE7: =Datos_originales!$AE221/Datos_originales!$E221 -> 0 | BF7: =Datos_originales!$AF221/Datos_originales!$E221 -> 0.0067114094 | BG7: =Datos_originales!$AG221/Datos_originales!$E221 -> 0
A8: 10302 | B8: Chuquisaca | C8: Presto | D8: =IF(Datos_originales!$E8<1000,"Bosque menor a 1000 ha",Datos_originales!$E8) -> 33133.32 | E8: 33133.32 | F8: =AVERAGE(Datos_originales!$H231:$J231) -> 0.18 | G8: =AVERAGE(Datos_originales!$R231:$T231) -> 0.48 | H8: 0.54 | I8: 0.09 | J8: 0.45 | K8: 0 | L8: 0 | M8: 0 | N8: 0 | O8: 0 | P8: 0 | Q8: 0 | R8: 0 | S8: 14.31 | T8: 1.98 | U8: 61.38 | V8: 25.56 | W8: 319.5 | X8: 11.88 | Y8: 17.46 | Z8: 10.44 | AA8: 51.39 | AB8: 64.89 | AC8: 410.31 | AD8: 0.09 | AE8: 0.45 | AF8: 52.83 | AG8: 3.15 | AH8: =Datos_originales!$H231/Datos_originales!$E231 -> 0 | AI8: =Datos_originales!$I231/Datos_originales!$E231 -> 0 | AJ8: =Datos_originales!$J231/Datos_originales!$E231 -> 0.012847966 | AK8: =Datos_originales!$K231/Datos_originales!$E231 -> 0.017130621 | AL8: =Datos_originales!$L231/Datos_originales!$E231 -> 0.0085653105 | AM8: =Datos_originales!$M231/Datos_originales!$E231 -> 0.0042826552 | AN8: =Datos_originales!$N231/Datos_originales!$E231 -> 0.0042826552 | AO8: =Datos_originales!$O231/Datos_originales!$E231 -> 0.010706638 | AP8: =Datos_originales!$P231/Datos_originales!$E231 -> 0.0021413276 | AQ8: =Datos_originales!$Q231/Datos_originales!$E231 -> 0.010706638 | AR8: =Datos_originales!$R231/Datos_originales!$E231 -> 0 | AS8: =Datos_originales!$S231/Datos_originales!$E231 -> 0.0021413276 | AT8: =Datos_originales!$T231/Datos_originales!$E231 -> 0.032119914 | AU8: =Datos_originales!$U231/Datos_originales!$E231 -> 0 | AV8: =Datos_originales!$V231/Datos_originales!$E231 -> 0.014989293 | AW8: =Datos_originales!$W231/Datos_originales!$E231 -> 0.038543897 | AX8: =Datos_originales!$X231/Datos_originales!$E231 -> 0.027837259 | AY8: =Datos_originales!$Y231/Datos_originales!$E231 -> 0.027837259 | AZ8: =Datos_originales!$Z231/Datos_originales!$E231 -> 0.0064239829 | BA8: =Datos_originales!$AA231/Datos_originales!$E231 -> 0.012847966 | BB8: =Datos_originales!$AB231/Datos_originales!$E231 -> 0.014989293 | BC8: =Datos_originales!$AC231/Datos_originales!$E231 -> 0.0021413276 | BD8: =Datos_originales!$AD231/Datos_originales!$E231 -> 0.034261242 | BE8: =Datos_originales!$AE231/Datos_originales!$E231 -> 0.0064239829 | BF8: =Datos_originales!$AF231/Datos_originales!$E231 -> 0.0042826552 | BG8: =Datos_originales!$AG231/Datos_originales!$E231 -> 0.47965739
A9: 10303 | B9: Chuquisaca | C9: Mojocoya | D9: =IF(Datos_originales!$E9<1000,"Bosque menor a 1000 ha",Datos_originales!$E9) -> 30785.4 | E9: 30785.4 | F9: =AVERAGE(Datos_originales!$H206:$J206) -> 0 | G9: =AVERAGE(Datos_originales!$R206:$T206) -> 0 | H9: 0.72 | I9: 2.25 | J9: 1.17 | K9: 0.54 | L9: 2.16 | M9: 1.44 | N9: 1.89 | O9: 1.98 | P9: 1.08 | Q9: 0 | R9: 27.99 | S9: 38.07 | T9: 35.01 | U9: 16.74 | V9: 17.1 | W9: 283.59 | X9: 9.99 | Y9: 31.5 | Z9: 13.14 | AA9: 36 | AB9: 57.96 | AC9: 151.47 | AD9: 0.27 | AE9: 54.09 | AF9: 116.73 | AG9: 36.72 | AH9: =Datos_originales!$H206/Datos_originales!$E206 -> 0 | AI9: =Datos_originales!$I206/Datos_originales!$E206 -> 0 | AJ9: =Datos_originales!$J206/Datos_originales!$E206 -> 0 | AK9: =Datos_originales!$K206/Datos_originales!$E206 -> 0 | AL9: =Datos_originales!$L206/Datos_originales!$E206 -> 0 | AM9: =Datos_originales!$M206/Datos_originales!$E206 -> 0 | AN9: =Datos_originales!$N206/Datos_originales!$E206 -> 0 | AO9: =Datos_originales!$O206/Datos_originales!$E206 -> 0 | AP9: =Datos_originales!$P206/Datos_originales!$E206 -> 0 | AQ9: =Datos_originales!$Q206/Datos_originales!$E206 -> 0 | AR9: =Datos_originales!$R206/Datos_originales!$E206 -> 0 | AS9: =Datos_originales!$S206/Datos_originales!$E206 -> 0 | AT9: =Datos_originales!$T206/Datos_originales!$E206 -> 0 | AU9: =Datos_originales!$U206/Datos_originales!$E206 -> 0 | AV9: =Datos_originales!$V206/Datos_originales!$E206 -> 0.0070921986 | AW9: =Datos_originales!$W206/Datos_originales!$E206 -> 0.042553191 | AX9: =Datos_originales!$X206/Datos_originales!$E206 -> 0.021276596 | AY9: =Datos_originales!$Y206/Datos_originales!$E206 -> 0 | AZ9: =Datos_originales!$Z206/Datos_originales!$E206 -> 0.070921986 | BA9: =Datos_originales!$AA206/Datos_originales!$E206 -> 0 | BB9: =Datos_originales!$AB206/Datos_originales!$E206 -> 0.092198582 | BC9: =Datos_originales!$AC206/Datos_originales!$E206 -> 0 | BD9: =Datos_originales!$AD206/Datos_originales!$E206 -> 0 | BE9: =Datos_originales!$AE206/Datos_originales!$E206 -> 0 | BF9: =Datos_originales!$AF206/Datos_originales!$E206 -> 0.014184397 | BG9: =Datos_originales!$AG206/Datos_originales!$E206 -> 0
A10: 10304 | B10: Chuquisaca | C10: Icla | D10: =IF(Datos_originales!$E10<1000,"Bosque menor a 1000 ha",Datos_originales!$E10) -> 2886.39 | E10: 2886.39 | F10: =AVERAGE(Datos_originales!$H216:$J216) -> 0 | G10: =AVERAGE(Datos_originales!$R216:$T216) -> 0 | H10: 0.81 | I10: 1.89 | J10: 1.98 | K10: 1.26 | L10: 0.9 | M10: 1.44 | N10: 2.07 | O10: 2.25 | P10: 0.36 | Q10: 1.71 | R10: 0 | S10: 1.35 | T10: 1.44 | U10: 4.86 | V10: 5.49 | W10: 50.58 | X10: 2.61 | Y10: 3.33 | Z10: 3.42 | AA10: 3.15 | AB10: 4.95 | AC10: 2.07 | AD10: 5.22 | AE10: 0.81 | AF10: 2.79 | AG10: 1.62 | AH10: =Datos_originales!$H216/Datos_originales!$E216 -> #DIV/0! | AI10: =Datos_originales!$I216/Datos_originales!$E216 -> #DIV/0! | AJ10: =Datos_originales!$J216/Datos_originales!$E216 -> #DIV/0! | AK10: =Datos_originales!$K216/Datos_originales!$E216 -> #DIV/0! | AL10: =Datos_originales!$L216/Datos_originales!$E216 -> #DIV/0! | AM10: =Datos_originales!$M216/Datos_originales!$E216 -> #DIV/0! | AN10: =Datos_originales!$N216/Datos_originales!$E216 -> #DIV/0! | AO10: =Datos_originales!$O216/Datos_originales!$E216 -> #DIV/0! | AP10: =Datos_originales!$P216/Datos_originales!$E216 -> #DIV/0! | AQ10: =Datos_originales!$Q216/Datos_originales!$E216 -> #DIV/0! | AR10: =Datos_originales!$R216/Datos_originales!$E216 -> #DIV/0! | AS10: =Datos_originales!$S216/Datos_originales!$E216 -> #DIV/0! | AT10: =Datos_originales!$T216/Datos_originales!$E216 -> #DIV/0! | AU10: =Datos_originales!$U216/Datos_originales!$E216 -> #DIV/0! | AV10: =Datos_originales!$V216/Datos_originales!$E216 -> #DIV/0! | AW10: =Datos_originales!$W216/Datos_originales!$E216 -> #DIV/0! | AX10: =Datos_originales!$X216/Datos_originales!$E216 -> #DIV/0! | AY10: =Datos_originales!$Y216/Datos_originales!$E216 -> #DIV/0! | AZ10: =Datos_originales!$Z216/Datos_originales!$E216 -> #DIV/0! | BA10: =Datos_originales!$AA216/Datos_originales!$E216 -> #DIV/0! | BB10: =Datos_originales!$AB216/Datos_originales!$E216 -> #DIV/0! | BC10: =Datos_originales!$AC216/Datos_originales!$E216 -> #DIV/0! | BD10: =Datos_originales!$AD216/Datos_originales!$E216 -> #DIV/0! | BE10: =Datos_originales!$AE216/Datos_originales!$E216 -> #DIV/0! | BF10: =Datos_originales!$AF216/Datos_originales!$E216 -> #DIV/0! | BG10: =Datos_originales!$AG216/Datos_originales!$E216 -> #DIV/0!
A11: 10401 | B11: Chuquisaca | C11: Padilla | D11: =IF(Datos_originales!$E11<1000,"Bosque menor a 1000 ha",Datos_originales!$E11) -> 117418.41 | E11: 117418.41 | F11: =AVERAGE(Datos_originales!$H185:$J185) -> 0 | G11: =AVERAGE(Datos_originales!$R185:$T185) -> 0 | H11: 212.49 | I11: 262.62 | J11: 149.58 | K11: 124.65 | L11: 183.42 | M11: 226.89 | N11: 379.71 | O11: 160.92 | P11: 446.94 | Q11: 225.09 | R11: 182.88 | S11: 1026.9 | T11: 285.84 | U11: 289.89 | V11: 340.65 | W11: 488.52 | X11: 158.04 | Y11: 224.91 | Z11: 274.5 | AA11: 434.7 | AB11: 251.64 | AC11: 518.22 | AD11: 333.99 | AE11: 247.32 | AF11: 1132.29 | AG11: 291.42 | AH11: =Datos_originales!$H185/Datos_originales!$E185 -> #DIV/0! | AI11: =Datos_originales!$I185/Datos_originales!$E185 -> #DIV/0! | AJ11: =Datos_originales!$J185/Datos_originales!$E185 -> #DIV/0! | AK11: =Datos_originales!$K185/Datos_originales!$E185 -> #DIV/0! | AL11: =Datos_originales!$L185/Datos_originales!$E185 -> #DIV/0! | AM11: =Datos_originales!$M185/Datos_originales!$E185 -> #DIV/0! | AN11: =Datos_originales!$N185/Datos_originales!$E185 -> #DIV/0! | AO11: =Datos_originales!$O185/Datos_originales!$E185 -> #DIV/0! | AP11: =Datos_originales!$P185/Datos_originales!$E185 -> #DIV/0! | AQ11: =Datos_originales!$Q185/Datos_originales!$E185 -> #DIV/0! | AR11: =Datos_originales!$R185/Datos_originales!$E185 -> #DIV/0! | AS11: =Datos_originales!$S185/Datos_originales!$E185 -> #DIV/0! | AT11: =Datos_originales!$T185/Datos_originales!$E185 -> #DIV/0! | AU11: =Datos_originales!$U185/Datos_originales!$E185 -> #DIV/0! | AV11: =Datos_originales!$V185/Datos_originales!$E185 -> #DIV/0! | AW11: =Datos_originales!$W185/Datos_originales!$E185 -> #DIV/0! | AX11: =Datos_originales!$X185/Datos_originales!$E185 -> #DIV/0! | AY11: =Datos_originales!$Y185/Datos_originales!$E185 -> #DIV/0! | AZ11: =Datos_originales!$Z185/Datos_originales!$E185 -> #DIV/0! | BA11: =Datos_originales!$AA185/Datos_originales!$E185 -> #DIV/0! | BB11: =Datos_originales!$AB185/Datos_originales!$E185 -> #DIV/0! | BC11: =Datos_originales!$AC185/Datos_originales!$E185 -> #DIV/0! | BD11: =Datos_originales!$AD185/Datos_originales!$E185 -> #DIV/0! | BE11: =Datos_originales!$AE185/Datos_originales!$E185 -> #DIV/0! | BF11: =Datos_originales!$AF185/Datos_originales!$E185 -> #DIV/0! | BG11: =Datos_originales!$AG185/Datos_originales!$E185 -> #DIV/0!
A12: 10402 | B12: Chuquisaca | C12: Tomina | D12: =IF(Datos_originales!$E12<1000,"Bosque menor a 1000 ha",Datos_originales!$E12) -> 22272.39 | E12: 22272.39 | F12: =AVERAGE(Datos_originales!$H213:$J213) -> 0.06 | G12: =AVERAGE(Datos_originales!$R213:$T213) -> 3.15 | H12: 2.97 | I12: 2.52 | J12: 2.52 | K12: 1.35 | L12: 3.69 | M12: 1.26 | N12: 3.87 | O12: 2.16 | P12: 4.86 | Q12: 0.09 | R12: 5.58 | S12: 43.11 | T12: 19.71 | U12: 16.56 | V12: 18.99 | W12: 294.66 | X12: 8.1 | Y12: 18 | Z12: 11.97 | AA12: 24.03 | AB12: 32.13 | AC12: 47.79 | AD12: 0.18 | AE12: 40.05 | AF12: 133.47 | AG12: 20.79 | AH12: =Datos_originales!$H213/Datos_originales!$E213 -> 0 | AI12: =Datos_originales!$I213/Datos_originales!$E213 -> 1.2604301e-05 | AJ12: =Datos_originales!$J213/Datos_originales!$E213 -> 1.2604301e-05 | AK12: =Datos_originales!$K213/Datos_originales!$E213 -> 1.2604301e-05 | AL12: =Datos_originales!$L213/Datos_originales!$E213 -> 1.2604301e-05 | AM12: =Datos_originales!$M213/Datos_originales!$E213 -> 1.2604301e-05 | AN12: =Datos_originales!$N213/Datos_originales!$E213 -> 0 | AO12: =Datos_originales!$O213/Datos_originales!$E213 -> 1.2604301e-05 | AP12: =Datos_originales!$P213/Datos_originales!$E213 -> 0 | AQ12: =Datos_originales!$Q213/Datos_originales!$E213 -> 0 | AR12: =Datos_originales!$R213/Datos_originales!$E213 -> 0.00030250321 | AS12: =Datos_originales!$S213/Datos_originales!$E213 -> 0.00031510751 | AT12: =Datos_originales!$T213/Datos_originales!$E213 -> 0.00070584083 | AU12: =Datos_originales!$U213/Datos_originales!$E213 -> 0.0023948171 | AV12: =Datos_originales!$V213/Datos_originales!$E213 -> 0.0013360559 | AW12: =Datos_originales!$W213/Datos_originales!$E213 -> 0.016309965 | AX12: =Datos_originales!$X213/Datos_originales!$E213 -> 0.00061761073 | AY12: =Datos_originales!$Y213/Datos_originales!$E213 -> 0.00044115052 | AZ12: =Datos_originales!$Z213/Datos_originales!$E213 -> 0.00041594192 | BA12: =Datos_originales!$AA213/Datos_originales!$E213 -> 0.00063021503 | BB12: =Datos_originales!$AB213/Datos_originales!$E213 -> 0.0019410623 | BC12: =Datos_originales!$AC213/Datos_originales!$E213 -> 0.0076129976 | BD12: =Datos_originales!$AD213/Datos_originales!$E213 -> 8.8230104e-05 | BE12: =Datos_originales!$AE213/Datos_originales!$E213 -> 0.00054198493 | BF12: =Datos_originales!$AF213/Datos_originales!$E213 -> 0.0094658297 | BG12: =Datos_originales!$AG213/Datos_originales!$E213 -> 0.0074995588
A13: 10403 | B13: Chuquisaca | C13: Sopachuy | D13: =IF(Datos_originales!$E13<1000,"Bosque menor a 1000 ha",Datos_originales!$E13) -> 23945.58 | E13: 23945.58 | F13: =AVERAGE(Datos_originales!$H170:$J170) -> 0 | G13: =AVERAGE(Datos_originales!$R170:$T170) -> 0 | H13: 8.46 | I13: 14.85 | J13: 14.67 | K13: 5.58 | L13: 3.06 | M13: 4.14 | N13: 6.93 | O13: 6.39 | P13: 27 | Q13: 2.61 | R13: 2.25 | S13: 253.35 | T13: 67.05 | U13: 20.52 | V13: 55.08 | W13: 238.59 | X13: 15.75 | Y13: 8.91 | Z13: 12.51 | AA13: 14.76 | AB13: 26.55 | AC13: 45.9 | AD13: 2.61 | AE13: 114.03 | AF13: 448.29 | AG13: 82.53 | AH13: =Datos_originales!$H170/Datos_originales!$E170 -> 0 | AI13: =Datos_originales!$I170/Datos_originales!$E170 -> 0 | AJ13: =Datos_originales!$J170/Datos_originales!$E170 -> 0 | AK13: =Datos_originales!$K170/Datos_originales!$E170 -> 0 | AL13: =Datos_originales!$L170/Datos_originales!$E170 -> 0 | AM13: =Datos_originales!$M170/Datos_originales!$E170 -> 0 | AN13: =Datos_originales!$N170/Datos_originales!$E170 -> 0 | AO13: =Datos_originales!$O170/Datos_originales!$E170 -> 0 | AP13: =Datos_originales!$P170/Datos_originales!$E170 -> 0 | AQ13: =Datos_originales!$Q170/Datos_originales!$E170 -> 0 | AR13: =Datos_originales!$R170/Datos_originales!$E170 -> 0 | AS13: =Datos_originales!$S170/Datos_originales!$E170 -> 0 | AT13: =Datos_originales!$T170/Datos_originales!$E170 -> 0 | AU13: =Datos_originales!$U170/Datos_originales!$E170 -> 0 | AV13: =Datos_originales!$V170/Datos_originales!$E170 -> 0 | AW13: =Datos_originales!$W170/Datos_originales!$E170 -> 0 | AX13: =Datos_originales!$X170/Datos_originales!$E170 -> 0 | AY13: =Datos_originales!$Y170/Datos_originales!$E170 -> 0 | AZ13: =Datos_originales!$Z170/Datos_originales!$E170 -> 0 | BA13: =Datos_originales!$AA170/Datos_originales!$E170 -> 0 | BB13: =Datos_originales!$AB170/Datos_originales!$E170 -> 0 | BC13: =Datos_originales!$AC170/Datos_originales!$E170 -> 0 | BD13: =Datos_originales!$AD170/Datos_originales!$E170 -> 0 | BE13: =Datos_originales!$AE170/Datos_originales!$E170 -> 0 | BF13: =Datos_originales!$AF170/Datos_originales!$E170 -> 0 | BG13: =Datos_originales!$AG170/Datos_originales!$E170 -> 0.83333333
A14: 10404 | B14: Chuquisaca | C14: Alcalá | D14: =IF(Datos_originales!$E14<1000,"Bosque menor a 1000 ha",Datos_originales!$E14) -> 8220.87 | E14: 8220.87 | F14: =AVERAGE(Datos_originales!$H198:$J198) -> 0 | G14: =AVERAGE(Datos_originales!$R198:$T198) -> 0 | H14: 1.17 | I14: 0.54 | J14: 2.07 | K14: 0.54 | L14: 0.18 | M14: 1.35 | N14: 0.09 | O14: 0.63 | P14: 1.53 | Q14: 1.17 | R14: 0.27 | S14: 35.01 | T14: 11.43 | U14: 3.6 | V14: 3.96 | W14: 79.38 | X14: 2.79 | Y14: 1.8 | Z14: 3.6 | AA14: 6.21 | AB14: 10.89 | AC14: 32.4 | AD14: 1.17 | AE14: 14.58 | AF14: 75.33 | AG14: 12.69 | AH14: =Datos_originales!$H198/Datos_originales!$E198 -> #DIV/0! | AI14: =Datos_originales!$I198/Datos_originales!$E198 -> #DIV/0! | AJ14: =Datos_originales!$J198/Datos_originales!$E198 -> #DIV/0! | AK14: =Datos_originales!$K198/Datos_originales!$E198 -> #DIV/0! | AL14: =Datos_originales!$L198/Datos_originales!$E198 -> #DIV/0! | AM14: =Datos_originales!$M198/Datos_originales!$E198 -> #DIV/0! | AN14: =Datos_originales!$N198/Datos_originales!$E198 -> #DIV/0! | AO14: =Datos_originales!$O198/Datos_originales!$E198 -> #DIV/0! | AP14: =Datos_originales!$P198/Datos_originales!$E198 -> #DIV/0! | AQ14: =Datos_originales!$Q198/Datos_originales!$E198 -> #DIV/0! | AR14: =Datos_originales!$R198/Datos_originales!$E198 -> #DIV/0! | AS14: =Datos_originales!$S198/Datos_originales!$E198 -> #DIV/0! | AT14: =Datos_originales!$T198/Datos_originales!$E198 -> #DIV/0! | AU14: =Datos_originales!$U198/Datos_originales!$E198 -> #DIV/0! | AV14: =Datos_originales!$V198/Datos_originales!$E198 -> #DIV/0! | AW14: =Datos_originales!$W198/Datos_originales!$E198 -> #DIV/0! | AX14: =Datos_originales!$X198/Datos_originales!$E198 -> #DIV/0! | AY14: =Datos_originales!$Y198/Datos_originales!$E198 -> #DIV/0! | AZ14: =Datos_originales!$Z198/Datos_originales!$E198 -> #DIV/0! | BA14: =Datos_originales!$AA198/Datos_originales!$E198 -> #DIV/0! | BB14: =Datos_originales!$AB198/Datos_originales!$E198 -> #DIV/0! | BC14: =Datos_originales!$AC198/Datos_originales!$E198 -> #DIV/0! | BD14: =Datos_originales!$AD198/Datos_originales!$E198 -> #DIV/0! | BE14: =Datos_originales!$AE198/Datos_originales!$E198 -> #DIV/0! | BF14: =Datos_originales!$AF198/Datos_originales!$E198 -> #DIV/0! | BG14: =Datos_originales!$AG198/Datos_originales!$E198 -> #DIV/0!
A15: 10405 | B15: Chuquisaca | C15: El Villar | D15: =IF(Datos_originales!$E15<1000,"Bosque menor a 1000 ha",Datos_originales!$E15) -> 50038.29 | E15: 50038.29 | F15: =AVERAGE(Datos_originales!$H193:$J193) -> 0 | G15: =AVERAGE(Datos_originales!$R193:$T193) -> 0 | H15: 25.74 | I15: 59.58 | J15: 52.83 | K15: 29.34 | L15: 35.19 | M15: 30.33 | N15: 59.04 | O15: 43.47 | P15: 58.86 | Q15: 37.26 | R15: 39.6 | S15: 309.06 | T15: 83.34 | U15: 55.8 | V15: 89.1 | W15: 444.15 | X15: 46.35 | Y15: 50.85 | Z15: 41.58 | AA15: 73.17 | AB15: 95.4 | AC15: 76.95 | AD15: 84.24 | AE15: 100.8 | AF15: 365.31 | AG15: 91.08 | AH15: =Datos_originales!$H193/Datos_originales!$E193 -> #DIV/0! | AI15: =Datos_originales!$I193/Datos_originales!$E193 -> #DIV/0! | AJ15: =Datos_originales!$J193/Datos_originales!$E193 -> #DIV/0! | AK15: =Datos_originales!$K193/Datos_originales!$E193 -> #DIV/0! | AL15: =Datos_originales!$L193/Datos_originales!$E193 -> #DIV/0! | AM15: =Datos_originales!$M193/Datos_originales!$E193 -> #DIV/0! | AN15: =Datos_originales!$N193/Datos_originales!$E193 -> #DIV/0! | AO15: =Datos_originales!$O193/Datos_originales!$E193 -> #DIV/0! | AP15: =Datos_originales!$P193/Datos_originales!$E193 -> #DIV/0! | AQ15: =Datos_originales!$Q193/Datos_originales!$E193 -> #DIV/0! | AR15: =Datos_originales!$R193/Datos_originales!$E193 -> #DIV/0! | AS15: =Datos_originales!$S193/Datos_originales!$E193 -> #DIV/0! | AT15: =Datos_originales!$T193/Datos_originales!$E193 -> #DIV/0! | AU15: =Datos_originales!$U193/Datos_originales!$E193 -> #DIV/0! | AV15: =Datos_originales!$V193/Datos_originales!$E193 -> #DIV/0! | AW15: =Datos_originales!$W193/Datos_originales!$E193 -> #DIV/0! | AX15: =Datos_originales!$X193/Datos_originales!$E193 -> #DIV/0! | AY15: =Datos_originales!$Y193/Datos_originales!$E193 -> #DIV/0! | AZ15: =Datos_originales!$Z193/Datos_originales!$E193 -> #DIV/0! | BA15: =Datos_originales!$AA193/Datos_originales!$E193 -> #DIV/0! | BB15: =Datos_originales!$AB193/Datos_originales!$E193 -> #DIV/0! | BC15: =Datos_originales!$AC193/Datos_originales!$E193 -> #DIV/0! | BD15: =Datos_originales!$AD193/Datos_originales!$E193 -> #DIV/0! | BE15: =Datos_originales!$AE193/Datos_originales!$E193 -> #DIV/0! | BF15: =Datos_originales!$AF193/Datos_originales!$E193 -> #DIV/0! | BG15: =Datos_originales!$AG193/Datos_originales!$E193 -> #DIV/0!
A16: 10501 | B16: Chuquisaca | C16: Monteagudo | D16: =IF(Datos_originales!$E16<1000,"Bosque menor a 1000 ha",Datos_originales!$E16) -> 290186.28 | E16: 290186.28 | F16: =AVERAGE(Datos_originales!$H122:$J122) -> 18.09 | G16: =AVERAGE(Datos_originales!$R122:$T122) -> 85.26 | H16: 901.08 | I16: 1518.39 | J16: 866.52 | K16: 439.47 | L16: 674.82 | M16: 867.06 | N16: 1329.03 | O16: 1273.77 | P16: 1099.17 | Q16: 976.41 | R16: 277.38 | S16: 2491.56 | T16: 2418.84 | U16: 1048.5 | V16: 1645.29 | W16: 1286.91 | X16: 506.34 | Y16: 759.6 | Z16: 938.79 | AA16: 1398.6 | AB16: 1420.65 | AC16: 1195.29 | AD16: 1184.04 | AE16: 334.17 | AF16: 2577.15 | AG16: 2427.39 | AH16: =Datos_originales!$H122/Datos_originales!$E122 -> 0.00063964763 | AI16: =Datos_originales!$I122/Datos_originales!$E122 -> 0.00072871249 | AJ16: =Datos_originales!$J122/Datos_originales!$E122 -> 0.0010728267 | AK16: =Datos_originales!$K122/Datos_originales!$E122 -> 0.00055867957 | AL16: =Datos_originales!$L122/Datos_originales!$E122 -> 0.00065584124 | AM16: =Datos_originales!$M122/Datos_originales!$E122 -> 0.00058701839 | AN16: =Datos_originales!$N122/Datos_originales!$E122 -> 0.00050200194 | AO16: =Datos_originales!$O122/Datos_originales!$E122 -> 0.00028338819 | AP16: =Datos_originales!$P122/Datos_originales!$E122 -> 0.0019513301 | AQ16: =Datos_originales!$Q122/Datos_originales!$E122 -> 0.0001457425 | AR16: =Datos_originales!$R122/Datos_originales!$E122 -> 0.00042103388 | AS16: =Datos_originales!$S122/Datos_originales!$E122 -> 0.0040726931 | AT16: =Datos_originales!$T122/Datos_originales!$E122 -> 0.0070118335 | AU16: =Datos_originales!$U122/Datos_originales!$E122 -> 0.0049592933 | AV16: =Datos_originales!$V122/Datos_originales!$E122 -> 0.0031982381 | AW16: =Datos_originales!$W122/Datos_originales!$E122 -> 0.011141204 | AX16: =Datos_originales!$X122/Datos_originales!$E122 -> 0.0014290862 | AY16: =Datos_originales!$Y122/Datos_originales!$E122 -> 0.0014128925 | AZ16: =Datos_originales!$Z122/Datos_originales!$E122 -> 0.0011618916 | BA16: =Datos_originales!$AA122/Datos_originales!$E122 -> 0.0010485363 | BB16: =Datos_originales!$AB122/Datos_originales!$E122 -> 0.00085016457 | BC16: =Datos_originales!$AC122/Datos_originales!$E122 -> 0.0026355102 | BD16: =Datos_originales!$AD122/Datos_originales!$E122 -> 0.00077324492 | BE16: =Datos_originales!$AE122/Datos_originales!$E122 -> 0.00075705131 | BF16: =Datos_originales!$AF122/Datos_originales!$E122 -> 0.0049997773 | BG16: =Datos_originales!$AG122/Datos_originales!$E122 -> 0.020739967
A17: 10502 | B17: Chuquisaca | C17: Huacareta | D17: =IF(Datos_originales!$E17<1000,"Bosque menor a 1000 ha",Datos_originales!$E17) -> 280002.24 | E17: 280002.24 | F17: =AVERAGE(Datos_originales!$H115:$J115) -> 0 | G17: =AVERAGE(Datos_originales!$R115:$T115) -> 0 | H17: 401.04 | I17: 518.85 | J17: 484.29 | K17: 236.97 | L17: 529.29 | M17: 634.68 | N17: 714.87 | O17: 692.01 | P17: 598.05 | Q17: 725.85 | R17: 546.21 | S17: 1872.18 | T17: 3090.33 | U17: 433.8 | V17: 544.77 | W17: 550.53 | X17: 259.02 | Y17: 539.28 | Z17: 647.01 | AA17: 736.74 | AB17: 740.61 | AC17: 616.05 | AD17: 764.55 | AE17: 572.04 | AF17: 1921.32 | AG17: 3200.31 | AH17: =Datos_originales!$H115/Datos_originales!$E115 -> #DIV/0! | AI17: =Datos_originales!$I115/Datos_originales!$E115 -> #DIV/0! | AJ17: =Datos_originales!$J115/Datos_originales!$E115 -> #DIV/0! | AK17: =Datos_originales!$K115/Datos_originales!$E115 -> #DIV/0! | AL17: =Datos_originales!$L115/Datos_originales!$E115 -> #DIV/0! | AM17: =Datos_originales!$M115/Datos_originales!$E115 -> #DIV/0! | AN17: =Datos_originales!$N115/Datos_originales!$E115 -> #DIV/0! | AO17: =Datos_originales!$O115/Datos_originales!$E115 -> #DIV/0! | AP17: =Datos_originales!$P115/Datos_originales!$E115 -> #DIV/0! | AQ17: =Datos_originales!$Q115/Datos_originales!$E115 -> #DIV/0! | AR17: =Datos_originales!$R115/Datos_originales!$E115 -> #DIV/0! | AS17: =Datos_originales!$S115/Datos_originales!$E115 -> #DIV/0! | AT17: =Datos_originales!$T115/Datos_originales!$E115 -> #DIV/0! | AU17: =Datos_originales!$U115/Datos_originales!$E115 -> #DIV/0! | AV17: =Datos_originales!$V115/Datos_originales!$E115 -> #DIV/0! | AW17: =Datos_originales!$W115/Datos_originales!$E115 -> #DIV/0! | AX17: =Datos_originales!$X115/Datos_originales!$E115 -> #DIV/0! | AY17: =Datos_originales!$Y115/Datos_originales!$E115 -> #DIV/0! | AZ17: =Datos_originales!$Z115/Datos_originales!$E115 -> #DIV/0! | BA17: =Datos_originales!$AA115/Datos_originales!$E115 -> #DIV/0! | BB17: =Datos_originales!$AB115/Datos_originales!$E115 -> #DIV/0! | BC17: =Datos_originales!$AC115/Datos_originales!$E115 -> #DIV/0! | BD17: =Datos_originales!$AD115/Datos_originales!$E115 -> #DIV/0! | BE17: =Datos_originales!$AE115/Datos_originales!$E115 -> #DIV/0! | BF17: =Datos_originales!$AF115/Datos_originales!$E115 -> #DIV/0! | BG17: =Datos_originales!$AG115/Datos_originales!$E115 -> #DIV/0!
A18: 10601 | B18: Chuquisaca | C18: Tarabuco | D18: =IF(Datos_originales!$E18<1000,"Bosque menor a 1000 ha",Datos_originales!$E18) -> 4594.5 | E18: 4594.5 | F18: =AVERAGE(Datos_originales!$H217:$J217) -> 0.63 | G18: =AVERAGE(Datos_originales!$R217:$T217) -> 5.19 | H18: 0.18 | I18: 1.71 | J18: 1.89 | K18: 1.08 | L18: 0.18 | M18: 1.08 | N18: 0.36 | O18: 0.81 | P18: 3.78 | Q18: 0.27 | R18: 2.34 | S18: 7.2 | T18: 2.34 | U18: 9.99 | V18: 9.63 | W18: 75.42 | X18: 2.52 | Y18: 9.81 | Z18: 14.04 | AA18: 29.43 | AB18: 21.06 | AC18: 49.23 | AD18: 0.72 | AE18: 3.24 | AF18: 13.41 | AG18: 2.52 | AH18: =Datos_originales!$H217/Datos_originales!$E217 -> 7.1789055e-05 | AI18: =Datos_originales!$I217/Datos_originales!$E217 -> 6.461015e-05 | AJ18: =Datos_originales!$J217/Datos_originales!$E217 -> 1.4357811e-05 | AK18: =Datos_originales!$K217/Datos_originales!$E217 -> 1.4357811e-05 | AL18: =Datos_originales!$L217/Datos_originales!$E217 -> 7.1789055e-06 | AM18: =Datos_originales!$M217/Datos_originales!$E217 -> 0 | AN18: =Datos_originales!$N217/Datos_originales!$E217 -> 7.1789055e-06 | AO18: =Datos_originales!$O217/Datos_originales!$E217 -> 3.5894528e-05 | AP18: =Datos_originales!$P217/Datos_originales!$E217 -> 2.8715622e-05 | AQ18: =Datos_originales!$Q217/Datos_originales!$E217 -> 0 | AR18: =Datos_originales!$R217/Datos_originales!$E217 -> 3.5894528e-05 | AS18: =Datos_originales!$S217/Datos_originales!$E217 -> 0.0011916983 | AT18: =Datos_originales!$T217/Datos_originales!$E217 -> 1.4357811e-05 | AU18: =Datos_originales!$U217/Datos_originales!$E217 -> 0.0049893393 | AV18: =Datos_originales!$V217/Datos_originales!$E217 -> 0.003646884 | AW18: =Datos_originales!$W217/Datos_originales!$E217 -> 0.015736161 | AX18: =Datos_originales!$X217/Datos_originales!$E217 -> 0.0018090842 | AY18: =Datos_originales!$Y217/Datos_originales!$E217 -> 0.0011988772 | AZ18: =Datos_originales!$Z217/Datos_originales!$E217 -> 0.0011558038 | BA18: =Datos_originales!$AA217/Datos_originales!$E217 -> 0.0023977544 | BB18: =Datos_originales!$AB217/Datos_originales!$E217 -> 0.0048026878 | BC18: =Datos_originales!$AC217/Datos_originales!$E217 -> 0.016037675 | BD18: =Datos_originales!$AD217/Datos_originales!$E217 -> 5.7431244e-05 | BE18: =Datos_originales!$AE217/Datos_originales!$E217 -> 0.00033022965 | BF18: =Datos_originales!$AF217/Datos_originales!$E217 -> 0.0084423929 | BG18: =Datos_originales!$AG217/Datos_originales!$E217 -> 7.1789055e-05
A19: 10602 | B19: Chuquisaca | C19: Yamparáez | D19: =IF(Datos_originales!$E19<1000,"Bosque menor a 1000 ha",Datos_originales!$E19) -> Bosque menor a 1000 ha | E19: 694.26 | F19: =AVERAGE(Datos_originales!$H230:$J230) -> 0.33 | G19: =AVERAGE(Datos_originales!$R230:$T230) -> 0.99 | H19: 0 | I19: 0.18 | J19: 0.45 | K19: 0.09 | L19: 0.45 | M19: 0.18 | N19: 0 | O19: 0 | P19: 0 | Q19: 0.09 | R19: 0 | S19: 0.54 | T19: 0.09 | U19: 1.62 | V19: 1.44 | W19: 14.04 | X19: 0.72 | Y19: 0.81 | Z19: 0.18 | AA19: 0.45 | AB19: 0.27 | AC19: 1.26 | AD19: 0.63 | AE19: 0.09 | AF19: 0.72 | AG19: 0.09 | AH19: =Datos_originales!$H230/Datos_originales!$E230 -> 0.0081833061 | AI19: =Datos_originales!$I230/Datos_originales!$E230 -> 0.0065466448 | AJ19: =Datos_originales!$J230/Datos_originales!$E230 -> 0.0032733224 | AK19: =Datos_originales!$K230/Datos_originales!$E230 -> 0 | AL19: =Datos_originales!$L230/Datos_originales!$E230 -> 0.0098199673 | AM19: =Datos_originales!$M230/Datos_originales!$E230 -> 0.0016366612 | AN19: =Datos_originales!$N230/Datos_originales!$E230 -> 0.0065466448 | AO19: =Datos_originales!$O230/Datos_originales!$E230 -> 0.0016366612 | AP19: =Datos_originales!$P230/Datos_originales!$E230 -> 0 | AQ19: =Datos_originales!$Q230/Datos_originales!$E230 -> 0 | AR19: =Datos_originales!$R230/Datos_originales!$E230 -> 0 | AS19: =Datos_originales!$S230/Datos_originales!$E230 -> 0.0016366612 | AT19: =Datos_originales!$T230/Datos_originales!$E230 -> 0.052373159 | AU19: =Datos_originales!$U230/Datos_originales!$E230 -> 0.0098199673 | AV19: =Datos_originales!$V230/Datos_originales!$E230 -> 0.018003273 | AW19: =Datos_originales!$W230/Datos_originales!$E230 -> 0.032733224 | AX19: =Datos_originales!$X230/Datos_originales!$E230 -> 0 | AY19: =Datos_originales!$Y230/Datos_originales!$E230 -> 0.016366612 | AZ19: =Datos_originales!$Z230/Datos_originales!$E230 -> 0.0016366612 | BA19: =Datos_originales!$AA230/Datos_originales!$E230 -> 0.0065466448 | BB19: =Datos_originales!$AB230/Datos_originales!$E230 -> 0.0016366612 | BC19: =Datos_originales!$AC230/Datos_originales!$E230 -> 0 | BD19: =Datos_originales!$AD230/Datos_originales!$E230 -> 0 | BE19: =Datos_originales!$AE230/Datos_originales!$E230 -> 0 | BF19: =Datos_originales!$AF230/Datos_originales!$E230 -> 0.011456628 | BG19: =Datos_originales!$AG230/Datos_originales!$E230 -> 0.12274959
A20: 10701 | B20: Chuquisaca | C20: Camargo | D20: =IF(Datos_originales!$E20<1000,"Bosque menor a 1000 ha",Datos_originales!$E20) -> Bosque menor a 1000 ha | E20: 79.2 | F20: =AVERAGE(Datos_originales!$H7:$J7) -> 0.06 | G20: =AVERAGE(Datos_originales!$R7:$T7) -> 4.83 | H20: 1.89 | I20: 1.71 | J20: 0.9 | K20: 1.26 | L20: 2.07 | M20: 0.27 | N20: 0.54 | O20: 1.53 | P20: 0.27 | Q20: 0.99 | R20: 0 | S20: 1.35 | T20: 26.1 | U20: 2.79 | V20: 1.98 | W20: 1.53 | X20: 1.89 | Y20: 2.16 | Z20: 0.36 | AA20: 0.54 | AB20: 2.07 | AC20: 0.36 | AD20: 1.17 | AE20: 0 | AF20: 1.8 | AG20: 49.32 | AH20: =Datos_originales!$H7/Datos_originales!$E7 -> 9.5794616e-06 | AI20: =Datos_originales!$I7/Datos_originales!$E7 -> 0 | AJ20: =Datos_originales!$J7/Datos_originales!$E7 -> 9.5794616e-06 | AK20: =Datos_originales!$K7/Datos_originales!$E7 -> 0 | AL20: =Datos_originales!$L7/Datos_originales!$E7 -> 1.9158923e-05 | AM20: =Datos_originales!$M7/Datos_originales!$E7 -> 0 | AN20: =Datos_originales!$N7/Datos_originales!$E7 -> 1.9158923e-05 | AO20: =Datos_originales!$O7/Datos_originales!$E7 -> 6.7056231e-05 | AP20: =Datos_originales!$P7/Datos_originales!$E7 -> 6.7056231e-05 | AQ20: =Datos_originales!$Q7/Datos_originales!$E7 -> 0 | AR20: =Datos_originales!$R7/Datos_originales!$E7 -> 9.5794616e-06 | AS20: =Datos_originales!$S7/Datos_originales!$E7 -> 0.001120797 | AT20: =Datos_originales!$T7/Datos_originales!$E7 -> 0.00041191685 | AU20: =Datos_originales!$U7/Datos_originales!$E7 -> 0.00092920778 | AV20: =Datos_originales!$V7/Datos_originales!$E7 -> 0.00073761855 | AW20: =Datos_originales!$W7/Datos_originales!$E7 -> 0.015250503 | AX20: =Datos_originales!$X7/Datos_originales!$E7 -> 0.00013411246 | AY20: =Datos_originales!$Y7/Datos_originales!$E7 -> 0.0014177603 | AZ20: =Datos_originales!$Z7/Datos_originales!$E7 -> 0.0019637896 | BA20: =Datos_originales!$AA7/Datos_originales!$E7 -> 0.0078551585 | BB20: =Datos_originales!$AB7/Datos_originales!$E7 -> 0.0079701121 | BC20: =Datos_originales!$AC7/Datos_originales!$E7 -> 0.0080180094 | BD20: =Datos_originales!$AD7/Datos_originales!$E7 -> 9.5794616e-06 | BE20: =Datos_originales!$AE7/Datos_originales!$E7 -> 8.6215155e-05 | BF20: =Datos_originales!$AF7/Datos_originales!$E7 -> 0.0041670658 | BG20: =Datos_originales!$AG7/Datos_originales!$E7 -> 0.00045981416
A21: 10702 | B21: Chuquisaca | C21: San Lucas | D21: =IF(Datos_originales!$E21<1000,"Bosque menor a 1000 ha",Datos_originales!$E21) -> 40473.81 | E21: 40473.81 | F21: =AVERAGE(Datos_originales!$H76:$J76) -> 0.42 | G21: =AVERAGE(Datos_originales!$R76:$T76) -> 30.3 | H21: 26.28 | I21: 39.33 | J21: 64.62 | K21: 46.98 | L21: 45.18 | M21: 85.77 | N21: 89.01 | O21: 68.58 | P21: 30.15 | Q21: 10.44 | R21: 9.63 | S21: 10.26 | T21: 39.6 | U21: 33.03 | V21: 51.93 | W21: 279 | X21: 54.72 | Y21: 51.39 | Z21: 92.88 | AA21: 97.65 | AB21: 80.82 | AC21: 36.9 | AD21: 28.35 | AE21: 11.34 | AF21: 13.59 | AG21: 829.44 | AH21: =Datos_originales!$H76/Datos_originales!$E76 -> 0.00074834295 | AI21: =Datos_originales!$I76/Datos_originales!$E76 -> 0.00032071841 | AJ21: =Datos_originales!$J76/Datos_originales!$E76 -> 0.00042762455 | AK21: =Datos_originales!$K76/Datos_originales!$E76 -> 0 | AL21: =Datos_originales!$L76/Datos_originales!$E76 -> 0.00021381227 | AM21: =Datos_originales!$M76/Datos_originales!$E76 -> 0.00021381227 | AN21: =Datos_originales!$N76/Datos_originales!$E76 -> 0 | AO21: =Datos_originales!$O76/Datos_originales!$E76 -> 0.001603592 | AP21: =Datos_originales!$P76/Datos_originales!$E76 -> 0.0010690614 | AQ21: =Datos_originales!$Q76/Datos_originales!$E76 -> 0.0043831516 | AR21: =Datos_originales!$R76/Datos_originales!$E76 -> 0.011866581 | AS21: =Datos_originales!$S76/Datos_originales!$E76 -> 0.078682916 | AT21: =Datos_originales!$T76/Datos_originales!$E76 -> 0.0174257 | AU21: =Datos_originales!$U76/Datos_originales!$E76 -> 0.0045969639 | AV21: =Datos_originales!$V76/Datos_originales!$E76 -> 0.0036348086 | AW21: =Datos_originales!$W76/Datos_originales!$E76 -> 0.021274321 | AX21: =Datos_originales!$X76/Datos_originales!$E76 -> 0.0010690614 | AY21: =Datos_originales!$Y76/Datos_originales!$E76 -> 0.0022450289 | AZ21: =Datos_originales!$Z76/Datos_originales!$E76 -> 0.00085524909 | BA21: =Datos_originales!$AA76/Datos_originales!$E76 -> 0.0011759675 | BB21: =Datos_originales!$AB76/Datos_originales!$E76 -> 0.0029933718 | BC21: =Datos_originales!$AC76/Datos_originales!$E76 -> 0.0040624332 | BD21: =Datos_originales!$AD76/Datos_originales!$E76 -> 0.0048107761 | BE21: =Datos_originales!$AE76/Datos_originales!$E76 -> 0.011866581 | BF21: =Datos_originales!$AF76/Datos_originales!$E76 -> 0.086807783 | BG21: =Datos_originales!$AG76/Datos_originales!$E76 -> 0.017853325
A22: 10703 | B22: Chuquisaca | C22: Incahuasi | D22: =IF(Datos_originales!$E22<1000,"Bosque menor a 1000 ha",Datos_originales!$E22) -> 53681.22 | E22: 53681.22 | F22: =AVERAGE(Datos_originales!$H121:$J121) -> 0.39 | G22: =AVERAGE(Datos_originales!$R121:$T121) -> 17.79 | H22: 35.91 | I22: 105.3 | J22: 77.49 | K22: 32.04 | L22: 96.66 | M22: 100.62 | N22: 95.67 | O22: 97.2 | P22: 136.98 | Q22: 34.56 | R22: 196.2 | S22: 648.36 | T22: 412.56 | U22: 64.53 | V22: 166.86 | W22: 259.2 | X22: 41.13 | Y22: 121.59 | Z22: 114.21 | AA22: 107.55 | AB22: 116.01 | AC22: 148.14 | AD22: 85.59 | AE22: 198.18 | AF22: 669.24 | AG22: 457.65 | AH22: =Datos_originales!$H121/Datos_originales!$E121 -> 4.8290183e-05 | AI22: =Datos_originales!$I121/Datos_originales!$E121 -> 2.0695793e-05 | AJ22: =Datos_originales!$J121/Datos_originales!$E121 -> 2.0695793e-05 | AK22: =Datos_originales!$K121/Datos_originales!$E121 -> 1.3797195e-05 | AL22: =Datos_originales!$L121/Datos_originales!$E121 -> 2.759439e-05 | AM22: =Datos_originales!$M121/Datos_originales!$E121 -> 6.8985975e-06 | AN22: =Datos_originales!$N121/Datos_originales!$E121 -> 2.0695793e-05 | AO22: =Datos_originales!$O121/Datos_originales!$E121 -> 4.8290183e-05 | AP22: =Datos_originales!$P121/Datos_originales!$E121 -> 4.1391585e-05 | AQ22: =Datos_originales!$Q121/Datos_originales!$E121 -> 0.00024834951 | AR22: =Datos_originales!$R121/Datos_originales!$E121 -> 0.0018281283 | AS22: =Datos_originales!$S121/Datos_originales!$E121 -> 0.0010002966 | AT22: =Datos_originales!$T121/Datos_originales!$E121 -> 0.0012624433 | AU22: =Datos_originales!$U121/Datos_originales!$E121 -> 0.00042081445 | AV22: =Datos_originales!$V121/Datos_originales!$E121 -> 0.00084852749 | AW22: =Datos_originales!$W121/Datos_originales!$E121 -> 0.011341294 | AX22: =Datos_originales!$X121/Datos_originales!$E121 -> 0.00053119201 | AY22: =Datos_originales!$Y121/Datos_originales!$E121 -> 0.0002690453 | AZ22: =Datos_originales!$Z121/Datos_originales!$E121 -> 0.00035182847 | BA22: =Datos_originales!$AA121/Datos_originales!$E121 -> 0.00040701725 | BB22: =Datos_originales!$AB121/Datos_originales!$E121 -> 0.00035872707 | BC22: =Datos_originales!$AC121/Datos_originales!$E121 -> 0.00039322006 | BD22: =Datos_originales!$AD121/Datos_originales!$E121 -> 0.00026214671 | BE22: =Datos_originales!$AE121/Datos_originales!$E121 -> 0.0021178694 | BF22: =Datos_originales!$AF121/Datos_originales!$E121 -> 0.0030008899 | BG22: =Datos_originales!$AG121/Datos_originales!$E121 -> 0.0013866181
A23: 10704 | B23: Chuquisaca | C23: Villa Charcas | D23: =IF(Datos_originales!$E23<1000,"Bosque menor a 1000 ha",Datos_originales!$E23) -> 10740.24 | E23: 10740.24 | F23: =AVERAGE(Datos_originales!$H171:$J171) -> 0 | G23: =AVERAGE(Datos_originales!$R171:$T171) -> 0 | H23: 4.32 | I23: 9.72 | J23: 27.36 | K23: 13.14 | L23: 9.9 | M23: 25.02 | N23: 16.65 | O23: 27.99 | P23: 4.59 | Q23: 2.7 | R23: 1.17 | S23: 3.96 | T23: 14.31 | U23: 8.1 | V23: 14.13 | W23: 106.2 | X23: 15.57 | Y23: 12.42 | Z23: 29.79 | AA23: 20.34 | AB23: 32.85 | AC23: 8.28 | AD23: 13.05 | AE23: 1.62 | AF23: 5.94 | AG23: 36.54 | AH23: =Datos_originales!$H171/Datos_originales!$E171 -> #DIV/0! | AI23: =Datos_originales!$I171/Datos_originales!$E171 -> #DIV/0! | AJ23: =Datos_originales!$J171/Datos_originales!$E171 -> #DIV/0! | AK23: =Datos_originales!$K171/Datos_originales!$E171 -> #DIV/0! | AL23: =Datos_originales!$L171/Datos_originales!$E171 -> #DIV/0! | AM23: =Datos_originales!$M171/Datos_originales!$E171 -> #DIV/0! | AN23: =Datos_originales!$N171/Datos_originales!$E171 -> #DIV/0! | AO23: =Datos_originales!$O171/Datos_originales!$E171 -> #DIV/0! | AP23: =Datos_originales!$P171/Datos_originales!$E171 -> #DIV/0! | AQ23: =Datos_originales!$Q171/Datos_originales!$E171 -> #DIV/0! | AR23: =Datos_originales!$R171/Datos_originales!$E171 -> #DIV/0! | AS23: =Datos_originales!$S171/Datos_originales!$E171 -> #DIV/0! | AT23: =Datos_originales!$T171/Datos_originales!$E171 -> #DIV/0! | AU23: =Datos_originales!$U171/Datos_originales!$E171 -> #DIV/0! | AV23: =Datos_originales!$V171/Datos_originales!$E171 -> #DIV/0! | AW23: =Datos_originales!$W171/Datos_originales!$E171 -> #DIV/0! | AX23: =Datos_originales!$X171/Datos_originales!$E171 -> #DIV/0! | AY23: =Datos_originales!$Y171/Datos_originales!$E171 -> #DIV/0! | AZ23: =Datos_originales!$Z171/Datos_originales!$E171 -> #DIV/0! | BA23: =Datos_originales!$AA171/Datos_originales!$E171 -> #DIV/0! | BB23: =Datos_originales!$AB171/Datos_originales!$E171 -> #DIV/0! | BC23: =Datos_originales!$AC171/Datos_originales!$E171 -> #DIV/0! | BD23: =Datos_originales!$AD171/Datos_originales!$E171 -> #DIV/0! | BE23: =Datos_originales!$AE171/Datos_originales!$E171 -> #DIV/0! | BF23: =Datos_originales!$AF171/Datos_originales!$E171 -> #DIV/0! | BG23: =Datos_originales!$AG171/Datos_originales!$E171 -> #DIV/0!
A24: 10801 | B24: Chuquisaca | C24: Villa Serrano | D24: =IF(Datos_originales!$E24<1000,"Bosque menor a 1000 ha",Datos_originales!$E24) -> 99479.16 | E24: 99479.16 | F24: =AVERAGE(Datos_originales!$H160:$J160) -> 0.03 | G24: =AVERAGE(Datos_originales!$R160:$T160) -> 3.81 | H24: 69.03 | I24: 94.86 | J24: 138.24 | K24: 91.53 | L24: 44.91 | M24: 81.99 | N24: 156.87 | O24: 136.62 | P24: 160.83 | Q24: 118.44 | R24: 169.02 | S24: 789.21 | T24: 402.48 | U24: 236.88 | V24: 295.38 | W24: 1181.88 | X24: 145.62 | Y24: 80.01 | Z24: 110.07 | AA24: 198.54 | AB24: 235.53 | AC24: 223.56 | AD24: 187.02 | AE24: 319.23 | AF24: 1032.75 | AG24: 414.54 | AH24: =Datos_originales!$H160/Datos_originales!$E160 -> 0 | AI24: =Datos_originales!$I160/Datos_originales!$E160 -> 0 | AJ24: =Datos_originales!$J160/Datos_originales!$E160 -> 0.0001879346 | AK24: =Datos_originales!$K160/Datos_originales!$E160 -> 0.0001879346 | AL24: =Datos_originales!$L160/Datos_originales!$E160 -> 0.0001879346 | AM24: =Datos_originales!$M160/Datos_originales!$E160 -> 0 | AN24: =Datos_originales!$N160/Datos_originales!$E160 -> 0.001879346 | AO24: =Datos_originales!$O160/Datos_originales!$E160 -> 0.0005638038 | AP24: =Datos_originales!$P160/Datos_originales!$E160 -> 0.00093967299 | AQ24: =Datos_originales!$Q160/Datos_originales!$E160 -> 0.0060139072 | AR24: =Datos_originales!$R160/Datos_originales!$E160 -> 0.002819019 | AS24: =Datos_originales!$S160/Datos_originales!$E160 -> 0.021048675 | AT24: =Datos_originales!$T160/Datos_originales!$E160 -> 0 | AU24: =Datos_originales!$U160/Datos_originales!$E160 -> 0.0060139072 | AV24: =Datos_originales!$V160/Datos_originales!$E160 -> 0.0050742342 | AW24: =Datos_originales!$W160/Datos_originales!$E160 -> 0.020296937 | AX24: =Datos_originales!$X160/Datos_originales!$E160 -> 0.0077053185 | AY24: =Datos_originales!$Y160/Datos_originales!$E160 -> 0.0080811877 | AZ24: =Datos_originales!$Z160/Datos_originales!$E160 -> 0.042849089 | BA24: =Datos_originales!$AA160/Datos_originales!$E160 -> 0.048111257 | BB24: =Datos_originales!$AB160/Datos_originales!$E160 -> 0.041345612 | BC24: =Datos_originales!$AC160/Datos_originales!$E160 -> 0.0093967299 | BD24: =Datos_originales!$AD160/Datos_originales!$E160 -> 0.0063897764 | BE24: =Datos_originales!$AE160/Datos_originales!$E160 -> 0.0030069536 | BF24: =Datos_originales!$AF160/Datos_originales!$E160 -> 0.082503289 | BG24: =Datos_originales!$AG160/Datos_originales!$E160 -> 0
A25: 10901 | B25: Chuquisaca | C25: Villa Abecia | D25: =IF(Datos_originales!$E25<1000,"Bosque menor a 1000 ha",Datos_originales!$E25) -> Bosque menor a 1000 ha | E25: 120.96 | F25: =AVERAGE(Datos_originales!$H10:$J10) -> 1.56 | G25: =AVERAGE(Datos_originales!$R10:$T10) -> 0.93 | H25: 1.26 | I25: 4.32 | J25: 2.88 | K25: 1.71 | L25: 3.69 | M25: 1.26 | N25: 1.26 | O25: 2.34 | P25: 1.17 | Q25: 0.9 | R25: 0.09 | S25: 3.96 | T25: 37.44 | U25: 1.53 | V25: 5.4 | W25: 4.59 | X25: 1.89 | Y25: 4.32 | Z25: 1.62 | AA25: 1.53 | AB25: 2.79 | AC25: 1.17 | AD25: 1.17 | AE25: 0.18 | AF25: 3.96 | AG25: 58.59 | AH25: =Datos_originales!$H10/Datos_originales!$E10 -> 0.00028062736 | AI25: =Datos_originales!$I10/Datos_originales!$E10 -> 0.00065479717 | AJ25: =Datos_originales!$J10/Datos_originales!$E10 -> 0.00068597799 | AK25: =Datos_originales!$K10/Datos_originales!$E10 -> 0.00043653145 | AL25: =Datos_originales!$L10/Datos_originales!$E10 -> 0.00031180818 | AM25: =Datos_originales!$M10/Datos_originales!$E10 -> 0.00049889308 | AN25: =Datos_originales!$N10/Datos_originales!$E10 -> 0.0007171588 | AO25: =Datos_originales!$O10/Datos_originales!$E10 -> 0.00077952044 | AP25: =Datos_originales!$P10/Datos_originales!$E10 -> 0.00012472327 | AQ25: =Datos_originales!$Q10/Datos_originales!$E10 -> 0.00059243553 | AR25: =Datos_originales!$R10/Datos_originales!$E10 -> 0 | AS25: =Datos_originales!$S10/Datos_originales!$E10 -> 0.00046771226 | AT25: =Datos_originales!$T10/Datos_originales!$E10 -> 0.00049889308 | AU25: =Datos_originales!$U10/Datos_originales!$E10 -> 0.0016837641 | AV25: =Datos_originales!$V10/Datos_originales!$E10 -> 0.0019020299 | AW25: =Datos_originales!$W10/Datos_originales!$E10 -> 0.017523619 | AX25: =Datos_originales!$X10/Datos_originales!$E10 -> 0.00090424371 | AY25: =Datos_originales!$Y10/Datos_originales!$E10 -> 0.0011536903 | AZ25: =Datos_originales!$Z10/Datos_originales!$E10 -> 0.0011848711 | BA25: =Datos_originales!$AA10/Datos_originales!$E10 -> 0.0010913286 | BB25: =Datos_originales!$AB10/Datos_originales!$E10 -> 0.001714945 | BC25: =Datos_originales!$AC10/Datos_originales!$E10 -> 0.0007171588 | BD25: =Datos_originales!$AD10/Datos_originales!$E10 -> 0.0018084874 | BE25: =Datos_originales!$AE10/Datos_originales!$E10 -> 0.00028062736 | BF25: =Datos_originales!$AF10/Datos_originales!$E10 -> 0.00096660534 | BG25: =Datos_originales!$AG10/Datos_originales!$E10 -> 0.00056125472
A26: 10902 | B26: Chuquisaca | C26: Culpina | D26: =IF(Datos_originales!$E26<1000,"Bosque menor a 1000 ha",Datos_originales!$E26) -> 232980.57 | E26: 232980.57 | F26: =AVERAGE(Datos_originales!$H156:$J156) -> 0.03 | G26: =AVERAGE(Datos_originales!$R156:$T156) -> 1.77 | H26: 419.76 | I26: 561.42 | J26: 504.63 | K26: 246.51 | L26: 385.83 | M26: 660.51 | N26: 330.75 | O26: 913.14 | P26: 634.77 | Q26: 499.86 | R26: 280.44 | S26: 2403.36 | T26: 858.78 | U26: 460.53 | V26: 597.87 | W26: 826.83 | X26: 296.01 | Y26: 420.48 | Z26: 690.03 | AA26: 360.72 | AB26: 942.39 | AC26: 654.57 | AD26: 536.67 | AE26: 283.68 | AF26: 2493.63 | AG26: 1014.93 | AH26: =Datos_originales!$H156/Datos_originales!$E156 -> 0 | AI26: =Datos_originales!$I156/Datos_originales!$E156 -> 0 | AJ26: =Datos_originales!$J156/Datos_originales!$E156 -> 0.00013078734 | AK26: =Datos_originales!$K156/Datos_originales!$E156 -> 0 | AL26: =Datos_originales!$L156/Datos_originales!$E156 -> 0.00013078734 | AM26: =Datos_originales!$M156/Datos_originales!$E156 -> 0 | AN26: =Datos_originales!$N156/Datos_originales!$E156 -> 0.00013078734 | AO26: =Datos_originales!$O156/Datos_originales!$E156 -> 0 | AP26: =Datos_originales!$P156/Datos_originales!$E156 -> 0 | AQ26: =Datos_originales!$Q156/Datos_originales!$E156 -> 0.0006539367 | AR26: =Datos_originales!$R156/Datos_originales!$E156 -> 0.0024849595 | AS26: =Datos_originales!$S156/Datos_originales!$E156 -> 0.0049699189 | AT26: =Datos_originales!$T156/Datos_originales!$E156 -> 0.00026157468 | AU26: =Datos_originales!$U156/Datos_originales!$E156 -> 0.0018310228 | AV26: =Datos_originales!$V156/Datos_originales!$E156 -> 0.0035312582 | AW26: =Datos_originales!$W156/Datos_originales!$E156 -> 0.019487314 | AX26: =Datos_originales!$X156/Datos_originales!$E156 -> 0.0075856657 | AY26: =Datos_originales!$Y156/Datos_originales!$E156 -> 0.0048391316 | AZ26: =Datos_originales!$Z156/Datos_originales!$E156 -> 0.017394716 | BA26: =Datos_originales!$AA156/Datos_originales!$E156 -> 0.034789432 | BB26: =Datos_originales!$AB156/Datos_originales!$E156 -> 0.035574156 | BC26: =Datos_originales!$AC156/Datos_originales!$E156 -> 0.015171331 | BD26: =Datos_originales!$AD156/Datos_originales!$E156 -> 0.0020925974 | BE26: =Datos_originales!$AE156/Datos_originales!$E156 -> 0.0035312582 | BF26: =Datos_originales!$AF156/Datos_originales!$E156 -> 0.041590374 | BG26: =Datos_originales!$AG156/Datos_originales!$E156 -> 0.00026157468
